Workbook

Sheet INFORMACION
B2: Información del Jugador
B3: Nombre | C3: Maria Jesús Figueroa
B4: Mail | C4: maria.figueroa@alumnos.mtn.cl

Sheet GRUPO A
B3: GRUPO A
C5: 2 | D5: 3 | E5: 5 | F5: 6 | G5: 4
B6: Tabla de Posiciones | J6: Fecha | K6: Partidos | AJ6: 1 | AK6: 2 | AL6: Ganador | AN6: Orden | AO6: Equipo | AP6: Puntos | AQ6: DG | AR6: GF | AS6: GC | AV6: Equipo | AW6: Empatado Con | AX6: Ganador | AY6: Ganador? | AZ6: Formula Rank | BA6: Formula Rank Con Duelo Directo | BB6: Formula Rank Con Prioridad
B7: Posición | C7: Equipo | D7: Puntos | E7: GF | F7: GC | G7: DG | I7: 1 | J7: 44886 | K7: Senegal | L7: 0 | M7: 1 | N7: Holanda | AI7: =CONCATENATE(K7,"_",N7) -> Senegal_Holanda | AJ7: =IF(L7>M7,3,IF(L7<M7,0,1)) -> 0 | AK7: =IF(AJ7=3,0,IF(AJ7=1,1,3)) -> 3 | AL7: =IF(AJ7>AK7,K7,IF(AK7>AJ7,N7,"SIN GANADOR")) -> Holanda | AN7: =_xlfn.RANK.EQ(BB7,BB$7:BB$11,1) -> 4 | AO7: Qatar | AP7: =SUMIF($K$7:$K$12,AO7,$AJ$7:$AJ$12) + SUMIF($N$7:$N$12,AO7,$AK$7:$AK$12) -> 0 | AQ7: =AR7-AS7 -> -3 | AR7: =SUMIF($K$7:$K$12,AO7,$L$7:$L$12) + SUMIF($N$7:$N$12,AO7,$M$7:$M$12) -> 0 | AS7: =SUMIF($K$7:$K$12,AO7,$M$7:$M$12) + SUMIF($N$7:$N$12,AO7,$L$7:$L$12) -> 3 | AV7: =AO7 -> Qatar | AW7: =IF(AZ7=AZ8,AV8,IF(AZ7=AZ9,AV9,IF(AZ7=AZ10,AV10,""))) | AX7: =IF(AW7="","",IFERROR(VLOOKUP(CONCATENATE(AV7,"_",AW7),$AI$7:$AL$16,4,FALSE),VLOOKUP(CONCATENATE(AW7,"_",AV7),$AI$7:$AL$16,4,FALSE))) | AY7: =IF(AX7="",1,IF(AX7=AV7,1,0)) -> 1 | AZ7: =-AP7*10000000 - AQ7*10000 - AR7*100 -> 30000 | BA7: =AZ7-AY7*10 -> 29990 | BB7: =BA7+N23 -> 29994
B8: 1 | C8: =IFERROR(VLOOKUP($B8,$AN$7:$AS$11,C$5,FALSE),"") -> Holanda | D8: =IFERROR(VLOOKUP($B8,$AN$7:$AS$11,D$5,FALSE),"") -> 9 | E8: =IFERROR(VLOOKUP($B8,$AN$7:$AS$11,E$5,FALSE),"") -> 3 | F8: =IFERROR(VLOOKUP($B8,$AN$7:$AS$11,F$5,FALSE),"") -> 0 | G8: =IFERROR(VLOOKUP($B8,$AN$7:$AS$11,G$5,FALSE),"") -> 3 | I8: 2 | J8: 44886 | K8: Qatar | L8: 0 | M8: 1 | N8: Ecuador | AI8: =CONCATENATE(K8,"_",N8) -> Qatar_Ecuador | AJ8: =IF(L8>M8,3,IF(L8<M8,0,1)) -> 0 | AK8: =IF(AJ8=3,0,IF(AJ8=1,1,3)) -> 3 | AL8: =IF(AJ8>AK8,K8,IF(AK8>AJ8,N8,"SIN GANADOR")) -> Ecuador | AN8: =_xlfn.RANK.EQ(BB8,BB$7:BB$11,1) -> 1 | AO8: Holanda | AP8: =SUMIF($K$7:$K$12,AO8,$AJ$7:$AJ$12) + SUMIF($N$7:$N$12,AO8,$AK$7:$AK$12) -> 9 | AQ8: =AR8-AS8 -> 3 | AR8: =SUMIF($K$7:$K$12,AO8,$L$7:$L$12) + SUMIF($N$7:$N$12,AO8,$M$7:$M$12) -> 3 | AS8: =SUMIF($K$7:$K$12,AO8,$M$7:$M$12) + SUMIF($N$7:$N$12,AO8,$L$7:$L$12) -> 0 | AV8: =AO8 -> Holanda | AW8: =IF(AZ8=AZ9,AV9,IF(AZ8=AZ10,AV10,IF(AZ8=AZ7,AV7,""))) | AX8: =IF(AW8="","",IFERROR(VLOOKUP(CONCATENATE(AV8,"_",AW8),$AI$7:$AL$16,4,FALSE),VLOOKUP(CONCATENATE(AW8,"_",AV8),$AI$7:$AL$16,4,FALSE))) | AY8: =IF(AX8="",1,IF(AX8=AV8,1,0)) -> 1 | AZ8: =-AP8*10000000 - AQ8*10000 - AR8*100 -> -90030300 | BA8: =AZ8-AY8*10 -> -90030310 | BB8: =BA8+N24 -> -90030309
B9: 2 | C9: =IFERROR(VLOOKUP($B9,$AN$7:$AS$11,C$5,FALSE),"") -> Senegal | D9: =IFERROR(VLOOKUP($B9,$AN$7:$AS$11,D$5,FALSE),"") -> 6 | E9: =IFERROR(VLOOKUP($B9,$AN$7:$AS$11,E$5,FALSE),"") -> 2 | F9: =IFERROR(VLOOKUP($B9,$AN$7:$AS$11,F$5,FALSE),"") -> 1 | G9: =IFERROR(VLOOKUP($B9,$AN$7:$AS$11,G$5,FALSE),"") -> 1 | I9: =I7+16 -> 17 | J9: 44890 | K9: Qatar | L9: 0 | M9: 1 | N9: Senegal | AI9: =CONCATENATE(K9,"_",N9) -> Qatar_Senegal | AJ9: =IF(L9>M9,3,IF(L9<M9,0,1)) -> 0 | AK9: =IF(AJ9=3,0,IF(AJ9=1,1,3)) -> 3 | AL9: =IF(AJ9>AK9,K9,IF(AK9>AJ9,N9,"SIN GANADOR")) -> Senegal | AN9: =_xlfn.RANK.EQ(BB9,BB$7:BB$11,1) -> 2 | AO9: Senegal | AP9: =SUMIF($K$7:$K$12,AO9,$AJ$7:$AJ$12) + SUMIF($N$7:$N$12,AO9,$AK$7:$AK$12) -> 6 | AQ9: =AR9-AS9 -> 1 | AR9: =SUMIF($K$7:$K$12,AO9,$L$7:$L$12) + SUMIF($N$7:$N$12,AO9,$M$7:$M$12) -> 2 | AS9: =SUMIF($K$7:$K$12,AO9,$M$7:$M$12) + SUMIF($N$7:$N$12,AO9,$L$7:$L$12) -> 1 | AV9: =AO9 -> Senegal | AW9: =IF(AZ9=AZ10,AV10,IF(AZ9=AZ7,AV7,IF(AZ9=AZ8,AV8,""))) | AX9: =IF(AW9="","",IFERROR(VLOOKUP(CONCATENATE(AV9,"_",AW9),$AI$7:$AL$16,4,FALSE),VLOOKUP(CONCATENATE(AW9,"_",AV9),$AI$7:$AL$16,4,FALSE))) | AY9: =IF(AX9="",1,IF(AX9=AV9,1,0)) -> 1 | AZ9: =-AP9*10000000 - AQ9*10000 - AR9*100 -> -60010200 | BA9: =AZ9-AY9*10 -> -60010210 | BB9: =BA9+N25 -> -60010208
B10: 3 | C10: =IFERROR(VLOOKUP($B10,$AN$7:$AS$11,C$5,FALSE),"") -> Ecuador | D10: =IFERROR(VLOOKUP($B10,$AN$7:$AS$11,D$5,FALSE),"") -> 3 | E10: =IFERROR(VLOOKUP($B10,$AN$7:$AS$11,E$5,FALSE),"") -> 1 | F10: =IFERROR(VLOOKUP($B10,$AN$7:$AS$11,F$5,FALSE),"") -> 2 | G10: =IFERROR(VLOOKUP($B10,$AN$7:$AS$11,G$5,FALSE),"") -> -1 | I10: =I8+16 -> 18 | J10: 44890 | K10: Holanda | L10: 1 | M10: 0 | N10: Ecuador | AI10: =CONCATENATE(K10,"_",N10) -> Holanda_Ecuador | AJ10: =IF(L10>M10,3,IF(L10<M10,0,1)) -> 3 | AK10: =IF(AJ10=3,0,IF(AJ10=1,1,3)) -> 0 | AL10: =IF(AJ10>AK10,K10,IF(AK10>AJ10,N10,"SIN GANADOR")) -> Holanda | AN10: =_xlfn.RANK.EQ(BB10,BB$7:BB$11,1) -> 3 | AO10: Ecuador | AP10: =SUMIF($K$7:$K$12,AO10,$AJ$7:$AJ$12) + SUMIF($N$7:$N$12,AO10,$AK$7:$AK$12) -> 3 | AQ10: =AR10-AS10 -> -1 | AR10: =SUMIF($K$7:$K$12,AO10,$L$7:$L$12) + SUMIF($N$7:$N$12,AO10,$M$7:$M$12) -> 1 | AS10: =SUMIF($K$7:$K$12,AO10,$M$7:$M$12) + SUMIF($N$7:$N$12,AO10,$L$7:$L$12) -> 2 | AV10: =AO10 -> Ecuador | AW10: =IF(AZ10=AZ7,AV7,IF(AZ10=AZ8,AV8,IF(AZ10=AZ9,AV9,""))) | AX10: =IF(AW10="","",IFERROR(VLOOKUP(CONCATENATE(AV10,"_",AW10),$AI$7:$AL$16,4,FALSE),VLOOKUP(CONCATENATE(AW10,"_",AV10),$AI$7:$AL$16,4,FALSE))) | AY10: =IF(AX10="",1,IF(AX10=AV10,1,0)) -> 1 | AZ10: =-AP10*10000000 - AQ10*10000 - AR10*100 -> -29990100 | BA10: =AZ10-AY10*10 -> -29990110 | BB10: =BA10+N26 -> -29990107
B11: 4 | C11: =IFERROR(VLOOKUP($B11,$AN$7:$AS$11,C$5,FALSE),"") -> Qatar | D11: =IFERROR(VLOOKUP($B11,$AN$7:$AS$11,D$5,FALSE),"") -> 0 | E11: =IFERROR(VLOOKUP($B11,$AN$7:$AS$11,E$5,FALSE),"") -> 0 | F11: =IFERROR(VLOOKUP($B11,$AN$7:$AS$11,F$5,FALSE),"") -> 3 | G11: =IFERROR(VLOOKUP($B11,$AN$7:$AS$11,G$5,FALSE),"") -> -3 | I11: =I9+16 -> 33 | J11: 44894 | K11: Ecuador | L11: 0 | M11: 1 | N11: Senegal | AI11: =CONCATENATE(K11,"_",N11) -> Ecuador_Senegal | AJ11: =IF(L11>M11,3,IF(L11<M11,0,1)) -> 0 | AK11: =IF(AJ11=3,0,IF(AJ11=1,1,3)) -> 3 | AL11: =IF(AJ11>AK11,K11,IF(AK11>AJ11,N11,"SIN GANADOR")) -> Senegal
I12: =I10+16 -> 34 | J12: 44894 | K12: Holanda | L12: 1 | M12: 0 | N12: Qatar | AI12: =CONCATENATE(K12,"_",N12) -> Holanda_Qatar | AJ12: =IF(L12>M12,3,IF(L12<M12,0,1)) -> 3 | AK12: =IF(AJ12=3,0,IF(AJ12=1,1,3)) -> 0 | AL12: =IF(AJ12>AK12,K12,IF(AK12>AJ12,N12,"SIN GANADOR")) -> Holanda
B22: El recuadro de la derecha sirve para desempatar, en caso de que haya empate entre | I22: 1 | J22: Escoja por prioridad los siguientes equipos:
B23: uno o más equipos en todos los criterios considerados. | I23: =IF(J23="",0,1) -> 1 | J23: Qatar | M23: 4 | N23: =IF(J23="",0,M23) -> 4
B24: Para utilizarlo, asigne una prioridad entre 1 y 5 (siendo más bajo mejor) a cada equipo. | I24: =IF(J24="",0,1) -> 1 | J24: Holanda | M24: 1 | N24: =IF(J24="",0,M24) -> 1
B25: Puede pensarlo como el lugar que quedarían en la tabla de posiciones. | I25: =IF(J25="",0,1) -> 1 | J25: Senegal | M25: 2 | N25: =IF(J25="",0,M25) -> 2
B26: A modo de ejemplo, si su predicción es que todos los partidos terminan 0-0, el orden | I26: =IF(J26="",0,1) -> 1 | J26: Ecuador | M26: 3 | N26: =IF(J26="",0,M26) -> 3
B27: asignado en este recuadro es el que finalmente quedará en la tabla de posiciones. | N27: =IF(J27="",0,M27) -> 0

Sheet GRUPO B
B3: GRUPO B
C5: 2 | D5: 3 | E5: 5 | F5: 6 | G5: 4
B6: Tabla de Posiciones | J6: Fecha | K6: Partidos | AJ6: 1 | AK6: 2 | AL6: Ganador | AN6: Orden | AO6: Equipo | AP6: Puntos | AQ6: DG | AR6: GF | AS6: GC | AV6: Equipo | AW6: Empatado Con | AX6: Ganador | AY6: Ganador? | AZ6: Formula Rank | BA6: Formula Rank Con Duelo Directo | BB6: Formula Rank Con Prioridad
B7: Posición | C7: Equipo | D7: Puntos | E7: GF | F7: GC | G7: DG | I7: 3 | J7: 44886 | K7: Inglaterra | L7: 2 | M7: 0 | N7: Iran | AI7: =CONCATENATE(K7,"_",N7) -> Inglaterra_Iran | AJ7: =IF(L7>M7,3,IF(L7<M7,0,1)) -> 3 | AK7: =IF(AJ7=3,0,IF(AJ7=1,1,3)) -> 0 | AL7: =IF(AJ7>AK7,K7,IF(AK7>AJ7,N7,"SIN GANADOR")) -> Inglaterra | AN7: =_xlfn.RANK.EQ(BB7,BB$7:BB$11,1) -> 1 | AO7: Inglaterra | AP7: =SUMIF($K$7:$K$12,AO7,$AJ$7:$AJ$12) + SUMIF($N$7:$N$12,AO7,$AK$7:$AK$12) -> 9 | AQ7: =AR7-AS7 -> 4 | AR7: =SUMIF($K$7:$K$12,AO7,$L$7:$L$12) + SUMIF($N$7:$N$12,AO7,$M$7:$M$12) -> 5 | AS7: =SUMIF($K$7:$K$12,AO7,$M$7:$M$12) + SUMIF($N$7:$N$12,AO7,$L$7:$L$12) -> 1 | AV7: =AO7 -> Inglaterra | AW7: =IF(AZ7=AZ8,AV8,IF(AZ7=AZ9,AV9,IF(AZ7=AZ10,AV10,""))) | AX7: =IF(AW7="","",IFERROR(VLOOKUP(CONCATENATE(AV7,"_",AW7),$AI$7:$AL$16,4,FALSE),VLOOKUP(CONCATENATE(AW7,"_",AV7),$AI$7:$AL$16,4,FALSE))) | AY7: =IF(AX7="",1,IF(AX7=AV7,1,0)) -> 1 | AZ7: =-AP7*10000000 - AQ7*10000 - AR7*100 -> -90040500 | BA7: =AZ7-AY7*10 -> -90040510 | BB7: =BA7+N23 -> -90040509
B8: 1 | C8: =IFERROR(VLOOKUP($B8,$AN$7:$AS$11,C$5,FALSE),"") -> Inglaterra | D8: =IFERROR(VLOOKUP($B8,$AN$7:$AS$11,D$5,FALSE),"") -> 9 | E8: =IFERROR(VLOOKUP($B8,$AN$7:$AS$11,E$5,FALSE),"") -> 5 | F8: =IFERROR(VLOOKUP($B8,$AN$7:$AS$11,F$5,FALSE),"") -> 1 | G8: =IFERROR(VLOOKUP($B8,$AN$7:$AS$11,G$5,FALSE),"") -> 4 | I8: 4 | J8: 44886 | K8: USA | L8: 1 | M8: 1 | N8: Gales | AI8: =CONCATENATE(K8,"_",N8) -> USA_Gales | AJ8: =IF(L8>M8,3,IF(L8<M8,0,1)) -> 1 | AK8: =IF(AJ8=3,0,IF(AJ8=1,1,3)) -> 1 | AL8: =IF(AJ8>AK8,K8,IF(AK8>AJ8,N8,"SIN GANADOR")) -> SIN GANADOR | AN8: =_xlfn.RANK.EQ(BB8,BB$7:BB$11,1) -> 3 | AO8: USA | AP8: =SUMIF($K$7:$K$12,AO8,$AJ$7:$AJ$12) + SUMIF($N$7:$N$12,AO8,$AK$7:$AK$12) -> 2 | AQ8: =AR8-AS8 -> -1 | AR8: =SUMIF($K$7:$K$12,AO8,$L$7:$L$12) + SUMIF($N$7:$N$12,AO8,$M$7:$M$12) -> 2 | AS8: =SUMIF($K$7:$K$12,AO8,$M$7:$M$12) + SUMIF($N$7:$N$12,AO8,$L$7:$L$12) -> 3 | AV8: =AO8 -> USA | AW8: =IF(AZ8=AZ9,AV9,IF(AZ8=AZ10,AV10,IF(AZ8=AZ7,AV7,""))) -> Gales | AX8: =IF(AW8="","",IFERROR(VLOOKUP(CONCATENATE(AV8,"_",AW8),$AI$7:$AL$16,4,FALSE),VLOOKUP(CONCATENATE(AW8,"_",AV8),$AI$7:$AL$16,4,FALSE))) -> SIN GANADOR | AY8: =IF(AX8="",1,IF(AX8=AV8,1,0)) -> 0 | AZ8: =-AP8*10000000 - AQ8*10000 - AR8*100 -> -19990200 | BA8: =AZ8-AY8*10 -> -19990200 | BB8: =BA8+N24 -> -19990197
B9: 2 | C9: =IFERROR(VLOOKUP($B9,$AN$7:$AS$11,C$5,FALSE),"") -> Gales | D9: =IFERROR(VLOOKUP($B9,$AN$7:$AS$11,D$5,FALSE),"") -> 2 | E9: =IFERROR(VLOOKUP($B9,$AN$7:$AS$11,E$5,FALSE),"") -> 2 | F9: =IFERROR(VLOOKUP($B9,$AN$7:$AS$11,F$5,FALSE),"") -> 3 | G9: =IFERROR(VLOOKUP($B9,$AN$7:$AS$11,G$5,FALSE),"") -> -1 | I9: =I7+16 -> 19 | J9: 44890 | K9: Gales | L9: 0 | M9: 0 | N9: Iran | AI9: =CONCATENATE(K9,"_",N9) -> Gales_Iran | AJ9: =IF(L9>M9,3,IF(L9<M9,0,1)) -> 1 | AK9: =IF(AJ9=3,0,IF(AJ9=1,1,3)) -> 1 | AL9: =IF(AJ9>AK9,K9,IF(AK9>AJ9,N9,"SIN GANADOR")) -> SIN GANADOR | AN9: =_xlfn.RANK.EQ(BB9,BB$7:BB$11,1) -> 4 | AO9: Iran | AP9: =SUMIF($K$7:$K$12,AO9,$AJ$7:$AJ$12) + SUMIF($N$7:$N$12,AO9,$AK$7:$AK$12) -> 2 | AQ9: =AR9-AS9 -> -2 | AR9: =SUMIF($K$7:$K$12,AO9,$L$7:$L$12) + SUMIF($N$7:$N$12,AO9,$M$7:$M$12) -> 1 | AS9: =SUMIF($K$7:$K$12,AO9,$M$7:$M$12) + SUMIF($N$7:$N$12,AO9,$L$7:$L$12) -> 3 | AV9: =AO9 -> Iran | AW9: =IF(AZ9=AZ10,AV10,IF(AZ9=AZ7,AV7,IF(AZ9=AZ8,AV8,""))) | AX9: =IF(AW9="","",IFERROR(VLOOKUP(CONCATENATE(AV9,"_",AW9),$AI$7:$AL$16,4,FALSE),VLOOKUP(CONCATENATE(AW9,"_",AV9),$AI$7:$AL$16,4,FALSE))) | AY9: =IF(AX9="",1,IF(AX9=AV9,1,0)) -> 1 | AZ9: =-AP9*10000000 - AQ9*10000 - AR9*100 -> -19980100 | BA9: =AZ9-AY9*10 -> -19980110 | BB9: =BA9+N25 -> -19980106
B10: 3 | C10: =IFERROR(VLOOKUP($B10,$AN$7:$AS$11,C$5,FALSE),"") -> USA | D10: =IFERROR(VLOOKUP($B10,$AN$7:$AS$11,D$5,FALSE),"") -> 2 | E10: =IFERROR(VLOOKUP($B10,$AN$7:$AS$11,E$5,FALSE),"") -> 2 | F10: =IFERROR(VLOOKUP($B10,$AN$7:$AS$11,F$5,FALSE),"") -> 3 | G10: =IFERROR(VLOOKUP($B10,$AN$7:$AS$11,G$5,FALSE),"") -> -1 | I10: =I8+16 -> 20 | J10: 44890 | K10: Inglaterra | L10: 1 | M10: 0 | N10: USA | AI10: =CONCATENATE(K10,"_",N10) -> Inglaterra_USA | AJ10: =IF(L10>M10,3,IF(L10<M10,0,1)) -> 3 | AK10: =IF(AJ10=3,0,IF(AJ10=1,1,3)) -> 0 | AL10: =IF(AJ10>AK10,K10,IF(AK10>AJ10,N10,"SIN GANADOR")) -> Inglaterra | AN10: =_xlfn.RANK.EQ(BB10,BB$7:BB$11,1) -> 2 | AO10: Gales | AP10: =SUMIF($K$7:$K$12,AO10,$AJ$7:$AJ$12) + SUMIF($N$7:$N$12,AO10,$AK$7:$AK$12) -> 2 | AQ10: =AR10-AS10 -> -1 | AR10: =SUMIF($K$7:$K$12,AO10,$L$7:$L$12) + SUMIF($N$7:$N$12,AO10,$M$7:$M$12) -> 2 | AS10: =SUMIF($K$7:$K$12,AO10,$M$7:$M$12) + SUMIF($N$7:$N$12,AO10,$L$7:$L$12) -> 3 | AV10: =AO10 -> Gales | AW10: =IF(AZ10=AZ7,AV7,IF(AZ10=AZ8,AV8,IF(AZ10=AZ9,AV9,""))) -> USA | AX10: =IF(AW10="","",IFERROR(VLOOKUP(CONCATENATE(AV10,"_",AW10),$AI$7:$AL$16,4,FALSE),VLOOKUP(CONCATENATE(AW10,"_",AV10),$AI$7:$AL$16,4,FALSE))) -> SIN GANADOR | AY10: =IF(AX10="",1,IF(AX10=AV10,1,0)) -> 0 | AZ10: =-AP10*10000000 - AQ10*10000 - AR10*100 -> -19990200 | BA10: =AZ10-AY10*10 -> -19990200 | BB10: =BA10+N26 -> -19990198
B11: 4 | C11: =IFERROR(VLOOKUP($B11,$AN$7:$AS$11,C$5,FALSE),"") -> Iran | D11: =IFERROR(VLOOKUP($B11,$AN$7:$AS$11,D$5,FALSE),"") -> 2 | E11: =IFERROR(VLOOKUP($B11,$AN$7:$AS$11,E$5,FALSE),"") -> 1 | F11: =IFERROR(VLOOKUP($B11,$AN$7:$AS$11,F$5,FALSE),"") -> 3 | G11: =IFERROR(VLOOKUP($B11,$AN$7:$AS$11,G$5,FALSE),"") -> -2 | I11: =I9+16 -> 35 | J11: 44894 | K11: Gales | L11: 1 | M11: 2 | N11: Inglaterra | AI11: =CONCATENATE(K11,"_",N11) -> Gales_Inglaterra | AJ11: =IF(L11>M11,3,IF(L11<M11,0,1)) -> 0 | AK11: =IF(AJ11=3,0,IF(AJ11=1,1,3)) -> 3 | AL11: =IF(AJ11>AK11,K11,IF(AK11>AJ11,N11,"SIN GANADOR")) -> Inglaterra
I12: =I10+16 -> 36 | J12: 44894 | K12: Iran | L12: 1 | M12: 1 | N12: USA | AI12: =CONCATENATE(K12,"_",N12) -> Iran_USA | AJ12: =IF(L12>M12,3,IF(L12<M12,0,1)) -> 1 | AK12: =IF(AJ12=3,0,IF(AJ12=1,1,3)) -> 1 | AL12: =IF(AJ12>AK12,K12,IF(AK12>AJ12,N12,"SIN GANADOR")) -> SIN GANADOR
B22: El recuadro de la derecha sirve para desempatar, en caso de que haya empate entre | I22: 1 | J22: Escoja por prioridad los siguientes equipos:
B23: uno o más equipos en todos los criterios considerados. | I23: =IF(J23="",0,1) -> 1 | J23: Inglaterra | M23: 1 | N23: =IF(J23="",0,M23) -> 1
B24: Para utilizarlo, asigne una prioridad entre 1 y 5 (siendo más bajo mejor) a cada equipo. | I24: =IF(J24="",0,1) -> 1 | J24: USA | M24: 3 | N24: =IF(J24="",0,M24) -> 3
B25: Puede pensarlo como el lugar que quedarían en la tabla de posiciones. | I25: =IF(J25="",0,1) -> 1 | J25: Iran | M25: 4 | N25: =IF(J25="",0,M25) -> 4
B26: A modo de ejemplo, si su predicción es que todos los partidos terminan 0-0, el orden | I26: =IF(J26="",0,1) -> 1 | J26: Gales | M26: 2 | N26: =IF(J26="",0,M26) -> 2
B27: asignado en este recuadro es el que finalmente quedará en la tabla de posiciones. | N27: =IF(J27="",0,M27) -> 0

Sheet GRUPO C
B3: GRUPO C
C5: 2 | D5: 3 | E5: 5 | F5: 6 | G5: 4
B6: Tabla de Posiciones | J6: Fecha | K6: Partidos | AJ6: 1 | AK6: 2 | AL6: Ganador | AN6: Orden | AO6: Equipo | AP6: Puntos | AQ6: DG | AR6: GF | AS6: GC | AV6: Equipo | AW6: Empatado Con | AX6: Ganador | AY6: Ganador? | AZ6: Formula Rank | BA6: Formula Rank Con Duelo Directo | BB6: Formula Rank Con Prioridad
B7: Posición | C7: Equipo | D7: Puntos | E7: GF | F7: GC | G7: DG | I7: 5 | J7: 44887 | K7: Mexico | L7: 0 | M7: 1 | N7: Polonia | AI7: =CONCATENATE(K7,"_",N7) -> Mexico_Polonia | AJ7: =IF(L7>M7,3,IF(L7<M7,0,1)) -> 0 | AK7: =IF(AJ7=3,0,IF(AJ7=1,1,3)) -> 3 | AL7: =IF(AJ7>AK7,K7,IF(AK7>AJ7,N7,"SIN GANADOR")) -> Polonia | AN7: =_xlfn.RANK.EQ(BB7,BB$7:BB$11,1) -> 1 | AO7: Argentina | AP7: =SUMIF($K$7:$K$12,AO7,$AJ$7:$AJ$12) + SUMIF($N$7:$N$12,AO7,$AK$7:$AK$12) -> 9 | AQ7: =AR7-AS7 -> 7 | AR7: =SUMIF($K$7:$K$12,AO7,$L$7:$L$12) + SUMIF($N$7:$N$12,AO7,$M$7:$M$12) -> 8 | AS7: =SUMIF($K$7:$K$12,AO7,$M$7:$M$12) + SUMIF($N$7:$N$12,AO7,$L$7:$L$12) -> 1 | AV7: =AO7 -> Argentina | AW7: =IF(AZ7=AZ8,AV8,IF(AZ7=AZ9,AV9,IF(AZ7=AZ10,AV10,""))) | AX7: =IF(AW7="","",IFERROR(VLOOKUP(CONCATENATE(AV7,"_",AW7),$AI$7:$AL$16,4,FALSE),VLOOKUP(CONCATENATE(AW7,"_",AV7),$AI$7:$AL$16,4,FALSE))) | AY7: =IF(AX7="",1,IF(AX7=AV7,1,0)) -> 1 | AZ7: =-AP7*10000000 - AQ7*10000 - AR7*100 -> -90070800 | BA7: =AZ7-AY7*10 -> -90070810 | BB7: =BA7+N23 -> -90070809
B8: 1 | C8: =IFERROR(VLOOKUP($B8,$AN$7:$AS$11,C$5,FALSE),"") -> Argentina | D8: =IFERROR(VLOOKUP($B8,$AN$7:$AS$11,D$5,FALSE),"") -> 9 | E8: =IFERROR(VLOOKUP($B8,$AN$7:$AS$11,E$5,FALSE),"") -> 8 | F8: =IFERROR(VLOOKUP($B8,$AN$7:$AS$11,F$5,FALSE),"") -> 1 | G8: =IFERROR(VLOOKUP($B8,$AN$7:$AS$11,G$5,FALSE),"") -> 7 | I8: 6 | J8: 44887 | K8: Argentina | L8: 3 | M8: 0 | N8: Arabia Saudita | AI8: =CONCATENATE(K8,"_",N8) -> Argentina_Arabia Saudita | AJ8: =IF(L8>M8,3,IF(L8<M8,0,1)) -> 3 | AK8: =IF(AJ8=3,0,IF(AJ8=1,1,3)) -> 0 | AL8: =IF(AJ8>AK8,K8,IF(AK8>AJ8,N8,"SIN GANADOR")) -> Argentina | AN8: =_xlfn.RANK.EQ(BB8,BB$7:BB$11,1) -> 3 | AO8: Mexico | AP8: =SUMIF($K$7:$K$12,AO8,$AJ$7:$AJ$12) + SUMIF($N$7:$N$12,AO8,$AK$7:$AK$12) -> 1 | AQ8: =AR8-AS8 -> -3 | AR8: =SUMIF($K$7:$K$12,AO8,$L$7:$L$12) + SUMIF($N$7:$N$12,AO8,$M$7:$M$12) -> 0 | AS8: =SUMIF($K$7:$K$12,AO8,$M$7:$M$12) + SUMIF($N$7:$N$12,AO8,$L$7:$L$12) -> 3 | AV8: =AO8 -> Mexico | AW8: =IF(AZ8=AZ9,AV9,IF(AZ8=AZ10,AV10,IF(AZ8=AZ7,AV7,""))) | AX8: =IF(AW8="","",IFERROR(VLOOKUP(CONCATENATE(AV8,"_",AW8),$AI$7:$AL$16,4,FALSE),VLOOKUP(CONCATENATE(AW8,"_",AV8),$AI$7:$AL$16,4,FALSE))) | AY8: =IF(AX8="",1,IF(AX8=AV8,1,0)) -> 1 | AZ8: =-AP8*10000000 - AQ8*10000 - AR8*100 -> -9970000 | BA8: =AZ8-AY8*10 -> -9970010 | BB8: =BA8+N24 -> -9970007
B9: 2 | C9: =IFERROR(VLOOKUP($B9,$AN$7:$AS$11,C$5,FALSE),"") -> Polonia | D9: =IFERROR(VLOOKUP($B9,$AN$7:$AS$11,D$5,FALSE),"") -> 6 | E9: =IFERROR(VLOOKUP($B9,$AN$7:$AS$11,E$5,FALSE),"") -> 4 | F9: =IFERROR(VLOOKUP($B9,$AN$7:$AS$11,F$5,FALSE),"") -> 3 | G9: =IFERROR(VLOOKUP($B9,$AN$7:$AS$11,G$5,FALSE),"") -> 1 | I9: =I7+16 -> 21 | J9: 44891 | K9: Polonia | L9: 2 | M9: 0 | N9: Arabia Saudita | AI9: =CONCATENATE(K9,"_",N9) -> Polonia_Arabia Saudita | AJ9: =IF(L9>M9,3,IF(L9<M9,0,1)) -> 3 | AK9: =IF(AJ9=3,0,IF(AJ9=1,1,3)) -> 0 | AL9: =IF(AJ9>AK9,K9,IF(AK9>AJ9,N9,"SIN GANADOR")) -> Polonia | AN9: =_xlfn.RANK.EQ(BB9,BB$7:BB$11,1) -> 2 | AO9: Polonia | AP9: =SUMIF($K$7:$K$12,AO9,$AJ$7:$AJ$12) + SUMIF($N$7:$N$12,AO9,$AK$7:$AK$12) -> 6 | AQ9: =AR9-AS9 -> 1 | AR9: =SUMIF($K$7:$K$12,AO9,$L$7:$L$12) + SUMIF($N$7:$N$12,AO9,$M$7:$M$12) -> 4 | AS9: =SUMIF($K$7:$K$12,AO9,$M$7:$M$12) + SUMIF($N$7:$N$12,AO9,$L$7:$L$12) -> 3 | AV9: =AO9 -> Polonia | AW9: =IF(AZ9=AZ10,AV10,IF(AZ9=AZ7,AV7,IF(AZ9=AZ8,AV8,""))) | AX9: =IF(AW9="","",IFERROR(VLOOKUP(CONCATENATE(AV9,"_",AW9),$AI$7:$AL$16,4,FALSE),VLOOKUP(CONCATENATE(AW9,"_",AV9),$AI$7:$AL$16,4,FALSE))) | AY9: =IF(AX9="",1,IF(AX9=AV9,1,0)) -> 1 | AZ9: =-AP9*10000000 - AQ9*10000 - AR9*100 -> -60010400 | BA9: =AZ9-AY9*10 -> -60010410 | BB9: =BA9+N25 -> -60010408
B10: 3 | C10: =IFERROR(VLOOKUP($B10,$AN$7:$AS$11,C$5,FALSE),"") -> Mexico | D10: =IFERROR(VLOOKUP($B10,$AN$7:$AS$11,D$5,FALSE),"") -> 1 | E10: =IFERROR(VLOOKUP($B10,$AN$7:$AS$11,E$5,FALSE),"") -> 0 | F10: =IFERROR(VLOOKUP($B10,$AN$7:$AS$11,F$5,FALSE),"") -> 3 | G10: =IFERROR(VLOOKUP($B10,$AN$7:$AS$11,G$5,FALSE),"") -> -3 | I10: =I8+16 -> 22 | J10: 44891 | K10: Argentina | L10: 2 | M10: 0 | N10: Mexico | AI10: =CONCATENATE(K10,"_",N10) -> Argentina_Mexico | AJ10: =IF(L10>M10,3,IF(L10<M10,0,1)) -> 3 | AK10: =IF(AJ10=3,0,IF(AJ10=1,1,3)) -> 0 | AL10: =IF(AJ10>AK10,K10,IF(AK10>AJ10,N10,"SIN GANADOR")) -> Argentina | AN10: =_xlfn.RANK.EQ(BB10,BB$7:BB$11,1) -> 4 | AO10: Arabia Saudita | AP10: =SUMIF($K$7:$K$12,AO10,$AJ$7:$AJ$12) + SUMIF($N$7:$N$12,AO10,$AK$7:$AK$12) -> 1 | AQ10: =AR10-AS10 -> -5 | AR10: =SUMIF($K$7:$K$12,AO10,$L$7:$L$12) + SUMIF($N$7:$N$12,AO10,$M$7:$M$12) -> 0 | AS10: =SUMIF($K$7:$K$12,AO10,$M$7:$M$12) + SUMIF($N$7:$N$12,AO10,$L$7:$L$12) -> 5 | AV10: =AO10 -> Arabia Saudita | AW10: =IF(AZ10=AZ7,AV7,IF(AZ10=AZ8,AV8,IF(AZ10=AZ9,AV9,""))) | AX10: =IF(AW10="","",IFERROR(VLOOKUP(CONCATENATE(AV10,"_",AW10),$AI$7:$AL$16,4,FALSE),VLOOKUP(CONCATENATE(AW10,"_",AV10),$AI$7:$AL$16,4,FALSE))) | AY10: =IF(AX10="",1,IF(AX10=AV10,1,0)) -> 1 | AZ10: =-AP10*10000000 - AQ10*10000 - AR10*100 -> -9950000 | BA10: =AZ10-AY10*10 -> -9950010 | BB10: =BA10+N26 -> -9950006
B11: 4 | C11: =IFERROR(VLOOKUP($B11,$AN$7:$AS$11,C$5,FALSE),"") -> Arabia Saudita | D11: =IFERROR(VLOOKUP($B11,$AN$7:$AS$11,D$5,FALSE),"") -> 1 | E11: =IFERROR(VLOOKUP($B11,$AN$7:$AS$11,E$5,FALSE),"") -> 0 | F11: =IFERROR(VLOOKUP($B11,$AN$7:$AS$11,F$5,FALSE),"") -> 5 | G11: =IFERROR(VLOOKUP($B11,$AN$7:$AS$11,G$5,FALSE),"") -> -5 | I11: =I9+16 -> 37 | J11: 44895 | K11: Polonia | L11: 1 | M11: 3 | N11: Argentina | AI11: =CONCATENATE(K11,"_",N11) -> Polonia_Argentina | AJ11: =IF(L11>M11,3,IF(L11<M11,0,1)) -> 0 | AK11: =IF(AJ11=3,0,IF(AJ11=1,1,3)) -> 3 | AL11: =IF(AJ11>AK11,K11,IF(AK11>AJ11,N11,"SIN GANADOR")) -> Argentina
I12: =I10+16 -> 38 | J12: 44895 | K12: Arabia Saudita | L12: 0 | M12: 0 | N12: Mexico | AI12: =CONCATENATE(K12,"_",N12) -> Arabia Saudita_Mexico | AJ12: =IF(L12>M12,3,IF(L12<M12,0,1)) -> 1 | AK12: =IF(AJ12=3,0,IF(AJ12=1,1,3)) -> 1 | AL12: =IF(AJ12>AK12,K12,IF(AK12>AJ12,N12,"SIN GANADOR")) -> SIN GANADOR
B22: El recuadro de la derecha sirve para desempatar, en caso de que haya empate entre | I22: 1 | J22: Escoja por prioridad los siguientes equipos:
B23: uno o más equipos en todos los criterios considerados. | I23: =IF(J23="",0,1) -> 1 | J23: Argentina | M23: 1 | N23: =IF(J23="",0,M23) -> 1
B24: Para utilizarlo, asigne una prioridad entre 1 y 5 (siendo más bajo mejor) a cada equipo. | I24: =IF(J24="",0,1) -> 1 | J24: Mexico | M24: 3 | N24: =IF(J24="",0,M24) -> 3
B25: Puede pensarlo como el lugar que quedarían en la tabla de posiciones. | I25: =IF(J25="",0,1) -> 1 | J25: Polonia | M25: 2 | N25: =IF(J25="",0,M25) -> 2
B26: A modo de ejemplo, si su predicción es que todos los partidos terminan 0-0, el orden | I26: =IF(J26="",0,1) -> 1 | J26: Arabia Saudita | M26: 4 | N26: =IF(J26="",0,M26) -> 4
B27: asignado en este recuadro es el que finalmente quedará en la tabla de posiciones. | N27: =IF(J27="",0,M27) -> 0

Sheet GRUPO D
B3: GRUPO D
C5: 2 | D5: 3 | E5: 5 | F5: 6 | G5: 4
B6: Tabla de Posiciones | J6: Fecha | K6: Partidos | AJ6: 1 | AK6: 2 | AL6: Ganador | AN6: Orden | AO6: Equipo | AP6: Puntos | AQ6: DG | AR6: GF | AS6: GC | AV6: Equipo | AW6: Empatado Con | AX6: Ganador | AY6: Ganador? | AZ6: Formula Rank | BA6: Formula Rank Con Duelo Directo | BB6: Formula Rank Con Prioridad
B7: Posición | C7: Equipo | D7: Puntos | E7: GF | F7: GC | G7: DG | I7: 7 | J7: 44887 | K7: Dinamarca | L7: 1 | M7: 0 | N7: Tunez | AI7: =CONCATENATE(K7,"_",N7) -> Dinamarca_Tunez | AJ7: =IF(L7>M7,3,IF(L7<M7,0,1)) -> 3 | AK7: =IF(AJ7=3,0,IF(AJ7=1,1,3)) -> 0 | AL7: =IF(AJ7>AK7,K7,IF(AK7>AJ7,N7,"SIN GANADOR")) -> Dinamarca | AN7: =_xlfn.RANK.EQ(BB7,BB$7:BB$11,1) -> 1 | AO7: Francia | AP7: =SUMIF($K$7:$K$12,AO7,$AJ$7:$AJ$12) + SUMIF($N$7:$N$12,AO7,$AK$7:$AK$12) -> 9 | AQ7: =AR7-AS7 -> 8 | AR7: =SUMIF($K$7:$K$12,AO7,$L$7:$L$12) + SUMIF($N$7:$N$12,AO7,$M$7:$M$12) -> 9 | AS7: =SUMIF($K$7:$K$12,AO7,$M$7:$M$12) + SUMIF($N$7:$N$12,AO7,$L$7:$L$12) -> 1 | AV7: =AO7 -> Francia | AW7: =IF(AZ7=AZ8,AV8,IF(AZ7=AZ9,AV9,IF(AZ7=AZ10,AV10,""))) | AX7: =IF(AW7="","",IFERROR(VLOOKUP(CONCATENATE(AV7,"_",AW7),$AI$7:$AL$16,4,FALSE),VLOOKUP(CONCATENATE(AW7,"_",AV7),$AI$7:$AL$16,4,FALSE))) | AY7: =IF(AX7="",1,IF(AX7=AV7,1,0)) -> 1 | AZ7: =-AP7*10000000 - AQ7*10000 - AR7*100 -> -90080900 | BA7: =AZ7-AY7*10 -> -90080910 | BB7: =BA7+N23 -> -90080909
B8: 1 | C8: =IFERROR(VLOOKUP($B8,$AN$7:$AS$11,C$5,FALSE),"") -> Francia | D8: =IFERROR(VLOOKUP($B8,$AN$7:$AS$11,D$5,FALSE),"") -> 9 | E8: =IFERROR(VLOOKUP($B8,$AN$7:$AS$11,E$5,FALSE),"") -> 9 | F8: =IFERROR(VLOOKUP($B8,$AN$7:$AS$11,F$5,FALSE),"") -> 1 | G8: =IFERROR(VLOOKUP($B8,$AN$7:$AS$11,G$5,FALSE),"") -> 8 | I8: 8 | J8: 44887 | K8: Francia | L8: 3 | M8: 0 | N8: Australia | AI8: =CONCATENATE(K8,"_",N8) -> Francia_Australia | AJ8: =IF(L8>M8,3,IF(L8<M8,0,1)) -> 3 | AK8: =IF(AJ8=3,0,IF(AJ8=1,1,3)) -> 0 | AL8: =IF(AJ8>AK8,K8,IF(AK8>AJ8,N8,"SIN GANADOR")) -> Francia | AN8: =_xlfn.RANK.EQ(BB8,BB$7:BB$11,1) -> 2 | AO8: Dinamarca | AP8: =SUMIF($K$7:$K$12,AO8,$AJ$7:$AJ$12) + SUMIF($N$7:$N$12,AO8,$AK$7:$AK$12) -> 4 | AQ8: =AR8-AS8 -> -2 | AR8: =SUMIF($K$7:$K$12,AO8,$L$7:$L$12) + SUMIF($N$7:$N$12,AO8,$M$7:$M$12) -> 1 | AS8: =SUMIF($K$7:$K$12,AO8,$M$7:$M$12) + SUMIF($N$7:$N$12,AO8,$L$7:$L$12) -> 3 | AV8: =AO8 -> Dinamarca | AW8: =IF(AZ8=AZ9,AV9,IF(AZ8=AZ10,AV10,IF(AZ8=AZ7,AV7,""))) | AX8: =IF(AW8="","",IFERROR(VLOOKUP(CONCATENATE(AV8,"_",AW8),$AI$7:$AL$16,4,FALSE),VLOOKUP(CONCATENATE(AW8,"_",AV8),$AI$7:$AL$16,4,FALSE))) | AY8: =IF(AX8="",1,IF(AX8=AV8,1,0)) -> 1 | AZ8: =-AP8*10000000 - AQ8*10000 - AR8*100 -> -39980100 | BA8: =AZ8-AY8*10 -> -39980110 | BB8: =BA8+N24 -> -39980108
B9: 2 | C9: =IFERROR(VLOOKUP($B9,$AN$7:$AS$11,C$5,FALSE),"") -> Dinamarca | D9: =IFERROR(VLOOKUP($B9,$AN$7:$AS$11,D$5,FALSE),"") -> 4 | E9: =IFERROR(VLOOKUP($B9,$AN$7:$AS$11,E$5,FALSE),"") -> 1 | F9: =IFERROR(VLOOKUP($B9,$AN$7:$AS$11,F$5,FALSE),"") -> 3 | G9: =IFERROR(VLOOKUP($B9,$AN$7:$AS$11,G$5,FALSE),"") -> -2 | I9: =I7+16 -> 23 | J9: 44891 | K9: Tunez | L9: 1 | M9: 0 | N9: Australia | AI9: =CONCATENATE(K9,"_",N9) -> Tunez_Australia | AJ9: =IF(L9>M9,3,IF(L9<M9,0,1)) -> 3 | AK9: =IF(AJ9=3,0,IF(AJ9=1,1,3)) -> 0 | AL9: =IF(AJ9>AK9,K9,IF(AK9>AJ9,N9,"SIN GANADOR")) -> Tunez | AN9: =_xlfn.RANK.EQ(BB9,BB$7:BB$11,1) -> 3 | AO9: Tunez | AP9: =SUMIF($K$7:$K$12,AO9,$AJ$7:$AJ$12) + SUMIF($N$7:$N$12,AO9,$AK$7:$AK$12) -> 3 | AQ9: =AR9-AS9 -> -2 | AR9: =SUMIF($K$7:$K$12,AO9,$L$7:$L$12) + SUMIF($N$7:$N$12,AO9,$M$7:$M$12) -> 2 | AS9: =SUMIF($K$7:$K$12,AO9,$M$7:$M$12) + SUMIF($N$7:$N$12,AO9,$L$7:$L$12) -> 4 | AV9: =AO9 -> Tunez | AW9: =IF(AZ9=AZ10,AV10,IF(AZ9=AZ7,AV7,IF(AZ9=AZ8,AV8,""))) | AX9: =IF(AW9="","",IFERROR(VLOOKUP(CONCATENATE(AV9,"_",AW9),$AI$7:$AL$16,4,FALSE),VLOOKUP(CONCATENATE(AW9,"_",AV9),$AI$7:$AL$16,4,FALSE))) | AY9: =IF(AX9="",1,IF(AX9=AV9,1,0)) -> 1 | AZ9: =-AP9*10000000 - AQ9*10000 - AR9*100 -> -29980200 | BA9: =AZ9-AY9*10 -> -29980210 | BB9: =BA9+N25 -> -29980207
B10: 3 | C10: =IFERROR(VLOOKUP($B10,$AN$7:$AS$11,C$5,FALSE),"") -> Tunez | D10: =IFERROR(VLOOKUP($B10,$AN$7:$AS$11,D$5,FALSE),"") -> 3 | E10: =IFERROR(VLOOKUP($B10,$AN$7:$AS$11,E$5,FALSE),"") -> 2 | F10: =IFERROR(VLOOKUP($B10,$AN$7:$AS$11,F$5,FALSE),"") -> 4 | G10: =IFERROR(VLOOKUP($B10,$AN$7:$AS$11,G$5,FALSE),"") -> -2 | I10: =I8+16 -> 24 | J10: 44891 | K10: Francia | L10: 3 | M10: 0 | N10: Dinamarca | AI10: =CONCATENATE(K10,"_",N10) -> Francia_Dinamarca | AJ10: =IF(L10>M10,3,IF(L10<M10,0,1)) -> 3 | AK10: =IF(AJ10=3,0,IF(AJ10=1,1,3)) -> 0 | AL10: =IF(AJ10>AK10,K10,IF(AK10>AJ10,N10,"SIN GANADOR")) -> Francia | AN10: =_xlfn.RANK.EQ(BB10,BB$7:BB$11,1) -> 4 | AO10: Australia | AP10: =SUMIF($K$7:$K$12,AO10,$AJ$7:$AJ$12) + SUMIF($N$7:$N$12,AO10,$AK$7:$AK$12) -> 1 | AQ10: =AR10-AS10 -> -4 | AR10: =SUMIF($K$7:$K$12,AO10,$L$7:$L$12) + SUMIF($N$7:$N$12,AO10,$M$7:$M$12) -> 0 | AS10: =SUMIF($K$7:$K$12,AO10,$M$7:$M$12) + SUMIF($N$7:$N$12,AO10,$L$7:$L$12) -> 4 | AV10: =AO10 -> Australia | AW10: =IF(AZ10=AZ7,AV7,IF(AZ10=AZ8,AV8,IF(AZ10=AZ9,AV9,""))) | AX10: =IF(AW10="","",IFERROR(VLOOKUP(CONCATENATE(AV10,"_",AW10),$AI$7:$AL$16,4,FALSE),VLOOKUP(CONCATENATE(AW10,"_",AV10),$AI$7:$AL$16,4,FALSE))) | AY10: =IF(AX10="",1,IF(AX10=AV10,1,0)) -> 1 | AZ10: =-AP10*10000000 - AQ10*10000 - AR10*100 -> -9960000 | BA10: =AZ10-AY10*10 -> -9960010 | BB10: =BA10+N26 -> -9960006
B11: 4 | C11: =IFERROR(VLOOKUP($B11,$AN$7:$AS$11,C$5,FALSE),"") -> Australia | D11: =IFERROR(VLOOKUP($B11,$AN$7:$AS$11,D$5,FALSE),"") -> 1 | E11: =IFERROR(VLOOKUP($B11,$AN$7:$AS$11,E$5,FALSE),"") -> 0 | F11: =IFERROR(VLOOKUP($B11,$AN$7:$AS$11,F$5,FALSE),"") -> 4 | G11: =IFERROR(VLOOKUP($B11,$AN$7:$AS$11,G$5,FALSE),"") -> -4 | I11: =I9+16 -> 39 | J11: 44895 | K11: Tunez | L11: 1 | M11: 3 | N11: Francia | AI11: =CONCATENATE(K11,"_",N11) -> Tunez_Francia | AJ11: =IF(L11>M11,3,IF(L11<M11,0,1)) -> 0 | AK11: =IF(AJ11=3,0,IF(AJ11=1,1,3)) -> 3 | AL11: =IF(AJ11>AK11,K11,IF(AK11>AJ11,N11,"SIN GANADOR")) -> Francia
I12: =I10+16 -> 40 | J12: 44895 | K12: Australia | L12: 0 | M12: 0 | N12: Dinamarca | AI12: =CONCATENATE(K12,"_",N12) -> Australia_Dinamarca | AJ12: =IF(L12>M12,3,IF(L12<M12,0,1)) -> 1 | AK12: =IF(AJ12=3,0,IF(AJ12=1,1,3)) -> 1 | AL12: =IF(AJ12>AK12,K12,IF(AK12>AJ12,N12,"SIN GANADOR")) -> SIN GANADOR
B22: El recuadro de la derecha sirve para desempatar, en caso de que haya empate entre | I22: 1 | J22: Escoja por prioridad los siguientes equipos:
B23: uno o más equipos en todos los criterios considerados. | I23: =IF(J23="",0,1) -> 1 | J23: Francia | M23: 1 | N23: =IF(J23="",0,M23) -> 1
B24: Para utilizarlo, asigne una prioridad entre 1 y 5 (siendo más bajo mejor) a cada equipo. | I24: =IF(J24="",0,1) -> 1 | J24: Dinamarca | M24: 2 | N24: =IF(J24="",0,M24) -> 2
B25: Puede pensarlo como el lugar que quedarían en la tabla de posiciones. | I25: =IF(J25="",0,1) -> 1 | J25: Tunez | M25: 3 | N25: =IF(J25="",0,M25) -> 3
B26: A modo de ejemplo, si su predicción es que todos los partidos terminan 0-0, el orden | I26: =IF(J26="",0,1) -> 1 | J26: Australia | M26: 4 | N26: =IF(J26="",0,M26) -> 4
B27: asignado en este recuadro es el que finalmente quedará en la tabla de posiciones. | N27: =IF(J27="",0,M27) -> 0

Sheet GRUPO E
B3: GRUPO E
C5: 2 | D5: 3 | E5: 5 | F5: 6 | G5: 4
B6: Tabla de Posiciones | J6: Fecha | K6: Partidos | AJ6: 1 | AK6: 2 | AL6: Ganador | AN6: Orden | AO6: Equipo | AP6: Puntos | AQ6: DG | AR6: GF | AS6: GC | AV6: Equipo | AW6: Empatado Con | AX6: Ganador | AY6: Ganador? | AZ6: Formula Rank | BA6: Formula Rank Con Duelo Directo | BB6: Formula Rank Con Prioridad
B7: Posición | C7: Equipo | D7: Puntos | E7: GF | F7: GC | G7: DG | I7: 9 | J7: 44888 | K7: Alemania | L7: 2 | M7: 0 | N7: Japon | AI7: =CONCATENATE(K7,"_",N7) -> Alemania_Japon | AJ7: =IF(L7>M7,3,IF(L7<M7,0,1)) -> 3 | AK7: =IF(AJ7=3,0,IF(AJ7=1,1,3)) -> 0 | AL7: =IF(AJ7>AK7,K7,IF(AK7>AJ7,N7,"SIN GANADOR")) -> Alemania | AN7: =_xlfn.RANK.EQ(BB7,BB$7:BB$11,1) -> 1 | AO7: España | AP7: =SUMIF($K$7:$K$12,AO7,$AJ$7:$AJ$12) + SUMIF($N$7:$N$12,AO7,$AK$7:$AK$12) -> 9 | AQ7: =AR7-AS7 -> 5 | AR7: =SUMIF($K$7:$K$12,AO7,$L$7:$L$12) + SUMIF($N$7:$N$12,AO7,$M$7:$M$12) -> 6 | AS7: =SUMIF($K$7:$K$12,AO7,$M$7:$M$12) + SUMIF($N$7:$N$12,AO7,$L$7:$L$12) -> 1 | AV7: =AO7 -> España | AW7: =IF(AZ7=AZ8,AV8,IF(AZ7=AZ9,AV9,IF(AZ7=AZ10,AV10,""))) | AX7: =IF(AW7="","",IFERROR(VLOOKUP(CONCATENATE(AV7,"_",AW7),$AI$7:$AL$16,4,FALSE),VLOOKUP(CONCATENATE(AW7,"_",AV7),$AI$7:$AL$16,4,FALSE))) | AY7: =IF(AX7="",1,IF(AX7=AV7,1,0)) -> 1 | AZ7: =-AP7*10000000 - AQ7*10000 - AR7*100 -> -90050600 | BA7: =AZ7-AY7*10 -> -90050610 | BB7: =BA7+N23 -> -90050609
B8: 1 | C8: =IFERROR(VLOOKUP($B8,$AN$7:$AS$11,C$5,FALSE),"") -> España | D8: =IFERROR(VLOOKUP($B8,$AN$7:$AS$11,D$5,FALSE),"") -> 9 | E8: =IFERROR(VLOOKUP($B8,$AN$7:$AS$11,E$5,FALSE),"") -> 6 | F8: =IFERROR(VLOOKUP($B8,$AN$7:$AS$11,F$5,FALSE),"") -> 1 | G8: =IFERROR(VLOOKUP($B8,$AN$7:$AS$11,G$5,FALSE),"") -> 5 | I8: 10 | J8: 44888 | K8: España | L8: 2 | M8: 0 | N8: Costa Rica | AI8: =CONCATENATE(K8,"_",N8) -> España_Costa Rica | AJ8: =IF(L8>M8,3,IF(L8<M8,0,1)) -> 3 | AK8: =IF(AJ8=3,0,IF(AJ8=1,1,3)) -> 0 | AL8: =IF(AJ8>AK8,K8,IF(AK8>AJ8,N8,"SIN GANADOR")) -> España | AN8: =_xlfn.RANK.EQ(BB8,BB$7:BB$11,1) -> 2 | AO8: Alemania | AP8: =SUMIF($K$7:$K$12,AO8,$AJ$7:$AJ$12) + SUMIF($N$7:$N$12,AO8,$AK$7:$AK$12) -> 6 | AQ8: =AR8-AS8 -> 2 | AR8: =SUMIF($K$7:$K$12,AO8,$L$7:$L$12) + SUMIF($N$7:$N$12,AO8,$M$7:$M$12) -> 4 | AS8: =SUMIF($K$7:$K$12,AO8,$M$7:$M$12) + SUMIF($N$7:$N$12,AO8,$L$7:$L$12) -> 2 | AV8: =AO8 -> Alemania | AW8: =IF(AZ8=AZ9,AV9,IF(AZ8=AZ10,AV10,IF(AZ8=AZ7,AV7,""))) | AX8: =IF(AW8="","",IFERROR(VLOOKUP(CONCATENATE(AV8,"_",AW8),$AI$7:$AL$16,4,FALSE),VLOOKUP(CONCATENATE(AW8,"_",AV8),$AI$7:$AL$16,4,FALSE))) | AY8: =IF(AX8="",1,IF(AX8=AV8,1,0)) -> 1 | AZ8: =-AP8*10000000 - AQ8*10000 - AR8*100 -> -60020400 | BA8: =AZ8-AY8*10 -> -60020410 | BB8: =BA8+N24 -> -60020408
B9: 2 | C9: =IFERROR(VLOOKUP($B9,$AN$7:$AS$11,C$5,FALSE),"") -> Alemania | D9: =IFERROR(VLOOKUP($B9,$AN$7:$AS$11,D$5,FALSE),"") -> 6 | E9: =IFERROR(VLOOKUP($B9,$AN$7:$AS$11,E$5,FALSE),"") -> 4 | F9: =IFERROR(VLOOKUP($B9,$AN$7:$AS$11,F$5,FALSE),"") -> 2 | G9: =IFERROR(VLOOKUP($B9,$AN$7:$AS$11,G$5,FALSE),"") -> 2 | I9: =I7+16 -> 25 | J9: 44892 | K9: Japon | L9: 0 | M9: 1 | N9: Costa Rica | AI9: =CONCATENATE(K9,"_",N9) -> Japon_Costa Rica | AJ9: =IF(L9>M9,3,IF(L9<M9,0,1)) -> 0 | AK9: =IF(AJ9=3,0,IF(AJ9=1,1,3)) -> 3 | AL9: =IF(AJ9>AK9,K9,IF(AK9>AJ9,N9,"SIN GANADOR")) -> Costa Rica | AN9: =_xlfn.RANK.EQ(BB9,BB$7:BB$11,1) -> 4 | AO9: Japon | AP9: =SUMIF($K$7:$K$12,AO9,$AJ$7:$AJ$12) + SUMIF($N$7:$N$12,AO9,$AK$7:$AK$12) -> 0 | AQ9: =AR9-AS9 -> -5 | AR9: =SUMIF($K$7:$K$12,AO9,$L$7:$L$12) + SUMIF($N$7:$N$12,AO9,$M$7:$M$12) -> 0 | AS9: =SUMIF($K$7:$K$12,AO9,$M$7:$M$12) + SUMIF($N$7:$N$12,AO9,$L$7:$L$12) -> 5 | AV9: =AO9 -> Japon | AW9: =IF(AZ9=AZ10,AV10,IF(AZ9=AZ7,AV7,IF(AZ9=AZ8,AV8,""))) | AX9: =IF(AW9="","",IFERROR(VLOOKUP(CONCATENATE(AV9,"_",AW9),$AI$7:$AL$16,4,FALSE),VLOOKUP(CONCATENATE(AW9,"_",AV9),$AI$7:$AL$16,4,FALSE))) | AY9: =IF(AX9="",1,IF(AX9=AV9,1,0)) -> 1 | AZ9: =-AP9*10000000 - AQ9*10000 - AR9*100 -> 50000 | BA9: =AZ9-AY9*10 -> 49990 | BB9: =BA9+N25 -> 49994
B10: 3 | C10: =IFERROR(VLOOKUP($B10,$AN$7:$AS$11,C$5,FALSE),"") -> Costa Rica | D10: =IFERROR(VLOOKUP($B10,$AN$7:$AS$11,D$5,FALSE),"") -> 3 | E10: =IFERROR(VLOOKUP($B10,$AN$7:$AS$11,E$5,FALSE),"") -> 1 | F10: =IFERROR(VLOOKUP($B10,$AN$7:$AS$11,F$5,FALSE),"") -> 3 | G10: =IFERROR(VLOOKUP($B10,$AN$7:$AS$11,G$5,FALSE),"") -> -2 | I10: =I8+16 -> 26 | J10: 44892 | K10: España | L10: 2 | M10: 1 | N10: Alemania | AI10: =CONCATENATE(K10,"_",N10) -> España_Alemania | AJ10: =IF(L10>M10,3,IF(L10<M10,0,1)) -> 3 | AK10: =IF(AJ10=3,0,IF(AJ10=1,1,3)) -> 0 | AL10: =IF(AJ10>AK10,K10,IF(AK10>AJ10,N10,"SIN GANADOR")) -> España | AN10: =_xlfn.RANK.EQ(BB10,BB$7:BB$11,1) -> 3 | AO10: Costa Rica | AP10: =SUMIF($K$7:$K$12,AO10,$AJ$7:$AJ$12) + SUMIF($N$7:$N$12,AO10,$AK$7:$AK$12) -> 3 | AQ10: =AR10-AS10 -> -2 | AR10: =SUMIF($K$7:$K$12,AO10,$L$7:$L$12) + SUMIF($N$7:$N$12,AO10,$M$7:$M$12) -> 1 | AS10: =SUMIF($K$7:$K$12,AO10,$M$7:$M$12) + SUMIF($N$7:$N$12,AO10,$L$7:$L$12) -> 3 | AV10: =AO10 -> Costa Rica | AW10: =IF(AZ10=AZ7,AV7,IF(AZ10=AZ8,AV8,IF(AZ10=AZ9,AV9,""))) | AX10: =IF(AW10="","",IFERROR(VLOOKUP(CONCATENATE(AV10,"_",AW10),$AI$7:$AL$16,4,FALSE),VLOOKUP(CONCATENATE(AW10,"_",AV10),$AI$7:$AL$16,4,FALSE))) | AY10: =IF(AX10="",1,IF(AX10=AV10,1,0)) -> 1 | AZ10: =-AP10*10000000 - AQ10*10000 - AR10*100 -> -29980100 | BA10: =AZ10-AY10*10 -> -29980110 | BB10: =BA10+N26 -> -29980107
B11: 4 | C11: =IFERROR(VLOOKUP($B11,$AN$7:$AS$11,C$5,FALSE),"") -> Japon | D11: =IFERROR(VLOOKUP($B11,$AN$7:$AS$11,D$5,FALSE),"") -> 0 | E11: =IFERROR(VLOOKUP($B11,$AN$7:$AS$11,E$5,FALSE),"") -> 0 | F11: =IFERROR(VLOOKUP($B11,$AN$7:$AS$11,F$5,FALSE),"") -> 5 | G11: =IFERROR(VLOOKUP($B11,$AN$7:$AS$11,G$5,FALSE),"") -> -5 | I11: =I9+16 -> 41 | J11: 44896 | K11: Japon | L11: 0 | M11: 2 | N11: España | AI11: =CONCATENATE(K11,"_",N11) -> Japon_España | AJ11: =IF(L11>M11,3,IF(L11<M11,0,1)) -> 0 | AK11: =IF(AJ11=3,0,IF(AJ11=1,1,3)) -> 3 | AL11: =IF(AJ11>AK11,K11,IF(AK11>AJ11,N11,"SIN GANADOR")) -> España
I12: =I10+16 -> 42 | J12: 44896 | K12: Costa Rica | L12: 0 | M12: 1 | N12: Alemania | AI12: =CONCATENATE(K12,"_",N12) -> Costa Rica_Alemania | AJ12: =IF(L12>M12,3,IF(L12<M12,0,1)) -> 0 | AK12: =IF(AJ12=3,0,IF(AJ12=1,1,3)) -> 3 | AL12: =IF(AJ12>AK12,K12,IF(AK12>AJ12,N12,"SIN GANADOR")) -> Alemania
B22: El recuadro de la derecha sirve para desempatar, en caso de que haya empate entre | I22: 1 | J22: Escoja por prioridad los siguientes equipos:
B23: uno o más equipos en todos los criterios considerados. | I23: =IF(J23="",0,1) -> 1 | J23: España | M23: 1 | N23: =IF(J23="",0,M23) -> 1
B24: Para utilizarlo, asigne una prioridad entre 1 y 5 (siendo más bajo mejor) a cada equipo. | I24: =IF(J24="",0,1) -> 1 | J24: Alemania | M24: 2 | N24: =IF(J24="",0,M24) -> 2
B25: Puede pensarlo como el lugar que quedarían en la tabla de posiciones. | I25: =IF(J25="",0,1) -> 1 | J25: Japon | M25: 4 | N25: =IF(J25="",0,M25) -> 4
B26: A modo de ejemplo, si su predicción es que todos los partidos terminan 0-0, el orden | I26: =IF(J26="",0,1) -> 1 | J26: Costa Rica | M26: 3 | N26: =IF(J26="",0,M26) -> 3
B27: asignado en este recuadro es el que finalmente quedará en la tabla de posiciones. | N27: =IF(J27="",0,M27) -> 0

Sheet GRUPO F
B3: GRUPO F
C5: 2 | D5: 3 | E5: 5 | F5: 6 | G5: 4
B6: Tabla de Posiciones | J6: Fecha | K6: Partidos | AJ6: 1 | AK6: 2 | AL6: Ganador | AN6: Orden | AO6: Equipo | AP6: Puntos | AQ6: DG | AR6: GF | AS6: GC | AV6: Equipo | AW6: Empatado Con | AX6: Ganador | AY6: Ganador? | AZ6: Formula Rank | BA6: Formula Rank Con Duelo Directo | BB6: Formula Rank Con Prioridad
B7: Posición | C7: Equipo | D7: Puntos | E7: GF | F7: GC | G7: DG | I7: 11 | J7: 44888 | K7: Marruecos | L7: 0 | M7: 1 | N7: Croacia | AI7: =CONCATENATE(K7,"_",N7) -> Marruecos_Croacia | AJ7: =IF(L7>M7,3,IF(L7<M7,0,1)) -> 0 | AK7: =IF(AJ7=3,0,IF(AJ7=1,1,3)) -> 3 | AL7: =IF(AJ7>AK7,K7,IF(AK7>AJ7,N7,"SIN GANADOR")) -> Croacia | AN7: =_xlfn.RANK.EQ(BB7,BB$7:BB$11,1) -> 2 | AO7: Belgica | AP7: =SUMIF($K$7:$K$12,AO7,$AJ$7:$AJ$12) + SUMIF($N$7:$N$12,AO7,$AK$7:$AK$12) -> 5 | AQ7: =AR7-AS7 -> 1 | AR7: =SUMIF($K$7:$K$12,AO7,$L$7:$L$12) + SUMIF($N$7:$N$12,AO7,$M$7:$M$12) -> 3 | AS7: =SUMIF($K$7:$K$12,AO7,$M$7:$M$12) + SUMIF($N$7:$N$12,AO7,$L$7:$L$12) -> 2 | AV7: =AO7 -> Belgica | AW7: =IF(AZ7=AZ8,AV8,IF(AZ7=AZ9,AV9,IF(AZ7=AZ10,AV10,""))) | AX7: =IF(AW7="","",IFERROR(VLOOKUP(CONCATENATE(AV7,"_",AW7),$AI$7:$AL$16,4,FALSE),VLOOKUP(CONCATENATE(AW7,"_",AV7),$AI$7:$AL$16,4,FALSE))) | AY7: =IF(AX7="",1,IF(AX7=AV7,1,0)) -> 1 | AZ7: =-AP7*10000000 - AQ7*10000 - AR7*100 -> -50010300 | BA7: =AZ7-AY7*10 -> -50010310 | BB7: =BA7+N23 -> -50010308
B8: 1 | C8: =IFERROR(VLOOKUP($B8,$AN$7:$AS$11,C$5,FALSE),"") -> Croacia | D8: =IFERROR(VLOOKUP($B8,$AN$7:$AS$11,D$5,FALSE),"") -> 7 | E8: =IFERROR(VLOOKUP($B8,$AN$7:$AS$11,E$5,FALSE),"") -> 3 | F8: =IFERROR(VLOOKUP($B8,$AN$7:$AS$11,F$5,FALSE),"") -> 1 | G8: =IFERROR(VLOOKUP($B8,$AN$7:$AS$11,G$5,FALSE),"") -> 2 | I8: 12 | J8: 44888 | K8: Belgica | L8: 1 | M8: 0 | N8: Canada | AI8: =CONCATENATE(K8,"_",N8) -> Belgica_Canada | AJ8: =IF(L8>M8,3,IF(L8<M8,0,1)) -> 3 | AK8: =IF(AJ8=3,0,IF(AJ8=1,1,3)) -> 0 | AL8: =IF(AJ8>AK8,K8,IF(AK8>AJ8,N8,"SIN GANADOR")) -> Belgica | AN8: =_xlfn.RANK.EQ(BB8,BB$7:BB$11,1) -> 1 | AO8: Croacia | AP8: =SUMIF($K$7:$K$12,AO8,$AJ$7:$AJ$12) + SUMIF($N$7:$N$12,AO8,$AK$7:$AK$12) -> 7 | AQ8: =AR8-AS8 -> 2 | AR8: =SUMIF($K$7:$K$12,AO8,$L$7:$L$12) + SUMIF($N$7:$N$12,AO8,$M$7:$M$12) -> 3 | AS8: =SUMIF($K$7:$K$12,AO8,$M$7:$M$12) + SUMIF($N$7:$N$12,AO8,$L$7:$L$12) -> 1 | AV8: =AO8 -> Croacia | AW8: =IF(AZ8=AZ9,AV9,IF(AZ8=AZ10,AV10,IF(AZ8=AZ7,AV7,""))) | AX8: =IF(AW8="","",IFERROR(VLOOKUP(CONCATENATE(AV8,"_",AW8),$AI$7:$AL$16,4,FALSE),VLOOKUP(CONCATENATE(AW8,"_",AV8),$AI$7:$AL$16,4,FALSE))) | AY8: =IF(AX8="",1,IF(AX8=AV8,1,0)) -> 1 | AZ8: =-AP8*10000000 - AQ8*10000 - AR8*100 -> -70020300 | BA8: =AZ8-AY8*10 -> -70020310 | BB8: =BA8+N24 -> -70020309
B9: 2 | C9: =IFERROR(VLOOKUP($B9,$AN$7:$AS$11,C$5,FALSE),"") -> Belgica | D9: =IFERROR(VLOOKUP($B9,$AN$7:$AS$11,D$5,FALSE),"") -> 5 | E9: =IFERROR(VLOOKUP($B9,$AN$7:$AS$11,E$5,FALSE),"") -> 3 | F9: =IFERROR(VLOOKUP($B9,$AN$7:$AS$11,F$5,FALSE),"") -> 2 | G9: =IFERROR(VLOOKUP($B9,$AN$7:$AS$11,G$5,FALSE),"") -> 1 | I9: =I7+16 -> 27 | J9: 44892 | K9: Belgica | L9: 1 | M9: 1 | N9: Marruecos | AI9: =CONCATENATE(K9,"_",N9) -> Belgica_Marruecos | AJ9: =IF(L9>M9,3,IF(L9<M9,0,1)) -> 1 | AK9: =IF(AJ9=3,0,IF(AJ9=1,1,3)) -> 1 | AL9: =IF(AJ9>AK9,K9,IF(AK9>AJ9,N9,"SIN GANADOR")) -> SIN GANADOR | AN9: =_xlfn.RANK.EQ(BB9,BB$7:BB$11,1) -> 3 | AO9: Marruecos | AP9: =SUMIF($K$7:$K$12,AO9,$AJ$7:$AJ$12) + SUMIF($N$7:$N$12,AO9,$AK$7:$AK$12) -> 2 | AQ9: =AR9-AS9 -> -1 | AR9: =SUMIF($K$7:$K$12,AO9,$L$7:$L$12) + SUMIF($N$7:$N$12,AO9,$M$7:$M$12) -> 1 | AS9: =SUMIF($K$7:$K$12,AO9,$M$7:$M$12) + SUMIF($N$7:$N$12,AO9,$L$7:$L$12) -> 2 | AV9: =AO9 -> Marruecos | AW9: =IF(AZ9=AZ10,AV10,IF(AZ9=AZ7,AV7,IF(AZ9=AZ8,AV8,""))) | AX9: =IF(AW9="","",IFERROR(VLOOKUP(CONCATENATE(AV9,"_",AW9),$AI$7:$AL$16,4,FALSE),VLOOKUP(CONCATENATE(AW9,"_",AV9),$AI$7:$AL$16,4,FALSE))) | AY9: =IF(AX9="",1,IF(AX9=AV9,1,0)) -> 1 | AZ9: =-AP9*10000000 - AQ9*10000 - AR9*100 -> -19990100 | BA9: =AZ9-AY9*10 -> -19990110 | BB9: =BA9+N25 -> -19990107
B10: 3 | C10: =IFERROR(VLOOKUP($B10,$AN$7:$AS$11,C$5,FALSE),"") -> Marruecos | D10: =IFERROR(VLOOKUP($B10,$AN$7:$AS$11,D$5,FALSE),"") -> 2 | E10: =IFERROR(VLOOKUP($B10,$AN$7:$AS$11,E$5,FALSE),"") -> 1 | F10: =IFERROR(VLOOKUP($B10,$AN$7:$AS$11,F$5,FALSE),"") -> 2 | G10: =IFERROR(VLOOKUP($B10,$AN$7:$AS$11,G$5,FALSE),"") -> -1 | I10: =I8+16 -> 28 | J10: 44892 | K10: Croacia | L10: 1 | M10: 0 | N10: Canada | AI10: =CONCATENATE(K10,"_",N10) -> Croacia_Canada | AJ10: =IF(L10>M10,3,IF(L10<M10,0,1)) -> 3 | AK10: =IF(AJ10=3,0,IF(AJ10=1,1,3)) -> 0 | AL10: =IF(AJ10>AK10,K10,IF(AK10>AJ10,N10,"SIN GANADOR")) -> Croacia | AN10: =_xlfn.RANK.EQ(BB10,BB$7:BB$11,1) -> 4 | AO10: Canada | AP10: =SUMIF($K$7:$K$12,AO10,$AJ$7:$AJ$12) + SUMIF($N$7:$N$12,AO10,$AK$7:$AK$12) -> 1 | AQ10: =AR10-AS10 -> -2 | AR10: =SUMIF($K$7:$K$12,AO10,$L$7:$L$12) + SUMIF($N$7:$N$12,AO10,$M$7:$M$12) -> 0 | AS10: =SUMIF($K$7:$K$12,AO10,$M$7:$M$12) + SUMIF($N$7:$N$12,AO10,$L$7:$L$12) -> 2 | AV10: =AO10 -> Canada | AW10: =IF(AZ10=AZ7,AV7,IF(AZ10=AZ8,AV8,IF(AZ10=AZ9,AV9,""))) | AX10: =IF(AW10="","",IFERROR(VLOOKUP(CONCATENATE(AV10,"_",AW10),$AI$7:$AL$16,4,FALSE),VLOOKUP(CONCATENATE(AW10,"_",AV10),$AI$7:$AL$16,4,FALSE))) | AY10: =IF(AX10="",1,IF(AX10=AV10,1,0)) -> 1 | AZ10: =-AP10*10000000 - AQ10*10000 - AR10*100 -> -9980000 | BA10: =AZ10-AY10*10 -> -9980010 | BB10: =BA10+N26 -> -9980006
B11: 4 | C11: =IFERROR(VLOOKUP($B11,$AN$7:$AS$11,C$5,FALSE),"") -> Canada | D11: =IFERROR(VLOOKUP($B11,$AN$7:$AS$11,D$5,FALSE),"") -> 1 | E11: =IFERROR(VLOOKUP($B11,$AN$7:$AS$11,E$5,FALSE),"") -> 0 | F11: =IFERROR(VLOOKUP($B11,$AN$7:$AS$11,F$5,FALSE),"") -> 2 | G11: =IFERROR(VLOOKUP($B11,$AN$7:$AS$11,G$5,FALSE),"") -> -2 | I11: =I9+16 -> 43 | J11: 44896 | K11: Croacia | L11: 1 | M11: 1 | N11: Belgica | AI11: =CONCATENATE(K11,"_",N11) -> Croacia_Belgica | AJ11: =IF(L11>M11,3,IF(L11<M11,0,1)) -> 1 | AK11: =IF(AJ11=3,0,IF(AJ11=1,1,3)) -> 1 | AL11: =IF(AJ11>AK11,K11,IF(AK11>AJ11,N11,"SIN GANADOR")) -> SIN GANADOR
I12: =I10+16 -> 44 | J12: 44896 | K12: Canada | L12: 0 | M12: 0 | N12: Marruecos | AI12: =CONCATENATE(K12,"_",N12) -> Canada_Marruecos | AJ12: =IF(L12>M12,3,IF(L12<M12,0,1)) -> 1 | AK12: =IF(AJ12=3,0,IF(AJ12=1,1,3)) -> 1 | AL12: =IF(AJ12>AK12,K12,IF(AK12>AJ12,N12,"SIN GANADOR")) -> SIN GANADOR
B22: El recuadro de la derecha sirve para desempatar, en caso de que haya empate entre | I22: 1 | J22: Escoja por prioridad los siguientes equipos:
B23: uno o más equipos en todos los criterios considerados. | I23: =IF(J23="",0,1) -> 1 | J23: Belgica | M23: 2 | N23: =IF(J23="",0,M23) -> 2
B24: Para utilizarlo, asigne una prioridad entre 1 y 5 (siendo más bajo mejor) a cada equipo. | I24: =IF(J24="",0,1) -> 1 | J24: Croacia | M24: 1 | N24: =IF(J24="",0,M24) -> 1
B25: Puede pensarlo como el lugar que quedarían en la tabla de posiciones. | I25: =IF(J25="",0,1) -> 1 | J25: Marruecos | M25: 3 | N25: =IF(J25="",0,M25) -> 3
B26: A modo de ejemplo, si su predicción es que todos los partidos terminan 0-0, el orden | I26: =IF(J26="",0,1) -> 1 | J26: Canada | M26: 4 | N26: =IF(J26="",0,M26) -> 4
B27: asignado en este recuadro es el que finalmente quedará en la tabla de posiciones. | N27: =IF(J27="",0,M27) -> 0

Sheet Hoja1

Sheet GRUPO G
B3: GRUPO G
C5: 2 | D5: 3 | E5: 5 | F5: 6 | G5: 4
B6: Tabla de Posiciones | J6: Fecha | K6: Partidos | AJ6: 1 | AK6: 2 | AL6: Ganador | AN6: Orden | AO6: Equipo | AP6: Puntos | AQ6: DG | AR6: GF | AS6: GC | AV6: Equipo | AW6: Empatado Con | AX6: Ganador | AY6: Ganador? | AZ6: Formula Rank | BA6: Formula Rank Con Duelo Directo | BB6: Formula Rank Con Prioridad
B7: Posición | C7: Equipo | D7: Puntos | E7: GF | F7: GC | G7: DG | I7: 13 | J7: 44889 | K7: Suiza | L7: 1 | M7: 0 | N7: Camerun | AI7: =CONCATENATE(K7,"_",N7) -> Suiza_Camerun | AJ7: =IF(L7>M7,3,IF(L7<M7,0,1)) -> 3 | AK7: =IF(AJ7=3,0,IF(AJ7=1,1,3)) -> 0 | AL7: =IF(AJ7>AK7,K7,IF(AK7>AJ7,N7,"SIN GANADOR")) -> Suiza | AN7: =_xlfn.RANK.EQ(BB7,BB$7:BB$11,1) -> 1 | AO7: Brasil | AP7: =SUMIF($K$7:$K$12,AO7,$AJ$7:$AJ$12) + SUMIF($N$7:$N$12,AO7,$AK$7:$AK$12) -> 9 | AQ7: =AR7-AS7 -> 7 | AR7: =SUMIF($K$7:$K$12,AO7,$L$7:$L$12) + SUMIF($N$7:$N$12,AO7,$M$7:$M$12) -> 7 | AS7: =SUMIF($K$7:$K$12,AO7,$M$7:$M$12) + SUMIF($N$7:$N$12,AO7,$L$7:$L$12) -> 0 | AV7: =AO7 -> Brasil | AW7: =IF(AZ7=AZ8,AV8,IF(AZ7=AZ9,AV9,IF(AZ7=AZ10,AV10,""))) | AX7: =IF(AW7="","",IFERROR(VLOOKUP(CONCATENATE(AV7,"_",AW7),$AI$7:$AL$16,4,FALSE),VLOOKUP(CONCATENATE(AW7,"_",AV7),$AI$7:$AL$16,4,FALSE))) | AY7: =IF(AX7="",1,IF(AX7=AV7,1,0)) -> 1 | AZ7: =-AP7*10000000 - AQ7*10000 - AR7*100 -> -90070700 | BA7: =AZ7-AY7*10 -> -90070710 | BB7: =BA7+N23 -> -90070709
B8: 1 | C8: =IFERROR(VLOOKUP($B8,$AN$7:$AS$11,C$5,FALSE),"") -> Brasil | D8: =IFERROR(VLOOKUP($B8,$AN$7:$AS$11,D$5,FALSE),"") -> 9 | E8: =IFERROR(VLOOKUP($B8,$AN$7:$AS$11,E$5,FALSE),"") -> 7 | F8: =IFERROR(VLOOKUP($B8,$AN$7:$AS$11,F$5,FALSE),"") -> 0 | G8: =IFERROR(VLOOKUP($B8,$AN$7:$AS$11,G$5,FALSE),"") -> 7 | I8: 14 | J8: 44889 | K8: Brasil | L8: 2 | M8: 0 | N8: Serbia | AI8: =CONCATENATE(K8,"_",N8) -> Brasil_Serbia | AJ8: =IF(L8>M8,3,IF(L8<M8,0,1)) -> 3 | AK8: =IF(AJ8=3,0,IF(AJ8=1,1,3)) -> 0 | AL8: =IF(AJ8>AK8,K8,IF(AK8>AJ8,N8,"SIN GANADOR")) -> Brasil | AN8: =_xlfn.RANK.EQ(BB8,BB$7:BB$11,1) -> 2 | AO8: Suiza | AP8: =SUMIF($K$7:$K$12,AO8,$AJ$7:$AJ$12) + SUMIF($N$7:$N$12,AO8,$AK$7:$AK$12) -> 4 | AQ8: =AR8-AS8 -> -1 | AR8: =SUMIF($K$7:$K$12,AO8,$L$7:$L$12) + SUMIF($N$7:$N$12,AO8,$M$7:$M$12) -> 2 | AS8: =SUMIF($K$7:$K$12,AO8,$M$7:$M$12) + SUMIF($N$7:$N$12,AO8,$L$7:$L$12) -> 3 | AV8: =AO8 -> Suiza | AW8: =IF(AZ8=AZ9,AV9,IF(AZ8=AZ10,AV10,IF(AZ8=AZ7,AV7,""))) -> Serbia | AX8: =IF(AW8="","",IFERROR(VLOOKUP(CONCATENATE(AV8,"_",AW8),$AI$7:$AL$16,4,FALSE),VLOOKUP(CONCATENATE(AW8,"_",AV8),$AI$7:$AL$16,4,FALSE))) -> SIN GANADOR | AY8: =IF(AX8="",1,IF(AX8=AV8,1,0)) -> 0 | AZ8: =-AP8*10000000 - AQ8*10000 - AR8*100 -> -39990200 | BA8: =AZ8-AY8*10 -> -39990200 | BB8: =BA8+N24 -> -39990198
B9: 2 | C9: =IFERROR(VLOOKUP($B9,$AN$7:$AS$11,C$5,FALSE),"") -> Suiza | D9: =IFERROR(VLOOKUP($B9,$AN$7:$AS$11,D$5,FALSE),"") -> 4 | E9: =IFERROR(VLOOKUP($B9,$AN$7:$AS$11,E$5,FALSE),"") -> 2 | F9: =IFERROR(VLOOKUP($B9,$AN$7:$AS$11,F$5,FALSE),"") -> 3 | G9: =IFERROR(VLOOKUP($B9,$AN$7:$AS$11,G$5,FALSE),"") -> -1 | I9: =I7+16 -> 29 | J9: 44893 | K9: Camerun | L9: 0 | M9: 1 | N9: Serbia | AI9: =CONCATENATE(K9,"_",N9) -> Camerun_Serbia | AJ9: =IF(L9>M9,3,IF(L9<M9,0,1)) -> 0 | AK9: =IF(AJ9=3,0,IF(AJ9=1,1,3)) -> 3 | AL9: =IF(AJ9>AK9,K9,IF(AK9>AJ9,N9,"SIN GANADOR")) -> Serbia | AN9: =_xlfn.RANK.EQ(BB9,BB$7:BB$11,1) -> 3 | AO9: Serbia | AP9: =SUMIF($K$7:$K$12,AO9,$AJ$7:$AJ$12) + SUMIF($N$7:$N$12,AO9,$AK$7:$AK$12) -> 4 | AQ9: =AR9-AS9 -> -1 | AR9: =SUMIF($K$7:$K$12,AO9,$L$7:$L$12) + SUMIF($N$7:$N$12,AO9,$M$7:$M$12) -> 2 | AS9: =SUMIF($K$7:$K$12,AO9,$M$7:$M$12) + SUMIF($N$7:$N$12,AO9,$L$7:$L$12) -> 3 | AV9: =AO9 -> Serbia | AW9: =IF(AZ9=AZ10,AV10,IF(AZ9=AZ7,AV7,IF(AZ9=AZ8,AV8,""))) -> Suiza | AX9: =IF(AW9="","",IFERROR(VLOOKUP(CONCATENATE(AV9,"_",AW9),$AI$7:$AL$16,4,FALSE),VLOOKUP(CONCATENATE(AW9,"_",AV9),$AI$7:$AL$16,4,FALSE))) -> SIN GANADOR | AY9: =IF(AX9="",1,IF(AX9=AV9,1,0)) -> 0 | AZ9: =-AP9*10000000 - AQ9*10000 - AR9*100 -> -39990200 | BA9: =AZ9-AY9*10 -> -39990200 | BB9: =BA9+N25 -> -39990197
B10: 3 | C10: =IFERROR(VLOOKUP($B10,$AN$7:$AS$11,C$5,FALSE),"") -> Serbia | D10: =IFERROR(VLOOKUP($B10,$AN$7:$AS$11,D$5,FALSE),"") -> 4 | E10: =IFERROR(VLOOKUP($B10,$AN$7:$AS$11,E$5,FALSE),"") -> 2 | F10: =IFERROR(VLOOKUP($B10,$AN$7:$AS$11,F$5,FALSE),"") -> 3 | G10: =IFERROR(VLOOKUP($B10,$AN$7:$AS$11,G$5,FALSE),"") -> -1 | I10: =I8+16 -> 30 | J10: 44893 | K10: Brasil | L10: 2 | M10: 0 | N10: Suiza | AI10: =CONCATENATE(K10,"_",N10) -> Brasil_Suiza | AJ10: =IF(L10>M10,3,IF(L10<M10,0,1)) -> 3 | AK10: =IF(AJ10=3,0,IF(AJ10=1,1,3)) -> 0 | AL10: =IF(AJ10>AK10,K10,IF(AK10>AJ10,N10,"SIN GANADOR")) -> Brasil | AN10: =_xlfn.RANK.EQ(BB10,BB$7:BB$11,1) -> 4 | AO10: Camerun | AP10: =SUMIF($K$7:$K$12,AO10,$AJ$7:$AJ$12) + SUMIF($N$7:$N$12,AO10,$AK$7:$AK$12) -> 0 | AQ10: =AR10-AS10 -> -5 | AR10: =SUMIF($K$7:$K$12,AO10,$L$7:$L$12) + SUMIF($N$7:$N$12,AO10,$M$7:$M$12) -> 0 | AS10: =SUMIF($K$7:$K$12,AO10,$M$7:$M$12) + SUMIF($N$7:$N$12,AO10,$L$7:$L$12) -> 5 | AV10: =AO10 -> Camerun | AW10: =IF(AZ10=AZ7,AV7,IF(AZ10=AZ8,AV8,IF(AZ10=AZ9,AV9,""))) | AX10: =IF(AW10="","",IFERROR(VLOOKUP(CONCATENATE(AV10,"_",AW10),$AI$7:$AL$16,4,FALSE),VLOOKUP(CONCATENATE(AW10,"_",AV10),$AI$7:$AL$16,4,FALSE))) | AY10: =IF(AX10="",1,IF(AX10=AV10,1,0)) -> 1 | AZ10: =-AP10*10000000 - AQ10*10000 - AR10*100 -> 50000 | BA10: =AZ10-AY10*10 -> 49990 | BB10: =BA10+N26 -> 49994
B11: 4 | C11: =IFERROR(VLOOKUP($B11,$AN$7:$AS$11,C$5,FALSE),"") -> Camerun | D11: =IFERROR(VLOOKUP($B11,$AN$7:$AS$11,D$5,FALSE),"") -> 0 | E11: =IFERROR(VLOOKUP($B11,$AN$7:$AS$11,E$5,FALSE),"") -> 0 | F11: =IFERROR(VLOOKUP($B11,$AN$7:$AS$11,F$5,FALSE),"") -> 5 | G11: =IFERROR(VLOOKUP($B11,$AN$7:$AS$11,G$5,FALSE),"") -> -5 | I11: =I9+16 -> 45 | J11: 44897 | K11: Serbia | L11: 1 | M11: 1 | N11: Suiza | AI11: =CONCATENATE(K11,"_",N11) -> Serbia_Suiza | AJ11: =IF(L11>M11,3,IF(L11<M11,0,1)) -> 1 | AK11: =IF(AJ11=3,0,IF(AJ11=1,1,3)) -> 1 | AL11: =IF(AJ11>AK11,K11,IF(AK11>AJ11,N11,"SIN GANADOR")) -> SIN GANADOR
I12: =I10+16 -> 46 | J12: 44897 | K12: Camerun | L12: 0 | M12: 3 | N12: Brasil | AI12: =CONCATENATE(K12,"_",N12) -> Camerun_Brasil | AJ12: =IF(L12>M12,3,IF(L12<M12,0,1)) -> 0 | AK12: =IF(AJ12=3,0,IF(AJ12=1,1,3)) -> 3 | AL12: =IF(AJ12>AK12,K12,IF(AK12>AJ12,N12,"SIN GANADOR")) -> Brasil
B22: El recuadro de la derecha sirve para desempatar, en caso de que haya empate entre | I22: 1 | J22: Escoja por prioridad los siguientes equipos:
B23: uno o más equipos en todos los criterios considerados. | I23: =IF(J23="",0,1) -> 1 | J23: Brasil | M23: 1 | N23: =IF(J23="",0,M23) -> 1
B24: Para utilizarlo, asigne una prioridad entre 1 y 5 (siendo más bajo mejor) a cada equipo. | I24: =IF(J24="",0,1) -> 1 | J24: Suiza | M24: 2 | N24: =IF(J24="",0,M24) -> 2
B25: Puede pensarlo como el lugar que quedarían en la tabla de posiciones. | I25: =IF(J25="",0,1) -> 1 | J25: Serbia | M25: 3 | N25: =IF(J25="",0,M25) -> 3
B26: A modo de ejemplo, si su predicción es que todos los partidos terminan 0-0, el orden | I26: =IF(J26="",0,1) -> 1 | J26: Camerun | M26: 4 | N26: =IF(J26="",0,M26) -> 4
B27: asignado en este recuadro es el que finalmente quedará en la tabla de posiciones. | N27: =IF(J27="",0,M27) -> 0

Sheet GRUPO H
B3: GRUPO H
C5: 2 | D5: 3 | E5: 5 | F5: 6 | G5: 4
B6: Tabla de Posiciones | J6: Fecha | K6: Partidos | AJ6: 1 | AK6: 2 | AL6: Ganador | AN6: Orden | AO6: Equipo | AP6: Puntos | AQ6: DG | AR6: GF | AS6: GC | AV6: Equipo | AW6: Empatado Con | AX6: Ganador | AY6: Ganador? | AZ6: Formula Rank | BA6: Formula Rank Con Duelo Directo | BB6: Formula Rank Con Prioridad
B7: Posición | C7: Equipo | D7: Puntos | E7: GF | F7: GC | G7: DG | I7: 15 | J7: 44889 | K7: Uruguay | L7: 2 | M7: 0 | N7: Corea | AI7: =CONCATENATE(K7,"_",N7) -> Uruguay_Corea | AJ7: =IF(L7>M7,3,IF(L7<M7,0,1)) -> 3 | AK7: =IF(AJ7=3,0,IF(AJ7=1,1,3)) -> 0 | AL7: =IF(AJ7>AK7,K7,IF(AK7>AJ7,N7,"SIN GANADOR")) -> Uruguay | AN7: =_xlfn.RANK.EQ(BB7,BB$7:BB$11,1) -> 1 | AO7: Portugal | AP7: =SUMIF($K$7:$K$12,AO7,$AJ$7:$AJ$12) + SUMIF($N$7:$N$12,AO7,$AK$7:$AK$12) -> 9 | AQ7: =AR7-AS7 -> 7 | AR7: =SUMIF($K$7:$K$12,AO7,$L$7:$L$12) + SUMIF($N$7:$N$12,AO7,$M$7:$M$12) -> 9 | AS7: =SUMIF($K$7:$K$12,AO7,$M$7:$M$12) + SUMIF($N$7:$N$12,AO7,$L$7:$L$12) -> 2 | AV7: =AO7 -> Portugal | AW7: =IF(AZ7=AZ8,AV8,IF(AZ7=AZ9,AV9,IF(AZ7=AZ10,AV10,""))) | AX7: =IF(AW7="","",IFERROR(VLOOKUP(CONCATENATE(AV7,"_",AW7),$AI$7:$AL$16,4,FALSE),VLOOKUP(CONCATENATE(AW7,"_",AV7),$AI$7:$AL$16,4,FALSE))) | AY7: =IF(AX7="",1,IF(AX7=AV7,1,0)) -> 1 | AZ7: =-AP7*10000000 - AQ7*10000 - AR7*100 -> -90070900 | BA7: =AZ7-AY7*10 -> -90070910 | BB7: =BA7+N23 -> -90070909
B8: 1 | C8: =IFERROR(VLOOKUP($B8,$AN$7:$AS$11,C$5,FALSE),"") -> Portugal | D8: =IFERROR(VLOOKUP($B8,$AN$7:$AS$11,D$5,FALSE),"") -> 9 | E8: =IFERROR(VLOOKUP($B8,$AN$7:$AS$11,E$5,FALSE),"") -> 9 | F8: =IFERROR(VLOOKUP($B8,$AN$7:$AS$11,F$5,FALSE),"") -> 2 | G8: =IFERROR(VLOOKUP($B8,$AN$7:$AS$11,G$5,FALSE),"") -> 7 | I8: 16 | J8: 44889 | K8: Portugal | L8: 3 | M8: 0 | N8: Gana | AI8: =CONCATENATE(K8,"_",N8) -> Portugal_Gana | AJ8: =IF(L8>M8,3,IF(L8<M8,0,1)) -> 3 | AK8: =IF(AJ8=3,0,IF(AJ8=1,1,3)) -> 0 | AL8: =IF(AJ8>AK8,K8,IF(AK8>AJ8,N8,"SIN GANADOR")) -> Portugal | AN8: =_xlfn.RANK.EQ(BB8,BB$7:BB$11,1) -> 2 | AO8: Uruguay | AP8: =SUMIF($K$7:$K$12,AO8,$AJ$7:$AJ$12) + SUMIF($N$7:$N$12,AO8,$AK$7:$AK$12) -> 6 | AQ8: =AR8-AS8 -> 3 | AR8: =SUMIF($K$7:$K$12,AO8,$L$7:$L$12) + SUMIF($N$7:$N$12,AO8,$M$7:$M$12) -> 6 | AS8: =SUMIF($K$7:$K$12,AO8,$M$7:$M$12) + SUMIF($N$7:$N$12,AO8,$L$7:$L$12) -> 3 | AV8: =AO8 -> Uruguay | AW8: =IF(AZ8=AZ9,AV9,IF(AZ8=AZ10,AV10,IF(AZ8=AZ7,AV7,""))) | AX8: =IF(AW8="","",IFERROR(VLOOKUP(CONCATENATE(AV8,"_",AW8),$AI$7:$AL$16,4,FALSE),VLOOKUP(CONCATENATE(AW8,"_",AV8),$AI$7:$AL$16,4,FALSE))) | AY8: =IF(AX8="",1,IF(AX8=AV8,1,0)) -> 1 | AZ8: =-AP8*10000000 - AQ8*10000 - AR8*100 -> -60030600 | BA8: =AZ8-AY8*10 -> -60030610 | BB8: =BA8+N24 -> -60030608
B9: 2 | C9: =IFERROR(VLOOKUP($B9,$AN$7:$AS$11,C$5,FALSE),"") -> Uruguay | D9: =IFERROR(VLOOKUP($B9,$AN$7:$AS$11,D$5,FALSE),"") -> 6 | E9: =IFERROR(VLOOKUP($B9,$AN$7:$AS$11,E$5,FALSE),"") -> 6 | F9: =IFERROR(VLOOKUP($B9,$AN$7:$AS$11,F$5,FALSE),"") -> 3 | G9: =IFERROR(VLOOKUP($B9,$AN$7:$AS$11,G$5,FALSE),"") -> 3 | I9: =I7+16 -> 31 | J9: 44893 | K9: Corea | L9: 1 | M9: 0 | N9: Gana | AI9: =CONCATENATE(K9,"_",N9) -> Corea_Gana | AJ9: =IF(L9>M9,3,IF(L9<M9,0,1)) -> 3 | AK9: =IF(AJ9=3,0,IF(AJ9=1,1,3)) -> 0 | AL9: =IF(AJ9>AK9,K9,IF(AK9>AJ9,N9,"SIN GANADOR")) -> Corea | AN9: =_xlfn.RANK.EQ(BB9,BB$7:BB$11,1) -> 3 | AO9: Corea | AP9: =SUMIF($K$7:$K$12,AO9,$AJ$7:$AJ$12) + SUMIF($N$7:$N$12,AO9,$AK$7:$AK$12) -> 3 | AQ9: =AR9-AS9 -> -4 | AR9: =SUMIF($K$7:$K$12,AO9,$L$7:$L$12) + SUMIF($N$7:$N$12,AO9,$M$7:$M$12) -> 1 | AS9: =SUMIF($K$7:$K$12,AO9,$M$7:$M$12) + SUMIF($N$7:$N$12,AO9,$L$7:$L$12) -> 5 | AV9: =AO9 -> Corea | AW9: =IF(AZ9=AZ10,AV10,IF(AZ9=AZ7,AV7,IF(AZ9=AZ8,AV8,""))) | AX9: =IF(AW9="","",IFERROR(VLOOKUP(CONCATENATE(AV9,"_",AW9),$AI$7:$AL$16,4,FALSE),VLOOKUP(CONCATENATE(AW9,"_",AV9),$AI$7:$AL$16,4,FALSE))) | AY9: =IF(AX9="",1,IF(AX9=AV9,1,0)) -> 1 | AZ9: =-AP9*10000000 - AQ9*10000 - AR9*100 -> -29960100 | BA9: =AZ9-AY9*10 -> -29960110 | BB9: =BA9+N25 -> -29960107
B10: 3 | C10: =IFERROR(VLOOKUP($B10,$AN$7:$AS$11,C$5,FALSE),"") -> Corea | D10: =IFERROR(VLOOKUP($B10,$AN$7:$AS$11,D$5,FALSE),"") -> 3 | E10: =IFERROR(VLOOKUP($B10,$AN$7:$AS$11,E$5,FALSE),"") -> 1 | F10: =IFERROR(VLOOKUP($B10,$AN$7:$AS$11,F$5,FALSE),"") -> 5 | G10: =IFERROR(VLOOKUP($B10,$AN$7:$AS$11,G$5,FALSE),"") -> -4 | I10: =I8+16 -> 32 | J10: 44893 | K10: Portugal | L10: 3 | M10: 2 | N10: Uruguay | AI10: =CONCATENATE(K10,"_",N10) -> Portugal_Uruguay | AJ10: =IF(L10>M10,3,IF(L10<M10,0,1)) -> 3 | AK10: =IF(AJ10=3,0,IF(AJ10=1,1,3)) -> 0 | AL10: =IF(AJ10>AK10,K10,IF(AK10>AJ10,N10,"SIN GANADOR")) -> Portugal | AN10: =_xlfn.RANK.EQ(BB10,BB$7:BB$11,1) -> 4 | AO10: Gana | AP10: =SUMIF($K$7:$K$12,AO10,$AJ$7:$AJ$12) + SUMIF($N$7:$N$12,AO10,$AK$7:$AK$12) -> 0 | AQ10: =AR10-AS10 -> -6 | AR10: =SUMIF($K$7:$K$12,AO10,$L$7:$L$12) + SUMIF($N$7:$N$12,AO10,$M$7:$M$12) -> 0 | AS10: =SUMIF($K$7:$K$12,AO10,$M$7:$M$12) + SUMIF($N$7:$N$12,AO10,$L$7:$L$12) -> 6 | AV10: =AO10 -> Gana | AW10: =IF(AZ10=AZ7,AV7,IF(AZ10=AZ8,AV8,IF(AZ10=AZ9,AV9,""))) | AX10: =IF(AW10="","",IFERROR(VLOOKUP(CONCATENATE(AV10,"_",AW10),$AI$7:$AL$16,4,FALSE),VLOOKUP(CONCATENATE(AW10,"_",AV10),$AI$7:$AL$16,4,FALSE))) | AY10: =IF(AX10="",1,IF(AX10=AV10,1,0)) -> 1 | AZ10: =-AP10*10000000 - AQ10*10000 - AR10*100 -> 60000 | BA10: =AZ10-AY10*10 -> 59990 | BB10: =BA10+N26 -> 59994
B11: 4 | C11: =IFERROR(VLOOKUP($B11,$AN$7:$AS$11,C$5,FALSE),"") -> Gana | D11: =IFERROR(VLOOKUP($B11,$AN$7:$AS$11,D$5,FALSE),"") -> 0 | E11: =IFERROR(VLOOKUP($B11,$AN$7:$AS$11,E$5,FALSE),"") -> 0 | F11: =IFERROR(VLOOKUP($B11,$AN$7:$AS$11,F$5,FALSE),"") -> 6 | G11: =IFERROR(VLOOKUP($B11,$AN$7:$AS$11,G$5,FALSE),"") -> -6 | I11: =I9+16 -> 47 | J11: 44897 | K11: Gana | L11: 0 | M11: 2 | N11: Uruguay | AI11: =CONCATENATE(K11,"_",N11) -> Gana_Uruguay | AJ11: =IF(L11>M11,3,IF(L11<M11,0,1)) -> 0 | AK11: =IF(AJ11=3,0,IF(AJ11=1,1,3)) -> 3 | AL11: =IF(AJ11>AK11,K11,IF(AK11>AJ11,N11,"SIN GANADOR")) -> Uruguay
I12: =I10+16 -> 48 | J12: 44897 | K12: Corea | L12: 0 | M12: 3 | N12: Portugal | AI12: =CONCATENATE(K12,"_",N12) -> Corea_Portugal | AJ12: =IF(L12>M12,3,IF(L12<M12,0,1)) -> 0 | AK12: =IF(AJ12=3,0,IF(AJ12=1,1,3)) -> 3 | AL12: =IF(AJ12>AK12,K12,IF(AK12>AJ12,N12,"SIN GANADOR")) -> Portugal
B22: El recuadro de la derecha sirve para desempatar, en caso de que haya empate entre | I22: 1 | J22: Escoja por prioridad los siguientes equipos:
B23: uno o más equipos en todos los criterios considerados. | I23: =IF(J23="",0,1) -> 1 | J23: Portugal | M23: 1 | N23: =IF(J23="",0,M23) -> 1
B24: Para utilizarlo, asigne una prioridad entre 1 y 5 (siendo más bajo mejor) a cada equipo. | I24: =IF(J24="",0,1) -> 1 | J24: Uruguay | M24: 2 | N24: =IF(J24="",0,M24) -> 2
B25: Puede pensarlo como el lugar que quedarían en la tabla de posiciones. | I25: =IF(J25="",0,1) -> 1 | J25: Corea | M25: 3 | N25: =IF(J25="",0,M25) -> 3
B26: A modo de ejemplo, si su predicción es que todos los partidos terminan 0-0, el orden | I26: =IF(J26="",0,1) -> 1 | J26: Gana | M26: 4 | N26: =IF(J26="",0,M26) -> 4
B27: asignado en este recuadro es el que finalmente quedará en la tabla de posiciones. | N27: =IF(J27="",0,M27) -> 0

Sheet Play-Off
B2: Octavos de Final
G4: Cuartos de Final
B5: 49 | C5: Resultado | D5: Penales
B6: ='GRUPO A'!C8 -> Holanda | C6: 1
B7: ='GRUPO B'!C9 -> Gales | C7: 0 | G7: 57 | H7: Resultado | I7: Penales
G8: =IF(C7>C6,B7,IF(C6>C7,B6,IF(D7>D6,B7,IF(D6>D7,B6,"")))) -> Holanda | H8: 0 | L8: Semi Final
B9: 50 | C9: Resultado | D9: Penales | G9: =IF(C11>C10,B11,IF(C10>C11,B10,IF(D11>D10,B11,IF(D10>D11,B10,"")))) -> Argentina | H9: 3
B10: ='GRUPO C'!C8 -> Argentina | C10: 2
B11: ='GRUPO D'!C9 -> Dinamarca | C11: 0 | L11: 61 | M11: Resultado | N11: Penales
L12: =IF(H9>H8,G9,IF(H8>H9,G8,IF(I9>I8,G9,IF(I8>I9,G8,"")))) -> Argentina | M12: 1
B13: 53 | C13: Resultado | D13: Penales | L13: =IF(H17>H16,G17,IF(H16>H17,G16,IF(I17>I16,G17,IF(I16>I17,G16,"")))) -> Brasil | M13: 3
B14: ='GRUPO E'!C8 -> España | C14: 2
B15: ='GRUPO F'!C9 -> Belgica | C15: 1 | G15: 58 | H15: Resultado | I15: Penales
G16: =IF(C15>C14,B15,IF(C14>C15,B14,IF(D15>D14,B15,IF(D14>D15,B14,"")))) -> España | H16: 0 | Q16: Final
B17: 54 | C17: Resultado | D17: Penales | G17: =IF(C19>C18,B19,IF(C18>C19,B18,IF(D19>D18,B19,IF(D18>D19,B18,"")))) -> Brasil | H17: 3
B18: ='GRUPO G'!C8 -> Brasil | C18: 3
B19: ='GRUPO H'!C9 -> Uruguay | C19: 0 | Q19: 64 | R19: Resultado | S19: Penales
Q20: =IF(M13>M12,L13,IF(M12>M13,L12,IF(N13>N12,L13,IF(N12>N13,L12,"")))) -> Brasil | R20: 3
B21: 51 | C21: Resultado | D21: Penales | Q21: =IF(M29>M28,L29,IF(M28>M29,L28,IF(N29>N28,L29,IF(N28>N29,L28,"")))) -> Francia | R21: 1
B22: ='GRUPO B'!C8 -> Inglaterra | C22: 1
B23: ='GRUPO A'!C9 -> Senegal | C23: 0 | G23: 59 | H23: Resultado | I23: Penales | V23: RESULTADOS TORNEO
G24: =IF(C23>C22,B23,IF(C22>C23,B22,IF(D23>D22,B23,IF(D22>D23,B22,"")))) -> Inglaterra | H24: 0 | V24: CAMPEÓN | W24: =IF(R20>R21,Q20,IF(R21>R20,Q21,IF(S20>S21,Q20,IF(S21>S20,Q21,"")))) -> Brasil
B25: 52 | C25: Resultado | D25: Penales | G25: =IF(C27>C26,B27,IF(C26>C27,B26,IF(D27>D26,B27,IF(D26>D27,B26,"")))) -> Francia | H25: 2 | Q25: Tercer y Cuarto Lugar | V25: SUB CAMPEÓN | W25: =IF(W24=Q20,Q21,IF(W24=Q21,Q20,"")) -> Francia
B26: ='GRUPO D'!C8 -> Francia | C26: 2 | V26: TERCER LUGAR | W26: =IF(R29>R30,Q29,IF(R30>R29,Q30,IF(S29>S30,Q29,IF(S30>S29,Q30,"")))) -> Portugal
B27: ='GRUPO C'!C9 -> Polonia | C27: 0 | L27: 62 | M27: Resultado | N27: Penales
L28: =IF(H25>H24,G25,IF(H24>H25,G24,IF(I25>I24,G25,IF(I24>I25,G24,"")))) -> Francia | M28: 2 | N28: 2 | Q28: 63 | R28: Resultado | S28: Penales
