Workbook

Sheet INFORMACION
J1: =SUM('GRUPO A'!AG13,'GRUPO B'!AG13,'GRUPO C'!AG13,'GRUPO D'!AG13,#REF!) -> #REF!
B2: Información del Jugador
B3: Nombre
B4: Mail
B6: Goleador

Sheet GRUPO A
B3: GRUPO A
C5: 2 | D5: 3 | E5: 5 | F5: 6 | G5: 4
B6: Tabla de Posiciones | J6: Fecha | K6: Partidos | AJ6: 1 | AK6: 2 | AL6: Ganador | AN6: Orden | AO6: Equipo | AP6: Puntos | AQ6: DG | AR6: GF | AS6: GC | AV6: Equipo | AW6: Empatado Con | AX6: Ganador | AY6: Ganador? | AZ6: Formula Rank | BA6: Formula Rank Con Duelo Directo | BB6: Formula Rank Con Prioridad
B7: Posición | C7: Equipo | D7: Puntos | E7: GF | F7: GC | G7: DG | I7: 1 | J7: 46184 | K7: México | N7: Sudáfrica | AG7: =IF(OR(L7="",M7=""),1,0) -> 1 | AI7: =CONCATENATE(K7,"_",N7) -> México_Sudáfrica | AJ7: =IF(L7>M7,3,IF(L7<M7,0,1)) -> 1 | AK7: =IF(AJ7=3,0,IF(AJ7=1,1,3)) -> 1 | AL7: =IF(AJ7>AK7,K7,IF(AK7>AJ7,N7,"SIN GANADOR")) -> SIN GANADOR | AN7: =_xlfn.RANK.EQ(BB7,BB$7:BB$11,1) -> 1 | AO7: =J23 -> México | AP7: =SUMIF($K$7:$K$12,AO7,$AJ$7:$AJ$12) + SUMIF($N$7:$N$12,AO7,$AK$7:$AK$12) -> 3 | AQ7: =AR7-AS7 -> 0 | AR7: =SUMIF($K$7:$K$12,AO7,$L$7:$L$12) + SUMIF($N$7:$N$12,AO7,$M$7:$M$12) -> 0 | AS7: =SUMIF($K$7:$K$12,AO7,$M$7:$M$12) + SUMIF($N$7:$N$12,AO7,$L$7:$L$12) -> 0 | AV7: =AO7 -> México | AW7: =IF(AZ7=AZ8,AV8,IF(AZ7=AZ9,AV9,IF(AZ7=AZ10,AV10,""))) -> Sudáfrica | AX7: =IF(AW7="","",IFERROR(VLOOKUP(CONCATENATE(AV7,"_",AW7),$AI$7:$AL$16,4,FALSE),VLOOKUP(CONCATENATE(AW7,"_",AV7),$AI$7:$AL$16,4,FALSE))) -> SIN GANADOR | AY7: =IF(AX7="",1,IF(AX7=AV7,1,0)) -> 0 | AZ7: =-AP7*10000000 - AQ7*10000 - AR7*100 -> -30000000 | BA7: =AZ7-AY7*10 -> -30000000 | BB7: =BA7+N23 -> -29999999
B8: 1 | C8: =IFERROR(VLOOKUP($B8,$AN$7:$AS$11,C$5,FALSE),"") -> México | D8: =IFERROR(VLOOKUP($B8,$AN$7:$AS$11,D$5,FALSE),"") -> 3 | E8: =IFERROR(VLOOKUP($B8,$AN$7:$AS$11,E$5,FALSE),"") -> 0 | F8: =IFERROR(VLOOKUP($B8,$AN$7:$AS$11,F$5,FALSE),"") -> 0 | G8: =IFERROR(VLOOKUP($B8,$AN$7:$AS$11,G$5,FALSE),"") -> 0 | I8: 2 | J8: 46184 | K8: Corea | N8: República Checa | AG8: =IF(OR(L8="",M8=""),1,0) -> 1 | AI8: =CONCATENATE(K8,"_",N8) -> Corea_República Checa | AJ8: =IF(L8>M8,3,IF(L8<M8,0,1)) -> 1 | AK8: =IF(AJ8=3,0,IF(AJ8=1,1,3)) -> 1 | AL8: =IF(AJ8>AK8,K8,IF(AK8>AJ8,N8,"SIN GANADOR")) -> SIN GANADOR | AN8: =_xlfn.RANK.EQ(BB8,BB$7:BB$11,1) -> 2 | AO8: =J24 -> Sudáfrica | AP8: =SUMIF($K$7:$K$12,AO8,$AJ$7:$AJ$12) + SUMIF($N$7:$N$12,AO8,$AK$7:$AK$12) -> 3 | AQ8: =AR8-AS8 -> 0 | AR8: =SUMIF($K$7:$K$12,AO8,$L$7:$L$12) + SUMIF($N$7:$N$12,AO8,$M$7:$M$12) -> 0 | AS8: =SUMIF($K$7:$K$12,AO8,$M$7:$M$12) + SUMIF($N$7:$N$12,AO8,$L$7:$L$12) -> 0 | AV8: =AO8 -> Sudáfrica | AW8: =IF(AZ8=AZ9,AV9,IF(AZ8=AZ10,AV10,IF(AZ8=AZ7,AV7,""))) -> Corea | AX8: =IF(AW8="","",IFERROR(VLOOKUP(CONCATENATE(AV8,"_",AW8),$AI$7:$AL$16,4,FALSE),VLOOKUP(CONCATENATE(AW8,"_",AV8),$AI$7:$AL$16,4,FALSE))) -> SIN GANADOR | AY8: =IF(AX8="",1,IF(AX8=AV8,1,0)) -> 0 | AZ8: =-AP8*10000000 - AQ8*10000 - AR8*100 -> -30000000 | BA8: =AZ8-AY8*10 -> -30000000 | BB8: =BA8+N24 -> -29999998
B9: 2 | C9: =IFERROR(VLOOKUP($B9,$AN$7:$AS$11,C$5,FALSE),"") -> Sudáfrica | D9: =IFERROR(VLOOKUP($B9,$AN$7:$AS$11,D$5,FALSE),"") -> 3 | E9: =IFERROR(VLOOKUP($B9,$AN$7:$AS$11,E$5,FALSE),"") -> 0 | F9: =IFERROR(VLOOKUP($B9,$AN$7:$AS$11,F$5,FALSE),"") -> 0 | G9: =IFERROR(VLOOKUP($B9,$AN$7:$AS$11,G$5,FALSE),"") -> 0 | I9: 25 | J9: 46191 | K9: República Checa | N9: Sudáfrica | AG9: =IF(OR(L9="",M9=""),1,0) -> 1 | AI9: =CONCATENATE(K9,"_",N9) -> República Checa_Sudáfrica | AJ9: =IF(L9>M9,3,IF(L9<M9,0,1)) -> 1 | AK9: =IF(AJ9=3,0,IF(AJ9=1,1,3)) -> 1 | AL9: =IF(AJ9>AK9,K9,IF(AK9>AJ9,N9,"SIN GANADOR")) -> SIN GANADOR | AN9: =_xlfn.RANK.EQ(BB9,BB$7:BB$11,1) -> 3 | AO9: =J25 -> Corea | AP9: =SUMIF($K$7:$K$12,AO9,$AJ$7:$AJ$12) + SUMIF($N$7:$N$12,AO9,$AK$7:$AK$12) -> 3 | AQ9: =AR9-AS9 -> 0 | AR9: =SUMIF($K$7:$K$12,AO9,$L$7:$L$12) + SUMIF($N$7:$N$12,AO9,$M$7:$M$12) -> 0 | AS9: =SUMIF($K$7:$K$12,AO9,$M$7:$M$12) + SUMIF($N$7:$N$12,AO9,$L$7:$L$12) -> 0 | AV9: =AO9 -> Corea | AW9: =IF(AZ9=AZ10,AV10,IF(AZ9=AZ7,AV7,IF(AZ9=AZ8,AV8,""))) -> República Checa | AX9: =IF(AW9="","",IFERROR(VLOOKUP(CONCATENATE(AV9,"_",AW9),$AI$7:$AL$16,4,FALSE),VLOOKUP(CONCATENATE(AW9,"_",AV9),$AI$7:$AL$16,4,FALSE))) -> SIN GANADOR | AY9: =IF(AX9="",1,IF(AX9=AV9,1,0)) -> 0 | AZ9: =-AP9*10000000 - AQ9*10000 - AR9*100 -> -30000000 | BA9: =AZ9-AY9*10 -> -30000000 | BB9: =BA9+N25 -> -29999997
B10: 3 | C10: =IFERROR(VLOOKUP($B10,$AN$7:$AS$11,C$5,FALSE),"") -> Corea | D10: =IFERROR(VLOOKUP($B10,$AN$7:$AS$11,D$5,FALSE),"") -> 3 | E10: =IFERROR(VLOOKUP($B10,$AN$7:$AS$11,E$5,FALSE),"") -> 0 | F10: =IFERROR(VLOOKUP($B10,$AN$7:$AS$11,F$5,FALSE),"") -> 0 | G10: =IFERROR(VLOOKUP($B10,$AN$7:$AS$11,G$5,FALSE),"") -> 0 | I10: 28 | J10: 46191 | K10: México | N10: Corea | AG10: =IF(OR(L10="",M10=""),1,0) -> 1 | AI10: =CONCATENATE(K10,"_",N10) -> México_Corea | AJ10: =IF(L10>M10,3,IF(L10<M10,0,1)) -> 1 | AK10: =IF(AJ10=3,0,IF(AJ10=1,1,3)) -> 1 | AL10: =IF(AJ10>AK10,K10,IF(AK10>AJ10,N10,"SIN GANADOR")) -> SIN GANADOR | AN10: =_xlfn.RANK.EQ(BB10,BB$7:BB$11,1) -> 4 | AO10: =J26 -> República Checa | AP10: =SUMIF($K$7:$K$12,AO10,$AJ$7:$AJ$12) + SUMIF($N$7:$N$12,AO10,$AK$7:$AK$12) -> 3 | AQ10: =AR10-AS10 -> 0 | AR10: =SUMIF($K$7:$K$12,AO10,$L$7:$L$12) + SUMIF($N$7:$N$12,AO10,$M$7:$M$12) -> 0 | AS10: =SUMIF($K$7:$K$12,AO10,$M$7:$M$12) + SUMIF($N$7:$N$12,AO10,$L$7:$L$12) -> 0 | AV10: =AO10 -> República Checa | AW10: =IF(AZ10=AZ7,AV7,IF(AZ10=AZ8,AV8,IF(AZ10=AZ9,AV9,""))) -> México | AX10: =IF(AW10="","",IFERROR(VLOOKUP(CONCATENATE(AV10,"_",AW10),$AI$7:$AL$16,4,FALSE),VLOOKUP(CONCATENATE(AW10,"_",AV10),$AI$7:$AL$16,4,FALSE))) -> SIN GANADOR | AY10: =IF(AX10="",1,IF(AX10=AV10,1,0)) -> 0 | AZ10: =-AP10*10000000 - AQ10*10000 - AR10*100 -> -30000000 | BA10: =AZ10-AY10*10 -> -30000000 | BB10: =BA10+N26 -> -29999996
B11: 4 | C11: =IFERROR(VLOOKUP($B11,$AN$7:$AS$11,C$5,FALSE),"") -> República Checa | D11: =IFERROR(VLOOKUP($B11,$AN$7:$AS$11,D$5,FALSE),"") -> 3 | E11: =IFERROR(VLOOKUP($B11,$AN$7:$AS$11,E$5,FALSE),"") -> 0 | F11: =IFERROR(VLOOKUP($B11,$AN$7:$AS$11,F$5,FALSE),"") -> 0 | G11: =IFERROR(VLOOKUP($B11,$AN$7:$AS$11,G$5,FALSE),"") -> 0 | I11: 53 | J11: 46197 | K11: República Checa | N11: México | AG11: =IF(OR(L11="",M11=""),1,0) -> 1 | AI11: =CONCATENATE(K11,"_",N11) -> República Checa_México | AJ11: =IF(L11>M11,3,IF(L11<M11,0,1)) -> 1 | AK11: =IF(AJ11=3,0,IF(AJ11=1,1,3)) -> 1 | AL11: =IF(AJ11>AK11,K11,IF(AK11>AJ11,N11,"SIN GANADOR")) -> SIN GANADOR
I12: 54 | J12: 46197 | K12: Sudáfrica | N12: Corea | AG12: =IF(OR(L12="",M12=""),1,0) -> 1 | AI12: =CONCATENATE(K12,"_",N12) -> Sudáfrica_Corea | AJ12: =IF(L12>M12,3,IF(L12<M12,0,1)) -> 1 | AK12: =IF(AJ12=3,0,IF(AJ12=1,1,3)) -> 1 | AL12: =IF(AJ12>AK12,K12,IF(AK12>AJ12,N12,"SIN GANADOR")) -> SIN GANADOR
AG13: =IF(SUM(AG7:AG12)>0,1,0) -> 1
B22: El recuadro de la derecha sirve para desempatar, en caso de que haya empate entre | I22: 1 | J22: Escoja por prioridad los siguientes equipos:
B23: uno o más equipos en todos los criterios considerados. | I23: =IF(J23="",0,1) -> 1 | J23: México | M23: 1 | N23: =IF(J23="",0,M23) -> 1
B24: Para utilizarlo, asigne una prioridad entre 1 y 5 (siendo más bajo mejor) a cada equipo. | I24: =IF(J24="",0,1) -> 1 | J24: Sudáfrica | M24: 2 | N24: =IF(J24="",0,M24) -> 2
B25: Puede pensarlo como el lugar que quedarían en la tabla de posiciones. | I25: =IF(J25="",0,1) -> 1 | J25: Corea | M25: 3 | N25: =IF(J25="",0,M25) -> 3
B26: A modo de ejemplo, si su predicción es que todos los partidos terminan 0-0, el orden | I26: =IF(J26="",0,1) -> 1 | J26: República Checa | M26: 4 | N26: =IF(J26="",0,M26) -> 4
B27: asignado en este recuadro es el que finalmente quedará en la tabla de posiciones. | N27: =IF(J27="",0,M27) -> 0

Sheet GRUPO B
B3: GRUPO B
C5: 2 | D5: 3 | E5: 5 | F5: 6 | G5: 4
B6: Tabla de Posiciones | J6: Fecha | K6: Partidos | AJ6: 1 | AK6: 2 | AL6: Ganador | AN6: Orden | AO6: Equipo | AP6: Puntos | AQ6: DG | AR6: GF | AS6: GC | AV6: Equipo | AW6: Empatado Con | AX6: Ganador | AY6: Ganador? | AZ6: Formula Rank | BA6: Formula Rank Con Duelo Directo | BB6: Formula Rank Con Prioridad
B7: Posición | C7: Equipo | D7: Puntos | E7: GF | F7: GC | G7: DG | I7: 3 | J7: 46185 | K7: Canadá | N7: Bosnia | AG7: =IF(OR(L7="",M7=""),1,0) -> 1 | AI7: =CONCATENATE(K7,"_",N7) -> Canadá_Bosnia | AJ7: =IF(L7>M7,3,IF(L7<M7,0,1)) -> 1 | AK7: =IF(AJ7=3,0,IF(AJ7=1,1,3)) -> 1 | AL7: =IF(AJ7>AK7,K7,IF(AK7>AJ7,N7,"SIN GANADOR")) -> SIN GANADOR | AN7: =_xlfn.RANK.EQ(BB7,BB$7:BB$11,1) -> 1 | AO7: =J23 -> Canadá | AP7: =SUMIF($K$7:$K$12,AO7,$AJ$7:$AJ$12) + SUMIF($N$7:$N$12,AO7,$AK$7:$AK$12) -> 3 | AQ7: =AR7-AS7 -> 0 | AR7: =SUMIF($K$7:$K$12,AO7,$L$7:$L$12) + SUMIF($N$7:$N$12,AO7,$M$7:$M$12) -> 0 | AS7: =SUMIF($K$7:$K$12,AO7,$M$7:$M$12) + SUMIF($N$7:$N$12,AO7,$L$7:$L$12) -> 0 | AV7: =AO7 -> Canadá | AW7: =IF(AZ7=AZ8,AV8,IF(AZ7=AZ9,AV9,IF(AZ7=AZ10,AV10,""))) -> Bosnia | AX7: =IF(AW7="","",IFERROR(VLOOKUP(CONCATENATE(AV7,"_",AW7),$AI$7:$AL$16,4,FALSE),VLOOKUP(CONCATENATE(AW7,"_",AV7),$AI$7:$AL$16,4,FALSE))) -> SIN GANADOR | AY7: =IF(AX7="",1,IF(AX7=AV7,1,0)) -> 0 | AZ7: =-AP7*10000000 - AQ7*10000 - AR7*100 -> -30000000 | BA7: =AZ7-AY7*10 -> -30000000 | BB7: =BA7+N23 -> -29999999
B8: 1 | C8: =IFERROR(VLOOKUP($B8,$AN$7:$AS$11,C$5,FALSE),"") -> Canadá | D8: =IFERROR(VLOOKUP($B8,$AN$7:$AS$11,D$5,FALSE),"") -> 3 | E8: =IFERROR(VLOOKUP($B8,$AN$7:$AS$11,E$5,FALSE),"") -> 0 | F8: =IFERROR(VLOOKUP($B8,$AN$7:$AS$11,F$5,FALSE),"") -> 0 | G8: =IFERROR(VLOOKUP($B8,$AN$7:$AS$11,G$5,FALSE),"") -> 0 | I8: 5 | J8: 46186 | K8: Catar | N8: Suiza | AG8: =IF(OR(L8="",M8=""),1,0) -> 1 | AI8: =CONCATENATE(K8,"_",N8) -> Catar_Suiza | AJ8: =IF(L8>M8,3,IF(L8<M8,0,1)) -> 1 | AK8: =IF(AJ8=3,0,IF(AJ8=1,1,3)) -> 1 | AL8: =IF(AJ8>AK8,K8,IF(AK8>AJ8,N8,"SIN GANADOR")) -> SIN GANADOR | AN8: =_xlfn.RANK.EQ(BB8,BB$7:BB$11,1) -> 2 | AO8: =J24 -> Bosnia | AP8: =SUMIF($K$7:$K$12,AO8,$AJ$7:$AJ$12) + SUMIF($N$7:$N$12,AO8,$AK$7:$AK$12) -> 3 | AQ8: =AR8-AS8 -> 0 | AR8: =SUMIF($K$7:$K$12,AO8,$L$7:$L$12) + SUMIF($N$7:$N$12,AO8,$M$7:$M$12) -> 0 | AS8: =SUMIF($K$7:$K$12,AO8,$M$7:$M$12) + SUMIF($N$7:$N$12,AO8,$L$7:$L$12) -> 0 | AV8: =AO8 -> Bosnia | AW8: =IF(AZ8=AZ9,AV9,IF(AZ8=AZ10,AV10,IF(AZ8=AZ7,AV7,""))) -> Suiza | AX8: =IF(AW8="","",IFERROR(VLOOKUP(CONCATENATE(AV8,"_",AW8),$AI$7:$AL$16,4,FALSE),VLOOKUP(CONCATENATE(AW8,"_",AV8),$AI$7:$AL$16,4,FALSE))) -> SIN GANADOR | AY8: =IF(AX8="",1,IF(AX8=AV8,1,0)) -> 0 | AZ8: =-AP8*10000000 - AQ8*10000 - AR8*100 -> -30000000 | BA8: =AZ8-AY8*10 -> -30000000 | BB8: =BA8+N24 -> -29999998
B9: 2 | C9: =IFERROR(VLOOKUP($B9,$AN$7:$AS$11,C$5,FALSE),"") -> Bosnia | D9: =IFERROR(VLOOKUP($B9,$AN$7:$AS$11,D$5,FALSE),"") -> 3 | E9: =IFERROR(VLOOKUP($B9,$AN$7:$AS$11,E$5,FALSE),"") -> 0 | F9: =IFERROR(VLOOKUP($B9,$AN$7:$AS$11,F$5,FALSE),"") -> 0 | G9: =IFERROR(VLOOKUP($B9,$AN$7:$AS$11,G$5,FALSE),"") -> 0 | I9: 26 | J9: 46191 | K9: Suiza | N9: Bosnia | AG9: =IF(OR(L9="",M9=""),1,0) -> 1 | AI9: =CONCATENATE(K9,"_",N9) -> Suiza_Bosnia | AJ9: =IF(L9>M9,3,IF(L9<M9,0,1)) -> 1 | AK9: =IF(AJ9=3,0,IF(AJ9=1,1,3)) -> 1 | AL9: =IF(AJ9>AK9,K9,IF(AK9>AJ9,N9,"SIN GANADOR")) -> SIN GANADOR | AN9: =_xlfn.RANK.EQ(BB9,BB$7:BB$11,1) -> 3 | AO9: =J25 -> Suiza | AP9: =SUMIF($K$7:$K$12,AO9,$AJ$7:$AJ$12) + SUMIF($N$7:$N$12,AO9,$AK$7:$AK$12) -> 3 | AQ9: =AR9-AS9 -> 0 | AR9: =SUMIF($K$7:$K$12,AO9,$L$7:$L$12) + SUMIF($N$7:$N$12,AO9,$M$7:$M$12) -> 0 | AS9: =SUMIF($K$7:$K$12,AO9,$M$7:$M$12) + SUMIF($N$7:$N$12,AO9,$L$7:$L$12) -> 0 | AV9: =AO9 -> Suiza | AW9: =IF(AZ9=AZ10,AV10,IF(AZ9=AZ7,AV7,IF(AZ9=AZ8,AV8,""))) -> Catar | AX9: =IF(AW9="","",IFERROR(VLOOKUP(CONCATENATE(AV9,"_",AW9),$AI$7:$AL$16,4,FALSE),VLOOKUP(CONCATENATE(AW9,"_",AV9),$AI$7:$AL$16,4,FALSE))) -> SIN GANADOR | AY9: =IF(AX9="",1,IF(AX9=AV9,1,0)) -> 0 | AZ9: =-AP9*10000000 - AQ9*10000 - AR9*100 -> -30000000 | BA9: =AZ9-AY9*10 -> -30000000 | BB9: =BA9+N25 -> -29999997
B10: 3 | C10: =IFERROR(VLOOKUP($B10,$AN$7:$AS$11,C$5,FALSE),"") -> Suiza | D10: =IFERROR(VLOOKUP($B10,$AN$7:$AS$11,D$5,FALSE),"") -> 3 | E10: =IFERROR(VLOOKUP($B10,$AN$7:$AS$11,E$5,FALSE),"") -> 0 | F10: =IFERROR(VLOOKUP($B10,$AN$7:$AS$11,F$5,FALSE),"") -> 0 | G10: =IFERROR(VLOOKUP($B10,$AN$7:$AS$11,G$5,FALSE),"") -> 0 | I10: 27 | J10: 46191 | K10: Canadá | N10: Catar | AG10: =IF(OR(L10="",M10=""),1,0) -> 1 | AI10: =CONCATENATE(K10,"_",N10) -> Canadá_Catar | AJ10: =IF(L10>M10,3,IF(L10<M10,0,1)) -> 1 | AK10: =IF(AJ10=3,0,IF(AJ10=1,1,3)) -> 1 | AL10: =IF(AJ10>AK10,K10,IF(AK10>AJ10,N10,"SIN GANADOR")) -> SIN GANADOR | AN10: =_xlfn.RANK.EQ(BB10,BB$7:BB$11,1) -> 4 | AO10: =J26 -> Catar | AP10: =SUMIF($K$7:$K$12,AO10,$AJ$7:$AJ$12) + SUMIF($N$7:$N$12,AO10,$AK$7:$AK$12) -> 3 | AQ10: =AR10-AS10 -> 0 | AR10: =SUMIF($K$7:$K$12,AO10,$L$7:$L$12) + SUMIF($N$7:$N$12,AO10,$M$7:$M$12) -> 0 | AS10: =SUMIF($K$7:$K$12,AO10,$M$7:$M$12) + SUMIF($N$7:$N$12,AO10,$L$7:$L$12) -> 0 | AV10: =AO10 -> Catar | AW10: =IF(AZ10=AZ7,AV7,IF(AZ10=AZ8,AV8,IF(AZ10=AZ9,AV9,""))) -> Canadá | AX10: =IF(AW10="","",IFERROR(VLOOKUP(CONCATENATE(AV10,"_",AW10),$AI$7:$AL$16,4,FALSE),VLOOKUP(CONCATENATE(AW10,"_",AV10),$AI$7:$AL$16,4,FALSE))) -> SIN GANADOR | AY10: =IF(AX10="",1,IF(AX10=AV10,1,0)) -> 0 | AZ10: =-AP10*10000000 - AQ10*10000 - AR10*100 -> -30000000 | BA10: =AZ10-AY10*10 -> -30000000 | BB10: =BA10+N26 -> -29999996
B11: 4 | C11: =IFERROR(VLOOKUP($B11,$AN$7:$AS$11,C$5,FALSE),"") -> Catar | D11: =IFERROR(VLOOKUP($B11,$AN$7:$AS$11,D$5,FALSE),"") -> 3 | E11: =IFERROR(VLOOKUP($B11,$AN$7:$AS$11,E$5,FALSE),"") -> 0 | F11: =IFERROR(VLOOKUP($B11,$AN$7:$AS$11,F$5,FALSE),"") -> 0 | G11: =IFERROR(VLOOKUP($B11,$AN$7:$AS$11,G$5,FALSE),"") -> 0 | I11: 49 | J11: 46197 | K11: Suiza | N11: Canadá | AG11: =IF(OR(L11="",M11=""),1,0) -> 1 | AI11: =CONCATENATE(K11,"_",N11) -> Suiza_Canadá | AJ11: =IF(L11>M11,3,IF(L11<M11,0,1)) -> 1 | AK11: =IF(AJ11=3,0,IF(AJ11=1,1,3)) -> 1 | AL11: =IF(AJ11>AK11,K11,IF(AK11>AJ11,N11,"SIN GANADOR")) -> SIN GANADOR
I12: 50 | J12: 46197 | K12: Bosnia | N12: Catar | AG12: =IF(OR(L12="",M12=""),1,0) -> 1 | AI12: =CONCATENATE(K12,"_",N12) -> Bosnia_Catar | AJ12: =IF(L12>M12,3,IF(L12<M12,0,1)) -> 1 | AK12: =IF(AJ12=3,0,IF(AJ12=1,1,3)) -> 1 | AL12: =IF(AJ12>AK12,K12,IF(AK12>AJ12,N12,"SIN GANADOR")) -> SIN GANADOR
AG13: =IF(SUM(AG7:AG12)>0,1,0) -> 1
B22: El recuadro de la derecha sirve para desempatar, en caso de que haya empate entre | I22: 1 | J22: Escoja por prioridad los siguientes equipos:
B23: uno o más equipos en todos los criterios considerados. | I23: =IF(J23="",0,1) -> 1 | J23: Canadá | M23: 1 | N23: =IF(J23="",0,M23) -> 1
B24: Para utilizarlo, asigne una prioridad entre 1 y 5 (siendo más bajo mejor) a cada equipo. | I24: =IF(J24="",0,1) -> 1 | J24: Bosnia | M24: 2 | N24: =IF(J24="",0,M24) -> 2
B25: Puede pensarlo como el lugar que quedarían en la tabla de posiciones. | I25: =IF(J25="",0,1) -> 1 | J25: Suiza | M25: 3 | N25: =IF(J25="",0,M25) -> 3
B26: A modo de ejemplo, si su predicción es que todos los partidos terminan 0-0, el orden | I26: =IF(J26="",0,1) -> 1 | J26: Catar | M26: 4 | N26: =IF(J26="",0,M26) -> 4
B27: asignado en este recuadro es el que finalmente quedará en la tabla de posiciones. | N27: =IF(J27="",0,M27) -> 0

Sheet GRUPO C
B3: GRUPO C
C5: 2 | D5: 3 | E5: 5 | F5: 6 | G5: 4
B6: Tabla de Posiciones | J6: Fecha | K6: Partidos | AJ6: 1 | AK6: 2 | AL6: Ganador | AN6: Orden | AO6: Equipo | AP6: Puntos | AQ6: DG | AR6: GF | AS6: GC | AV6: Equipo | AW6: Empatado Con | AX6: Ganador | AY6: Ganador? | AZ6: Formula Rank | BA6: Formula Rank Con Duelo Directo | BB6: Formula Rank Con Prioridad
B7: Posición | C7: Equipo | D7: Puntos | E7: GF | F7: GC | G7: DG | I7: 6 | J7: 46186 | K7: Brasil | N7: Marruecos | AG7: =IF(OR(L7="",M7=""),1,0) -> 1 | AI7: =CONCATENATE(K7,"_",N7) -> Brasil_Marruecos | AJ7: =IF(L7>M7,3,IF(L7<M7,0,1)) -> 1 | AK7: =IF(AJ7=3,0,IF(AJ7=1,1,3)) -> 1 | AL7: =IF(AJ7>AK7,K7,IF(AK7>AJ7,N7,"SIN GANADOR")) -> SIN GANADOR | AN7: =_xlfn.RANK.EQ(BB7,BB$7:BB$11,1) -> 1 | AO7: =J23 -> Brasil | AP7: =SUMIF($K$7:$K$12,AO7,$AJ$7:$AJ$12) + SUMIF($N$7:$N$12,AO7,$AK$7:$AK$12) -> 3 | AQ7: =AR7-AS7 -> 0 | AR7: =SUMIF($K$7:$K$12,AO7,$L$7:$L$12) + SUMIF($N$7:$N$12,AO7,$M$7:$M$12) -> 0 | AS7: =SUMIF($K$7:$K$12,AO7,$M$7:$M$12) + SUMIF($N$7:$N$12,AO7,$L$7:$L$12) -> 0 | AV7: =AO7 -> Brasil | AW7: =IF(AZ7=AZ8,AV8,IF(AZ7=AZ9,AV9,IF(AZ7=AZ10,AV10,""))) -> Marruecos | AX7: =IF(AW7="","",IFERROR(VLOOKUP(CONCATENATE(AV7,"_",AW7),$AI$7:$AL$16,4,FALSE),VLOOKUP(CONCATENATE(AW7,"_",AV7),$AI$7:$AL$16,4,FALSE))) -> SIN GANADOR | AY7: =IF(AX7="",1,IF(AX7=AV7,1,0)) -> 0 | AZ7: =-AP7*10000000 - AQ7*10000 - AR7*100 -> -30000000 | BA7: =AZ7-AY7*10 -> -30000000 | BB7: =BA7+N23 -> -29999999
B8: 1 | C8: =IFERROR(VLOOKUP($B8,$AN$7:$AS$11,C$5,FALSE),"") -> Brasil | D8: =IFERROR(VLOOKUP($B8,$AN$7:$AS$11,D$5,FALSE),"") -> 3 | E8: =IFERROR(VLOOKUP($B8,$AN$7:$AS$11,E$5,FALSE),"") -> 0 | F8: =IFERROR(VLOOKUP($B8,$AN$7:$AS$11,F$5,FALSE),"") -> 0 | G8: =IFERROR(VLOOKUP($B8,$AN$7:$AS$11,G$5,FALSE),"") -> 0 | I8: 7 | J8: 46186 | K8: Haití | N8: Escocia | AG8: =IF(OR(L8="",M8=""),1,0) -> 1 | AI8: =CONCATENATE(K8,"_",N8) -> Haití_Escocia | AJ8: =IF(L8>M8,3,IF(L8<M8,0,1)) -> 1 | AK8: =IF(AJ8=3,0,IF(AJ8=1,1,3)) -> 1 | AL8: =IF(AJ8>AK8,K8,IF(AK8>AJ8,N8,"SIN GANADOR")) -> SIN GANADOR | AN8: =_xlfn.RANK.EQ(BB8,BB$7:BB$11,1) -> 2 | AO8: =J24 -> Marruecos | AP8: =SUMIF($K$7:$K$12,AO8,$AJ$7:$AJ$12) + SUMIF($N$7:$N$12,AO8,$AK$7:$AK$12) -> 3 | AQ8: =AR8-AS8 -> 0 | AR8: =SUMIF($K$7:$K$12,AO8,$L$7:$L$12) + SUMIF($N$7:$N$12,AO8,$M$7:$M$12) -> 0 | AS8: =SUMIF($K$7:$K$12,AO8,$M$7:$M$12) + SUMIF($N$7:$N$12,AO8,$L$7:$L$12) -> 0 | AV8: =AO8 -> Marruecos | AW8: =IF(AZ8=AZ9,AV9,IF(AZ8=AZ10,AV10,IF(AZ8=AZ7,AV7,""))) -> Haití | AX8: =IF(AW8="","",IFERROR(VLOOKUP(CONCATENATE(AV8,"_",AW8),$AI$7:$AL$16,4,FALSE),VLOOKUP(CONCATENATE(AW8,"_",AV8),$AI$7:$AL$16,4,FALSE))) -> SIN GANADOR | AY8: =IF(AX8="",1,IF(AX8=AV8,1,0)) -> 0 | AZ8: =-AP8*10000000 - AQ8*10000 - AR8*100 -> -30000000 | BA8: =AZ8-AY8*10 -> -30000000 | BB8: =BA8+N24 -> -29999998
B9: 2 | C9: =IFERROR(VLOOKUP($B9,$AN$7:$AS$11,C$5,FALSE),"") -> Marruecos | D9: =IFERROR(VLOOKUP($B9,$AN$7:$AS$11,D$5,FALSE),"") -> 3 | E9: =IFERROR(VLOOKUP($B9,$AN$7:$AS$11,E$5,FALSE),"") -> 0 | F9: =IFERROR(VLOOKUP($B9,$AN$7:$AS$11,F$5,FALSE),"") -> 0 | G9: =IFERROR(VLOOKUP($B9,$AN$7:$AS$11,G$5,FALSE),"") -> 0 | I9: 30 | J9: 46192 | K9: Escocia | N9: Marruecos | AG9: =IF(OR(L9="",M9=""),1,0) -> 1 | AI9: =CONCATENATE(K9,"_",N9) -> Escocia_Marruecos | AJ9: =IF(L9>M9,3,IF(L9<M9,0,1)) -> 1 | AK9: =IF(AJ9=3,0,IF(AJ9=1,1,3)) -> 1 | AL9: =IF(AJ9>AK9,K9,IF(AK9>AJ9,N9,"SIN GANADOR")) -> SIN GANADOR | AN9: =_xlfn.RANK.EQ(BB9,BB$7:BB$11,1) -> 3 | AO9: =J25 -> Haití | AP9: =SUMIF($K$7:$K$12,AO9,$AJ$7:$AJ$12) + SUMIF($N$7:$N$12,AO9,$AK$7:$AK$12) -> 3 | AQ9: =AR9-AS9 -> 0 | AR9: =SUMIF($K$7:$K$12,AO9,$L$7:$L$12) + SUMIF($N$7:$N$12,AO9,$M$7:$M$12) -> 0 | AS9: =SUMIF($K$7:$K$12,AO9,$M$7:$M$12) + SUMIF($N$7:$N$12,AO9,$L$7:$L$12) -> 0 | AV9: =AO9 -> Haití | AW9: =IF(AZ9=AZ10,AV10,IF(AZ9=AZ7,AV7,IF(AZ9=AZ8,AV8,""))) -> Escocia | AX9: =IF(AW9="","",IFERROR(VLOOKUP(CONCATENATE(AV9,"_",AW9),$AI$7:$AL$16,4,FALSE),VLOOKUP(CONCATENATE(AW9,"_",AV9),$AI$7:$AL$16,4,FALSE))) -> SIN GANADOR | AY9: =IF(AX9="",1,IF(AX9=AV9,1,0)) -> 0 | AZ9: =-AP9*10000000 - AQ9*10000 - AR9*100 -> -30000000 | BA9: =AZ9-AY9*10 -> -30000000 | BB9: =BA9+N25 -> -29999997
B10: 3 | C10: =IFERROR(VLOOKUP($B10,$AN$7:$AS$11,C$5,FALSE),"") -> Haití | D10: =IFERROR(VLOOKUP($B10,$AN$7:$AS$11,D$5,FALSE),"") -> 3 | E10: =IFERROR(VLOOKUP($B10,$AN$7:$AS$11,E$5,FALSE),"") -> 0 | F10: =IFERROR(VLOOKUP($B10,$AN$7:$AS$11,F$5,FALSE),"") -> 0 | G10: =IFERROR(VLOOKUP($B10,$AN$7:$AS$11,G$5,FALSE),"") -> 0 | I10: 31 | J10: 46192 | K10: Brasil | N10: Haití | AG10: =IF(OR(L10="",M10=""),1,0) -> 1 | AI10: =CONCATENATE(K10,"_",N10) -> Brasil_Haití | AJ10: =IF(L10>M10,3,IF(L10<M10,0,1)) -> 1 | AK10: =IF(AJ10=3,0,IF(AJ10=1,1,3)) -> 1 | AL10: =IF(AJ10>AK10,K10,IF(AK10>AJ10,N10,"SIN GANADOR")) -> SIN GANADOR | AN10: =_xlfn.RANK.EQ(BB10,BB$7:BB$11,1) -> 4 | AO10: =J26 -> Escocia | AP10: =SUMIF($K$7:$K$12,AO10,$AJ$7:$AJ$12) + SUMIF($N$7:$N$12,AO10,$AK$7:$AK$12) -> 3 | AQ10: =AR10-AS10 -> 0 | AR10: =SUMIF($K$7:$K$12,AO10,$L$7:$L$12) + SUMIF($N$7:$N$12,AO10,$M$7:$M$12) -> 0 | AS10: =SUMIF($K$7:$K$12,AO10,$M$7:$M$12) + SUMIF($N$7:$N$12,AO10,$L$7:$L$12) -> 0 | AV10: =AO10 -> Escocia | AW10: =IF(AZ10=AZ7,AV7,IF(AZ10=AZ8,AV8,IF(AZ10=AZ9,AV9,""))) -> Brasil | AX10: =IF(AW10="","",IFERROR(VLOOKUP(CONCATENATE(AV10,"_",AW10),$AI$7:$AL$16,4,FALSE),VLOOKUP(CONCATENATE(AW10,"_",AV10),$AI$7:$AL$16,4,FALSE))) -> SIN GANADOR | AY10: =IF(AX10="",1,IF(AX10=AV10,1,0)) -> 0 | AZ10: =-AP10*10000000 - AQ10*10000 - AR10*100 -> -30000000 | BA10: =AZ10-AY10*10 -> -30000000 | BB10: =BA10+N26 -> -29999996
B11: 4 | C11: =IFERROR(VLOOKUP($B11,$AN$7:$AS$11,C$5,FALSE),"") -> Escocia | D11: =IFERROR(VLOOKUP($B11,$AN$7:$AS$11,D$5,FALSE),"") -> 3 | E11: =IFERROR(VLOOKUP($B11,$AN$7:$AS$11,E$5,FALSE),"") -> 0 | F11: =IFERROR(VLOOKUP($B11,$AN$7:$AS$11,F$5,FALSE),"") -> 0 | G11: =IFERROR(VLOOKUP($B11,$AN$7:$AS$11,G$5,FALSE),"") -> 0 | I11: 51 | J11: 46197 | K11: Brasil | N11: Escocia | AG11: =IF(OR(L11="",M11=""),1,0) -> 1 | AI11: =CONCATENATE(K11,"_",N11) -> Brasil_Escocia | AJ11: =IF(L11>M11,3,IF(L11<M11,0,1)) -> 1 | AK11: =IF(AJ11=3,0,IF(AJ11=1,1,3)) -> 1 | AL11: =IF(AJ11>AK11,K11,IF(AK11>AJ11,N11,"SIN GANADOR")) -> SIN GANADOR
I12: 52 | J12: 46197 | K12: Marruecos | N12: Haití | AG12: =IF(OR(L12="",M12=""),1,0) -> 1 | AI12: =CONCATENATE(K12,"_",N12) -> Marruecos_Haití | AJ12: =IF(L12>M12,3,IF(L12<M12,0,1)) -> 1 | AK12: =IF(AJ12=3,0,IF(AJ12=1,1,3)) -> 1 | AL12: =IF(AJ12>AK12,K12,IF(AK12>AJ12,N12,"SIN GANADOR")) -> SIN GANADOR
AG13: =IF(SUM(AG7:AG12)>0,1,0) -> 1
B22: El recuadro de la derecha sirve para desempatar, en caso de que haya empate entre | I22: 1 | J22: Escoja por prioridad los siguientes equipos:
B23: uno o más equipos en todos los criterios considerados. | I23: =IF(J23="",0,1) -> 1 | J23: Brasil | M23: 1 | N23: =IF(J23="",0,M23) -> 1
B24: Para utilizarlo, asigne una prioridad entre 1 y 5 (siendo más bajo mejor) a cada equipo. | I24: =IF(J24="",0,1) -> 1 | J24: Marruecos | M24: 2 | N24: =IF(J24="",0,M24) -> 2
B25: Puede pensarlo como el lugar que quedarían en la tabla de posiciones. | I25: =IF(J25="",0,1) -> 1 | J25: Haití | M25: 3 | N25: =IF(J25="",0,M25) -> 3
B26: A modo de ejemplo, si su predicción es que todos los partidos terminan 0-0, el orden | I26: =IF(J26="",0,1) -> 1 | J26: Escocia | M26: 4 | N26: =IF(J26="",0,M26) -> 4
B27: asignado en este recuadro es el que finalmente quedará en la tabla de posiciones. | N27: =IF(J27="",0,M27) -> 0

Sheet GRUPO D
B3: GRUPO D
C5: 2 | D5: 3 | E5: 5 | F5: 6 | G5: 4
B6: Tabla de Posiciones | J6: Fecha | K6: Partidos | AJ6: 1 | AK6: 2 | AL6: Ganador | AN6: Orden | AO6: Equipo | AP6: Puntos | AQ6: DG | AR6: GF | AS6: GC | AV6: Equipo | AW6: Empatado Con | AX6: Ganador | AY6: Ganador? | AZ6: Formula Rank | BA6: Formula Rank Con Duelo Directo | BB6: Formula Rank Con Prioridad
B7: Posición | C7: Equipo | D7: Puntos | E7: GF | F7: GC | G7: DG | I7: 4 | J7: 46185 | K7: USA | N7: Paraguay | AG7: =IF(OR(L7="",M7=""),1,0) -> 1 | AI7: =CONCATENATE(K7,"_",N7) -> USA_Paraguay | AJ7: =IF(L7>M7,3,IF(L7<M7,0,1)) -> 1 | AK7: =IF(AJ7=3,0,IF(AJ7=1,1,3)) -> 1 | AL7: =IF(AJ7>AK7,K7,IF(AK7>AJ7,N7,"SIN GANADOR")) -> SIN GANADOR | AN7: =_xlfn.RANK.EQ(BB7,BB$7:BB$11,1) -> 1 | AO7: =J23 -> USA | AP7: =SUMIF($K$7:$K$12,AO7,$AJ$7:$AJ$12) + SUMIF($N$7:$N$12,AO7,$AK$7:$AK$12) -> 3 | AQ7: =AR7-AS7 -> 0 | AR7: =SUMIF($K$7:$K$12,AO7,$L$7:$L$12) + SUMIF($N$7:$N$12,AO7,$M$7:$M$12) -> 0 | AS7: =SUMIF($K$7:$K$12,AO7,$M$7:$M$12) + SUMIF($N$7:$N$12,AO7,$L$7:$L$12) -> 0 | AV7: =AO7 -> USA | AW7: =IF(AZ7=AZ8,AV8,IF(AZ7=AZ9,AV9,IF(AZ7=AZ10,AV10,""))) -> Paraguay | AX7: =IF(AW7="","",IFERROR(VLOOKUP(CONCATENATE(AV7,"_",AW7),$AI$7:$AL$16,4,FALSE),VLOOKUP(CONCATENATE(AW7,"_",AV7),$AI$7:$AL$16,4,FALSE))) -> SIN GANADOR | AY7: =IF(AX7="",1,IF(AX7=AV7,1,0)) -> 0 | AZ7: =-AP7*10000000 - AQ7*10000 - AR7*100 -> -30000000 | BA7: =AZ7-AY7*10 -> -30000000 | BB7: =BA7+N23 -> -29999999
B8: 1 | C8: =IFERROR(VLOOKUP($B8,$AN$7:$AS$11,C$5,FALSE),"") -> USA | D8: =IFERROR(VLOOKUP($B8,$AN$7:$AS$11,D$5,FALSE),"") -> 3 | E8: =IFERROR(VLOOKUP($B8,$AN$7:$AS$11,E$5,FALSE),"") -> 0 | F8: =IFERROR(VLOOKUP($B8,$AN$7:$AS$11,F$5,FALSE),"") -> 0 | G8: =IFERROR(VLOOKUP($B8,$AN$7:$AS$11,G$5,FALSE),"") -> 0 | I8: 8 | J8: 46186 | K8: Australia | N8: Turquía | AG8: =IF(OR(L8="",M8=""),1,0) -> 1 | AI8: =CONCATENATE(K8,"_",N8) -> Australia_Turquía | AJ8: =IF(L8>M8,3,IF(L8<M8,0,1)) -> 1 | AK8: =IF(AJ8=3,0,IF(AJ8=1,1,3)) -> 1 | AL8: =IF(AJ8>AK8,K8,IF(AK8>AJ8,N8,"SIN GANADOR")) -> SIN GANADOR | AN8: =_xlfn.RANK.EQ(BB8,BB$7:BB$11,1) -> 2 | AO8: =J24 -> Paraguay | AP8: =SUMIF($K$7:$K$12,AO8,$AJ$7:$AJ$12) + SUMIF($N$7:$N$12,AO8,$AK$7:$AK$12) -> 3 | AQ8: =AR8-AS8 -> 0 | AR8: =SUMIF($K$7:$K$12,AO8,$L$7:$L$12) + SUMIF($N$7:$N$12,AO8,$M$7:$M$12) -> 0 | AS8: =SUMIF($K$7:$K$12,AO8,$M$7:$M$12) + SUMIF($N$7:$N$12,AO8,$L$7:$L$12) -> 0 | AV8: =AO8 -> Paraguay | AW8: =IF(AZ8=AZ9,AV9,IF(AZ8=AZ10,AV10,IF(AZ8=AZ7,AV7,""))) -> Australia | AX8: =IF(AW8="","",IFERROR(VLOOKUP(CONCATENATE(AV8,"_",AW8),$AI$7:$AL$16,4,FALSE),VLOOKUP(CONCATENATE(AW8,"_",AV8),$AI$7:$AL$16,4,FALSE))) -> SIN GANADOR | AY8: =IF(AX8="",1,IF(AX8=AV8,1,0)) -> 0 | AZ8: =-AP8*10000000 - AQ8*10000 - AR8*100 -> -30000000 | BA8: =AZ8-AY8*10 -> -30000000 | BB8: =BA8+N24 -> -29999998
B9: 2 | C9: =IFERROR(VLOOKUP($B9,$AN$7:$AS$11,C$5,FALSE),"") -> Paraguay | D9: =IFERROR(VLOOKUP($B9,$AN$7:$AS$11,D$5,FALSE),"") -> 3 | E9: =IFERROR(VLOOKUP($B9,$AN$7:$AS$11,E$5,FALSE),"") -> 0 | F9: =IFERROR(VLOOKUP($B9,$AN$7:$AS$11,F$5,FALSE),"") -> 0 | G9: =IFERROR(VLOOKUP($B9,$AN$7:$AS$11,G$5,FALSE),"") -> 0 | I9: 29 | J9: 46192 | K9: USA | N9: Australia | AG9: =IF(OR(L9="",M9=""),1,0) -> 1 | AI9: =CONCATENATE(K9,"_",N9) -> USA_Australia | AJ9: =IF(L9>M9,3,IF(L9<M9,0,1)) -> 1 | AK9: =IF(AJ9=3,0,IF(AJ9=1,1,3)) -> 1 | AL9: =IF(AJ9>AK9,K9,IF(AK9>AJ9,N9,"SIN GANADOR")) -> SIN GANADOR | AN9: =_xlfn.RANK.EQ(BB9,BB$7:BB$11,1) -> 3 | AO9: =J25 -> Australia | AP9: =SUMIF($K$7:$K$12,AO9,$AJ$7:$AJ$12) + SUMIF($N$7:$N$12,AO9,$AK$7:$AK$12) -> 3 | AQ9: =AR9-AS9 -> 0 | AR9: =SUMIF($K$7:$K$12,AO9,$L$7:$L$12) + SUMIF($N$7:$N$12,AO9,$M$7:$M$12) -> 0 | AS9: =SUMIF($K$7:$K$12,AO9,$M$7:$M$12) + SUMIF($N$7:$N$12,AO9,$L$7:$L$12) -> 0 | AV9: =AO9 -> Australia | AW9: =IF(AZ9=AZ10,AV10,IF(AZ9=AZ7,AV7,IF(AZ9=AZ8,AV8,""))) -> Turquía | AX9: =IF(AW9="","",IFERROR(VLOOKUP(CONCATENATE(AV9,"_",AW9),$AI$7:$AL$16,4,FALSE),VLOOKUP(CONCATENATE(AW9,"_",AV9),$AI$7:$AL$16,4,FALSE))) -> SIN GANADOR | AY9: =IF(AX9="",1,IF(AX9=AV9,1,0)) -> 0 | AZ9: =-AP9*10000000 - AQ9*10000 - AR9*100 -> -30000000 | BA9: =AZ9-AY9*10 -> -30000000 | BB9: =BA9+N25 -> -29999997
B10: 3 | C10: =IFERROR(VLOOKUP($B10,$AN$7:$AS$11,C$5,FALSE),"") -> Australia | D10: =IFERROR(VLOOKUP($B10,$AN$7:$AS$11,D$5,FALSE),"") -> 3 | E10: =IFERROR(VLOOKUP($B10,$AN$7:$AS$11,E$5,FALSE),"") -> 0 | F10: =IFERROR(VLOOKUP($B10,$AN$7:$AS$11,F$5,FALSE),"") -> 0 | G10: =IFERROR(VLOOKUP($B10,$AN$7:$AS$11,G$5,FALSE),"") -> 0 | I10: 32 | J10: 46192 | K10: Turquía | N10: Paraguay | AG10: =IF(OR(L10="",M10=""),1,0) -> 1 | AI10: =CONCATENATE(K10,"_",N10) -> Turquía_Paraguay | AJ10: =IF(L10>M10,3,IF(L10<M10,0,1)) -> 1 | AK10: =IF(AJ10=3,0,IF(AJ10=1,1,3)) -> 1 | AL10: =IF(AJ10>AK10,K10,IF(AK10>AJ10,N10,"SIN GANADOR")) -> SIN GANADOR | AN10: =_xlfn.RANK.EQ(BB10,BB$7:BB$11,1) -> 4 | AO10: =J26 -> Turquía | AP10: =SUMIF($K$7:$K$12,AO10,$AJ$7:$AJ$12) + SUMIF($N$7:$N$12,AO10,$AK$7:$AK$12) -> 3 | AQ10: =AR10-AS10 -> 0 | AR10: =SUMIF($K$7:$K$12,AO10,$L$7:$L$12) + SUMIF($N$7:$N$12,AO10,$M$7:$M$12) -> 0 | AS10: =SUMIF($K$7:$K$12,AO10,$M$7:$M$12) + SUMIF($N$7:$N$12,AO10,$L$7:$L$12) -> 0 | AV10: =AO10 -> Turquía | AW10: =IF(AZ10=AZ7,AV7,IF(AZ10=AZ8,AV8,IF(AZ10=AZ9,AV9,""))) -> USA | AX10: =IF(AW10="","",IFERROR(VLOOKUP(CONCATENATE(AV10,"_",AW10),$AI$7:$AL$16,4,FALSE),VLOOKUP(CONCATENATE(AW10,"_",AV10),$AI$7:$AL$16,4,FALSE))) -> SIN GANADOR | AY10: =IF(AX10="",1,IF(AX10=AV10,1,0)) -> 0 | AZ10: =-AP10*10000000 - AQ10*10000 - AR10*100 -> -30000000 | BA10: =AZ10-AY10*10 -> -30000000 | BB10: =BA10+N26 -> -29999996
B11: 4 | C11: =IFERROR(VLOOKUP($B11,$AN$7:$AS$11,C$5,FALSE),"") -> Turquía | D11: =IFERROR(VLOOKUP($B11,$AN$7:$AS$11,D$5,FALSE),"") -> 3 | E11: =IFERROR(VLOOKUP($B11,$AN$7:$AS$11,E$5,FALSE),"") -> 0 | F11: =IFERROR(VLOOKUP($B11,$AN$7:$AS$11,F$5,FALSE),"") -> 0 | G11: =IFERROR(VLOOKUP($B11,$AN$7:$AS$11,G$5,FALSE),"") -> 0 | I11: 59 | J11: 46198 | K11: Turquía | N11: USA | AG11: =IF(OR(L11="",M11=""),1,0) -> 1 | AI11: =CONCATENATE(K11,"_",N11) -> Turquía_USA | AJ11: =IF(L11>M11,3,IF(L11<M11,0,1)) -> 1 | AK11: =IF(AJ11=3,0,IF(AJ11=1,1,3)) -> 1 | AL11: =IF(AJ11>AK11,K11,IF(AK11>AJ11,N11,"SIN GANADOR")) -> SIN GANADOR
I12: 60 | J12: 46198 | K12: Paraguay | N12: Australia | AG12: =IF(OR(L12="",M12=""),1,0) -> 1 | AI12: =CONCATENATE(K12,"_",N12) -> Paraguay_Australia | AJ12: =IF(L12>M12,3,IF(L12<M12,0,1)) -> 1 | AK12: =IF(AJ12=3,0,IF(AJ12=1,1,3)) -> 1 | AL12: =IF(AJ12>AK12,K12,IF(AK12>AJ12,N12,"SIN GANADOR")) -> SIN GANADOR
AG13: =IF(SUM(AG7:AG12)>0,1,0) -> 1
B22: El recuadro de la derecha sirve para desempatar, en caso de que haya empate entre | I22: 1 | J22: Escoja por prioridad los siguientes equipos:
B23: uno o más equipos en todos los criterios considerados. | I23: =IF(J23="",0,1) -> 1 | J23: USA | M23: 1 | N23: =IF(J23="",0,M23) -> 1
B24: Para utilizarlo, asigne una prioridad entre 1 y 5 (siendo más bajo mejor) a cada equipo. | I24: =IF(J24="",0,1) -> 1 | J24: Paraguay | M24: 2 | N24: =IF(J24="",0,M24) -> 2
B25: Puede pensarlo como el lugar que quedarían en la tabla de posiciones. | I25: =IF(J25="",0,1) -> 1 | J25: Australia | M25: 3 | N25: =IF(J25="",0,M25) -> 3
B26: A modo de ejemplo, si su predicción es que todos los partidos terminan 0-0, el orden | I26: =IF(J26="",0,1) -> 1 | J26: Turquía | M26: 4 | N26: =IF(J26="",0,M26) -> 4
B27: asignado en este recuadro es el que finalmente quedará en la tabla de posiciones. | N27: =IF(J27="",0,M27) -> 0

Sheet GRUPO E
B3: GRUPO E
C5: 2 | D5: 3 | E5: 5 | F5: 6 | G5: 4
B6: Tabla de Posiciones | J6: Fecha | K6: Partidos | AJ6: 1 | AK6: 2 | AL6: Ganador | AN6: Orden | AO6: Equipo | AP6: Puntos | AQ6: DG | AR6: GF | AS6: GC | AV6: Equipo | AW6: Empatado Con | AX6: Ganador | AY6: Ganador? | AZ6: Formula Rank | BA6: Formula Rank Con Duelo Directo | BB6: Formula Rank Con Prioridad
B7: Posición | C7: Equipo | D7: Puntos | E7: GF | F7: GC | G7: DG | I7: 9 | J7: 46187 | K7: Alemania | N7: Curazao | AG7: =IF(OR(L7="",M7=""),1,0) -> 1 | AI7: =CONCATENATE(K7,"_",N7) -> Alemania_Curazao | AJ7: =IF(L7>M7,3,IF(L7<M7,0,1)) -> 1 | AK7: =IF(AJ7=3,0,IF(AJ7=1,1,3)) -> 1 | AL7: =IF(AJ7>AK7,K7,IF(AK7>AJ7,N7,"SIN GANADOR")) -> SIN GANADOR | AN7: =_xlfn.RANK.EQ(BB7,BB$7:BB$11,1) -> 1 | AO7: =J23 -> Alemania | AP7: =SUMIF($K$7:$K$12,AO7,$AJ$7:$AJ$12) + SUMIF($N$7:$N$12,AO7,$AK$7:$AK$12) -> 3 | AQ7: =AR7-AS7 -> 0 | AR7: =SUMIF($K$7:$K$12,AO7,$L$7:$L$12) + SUMIF($N$7:$N$12,AO7,$M$7:$M$12) -> 0 | AS7: =SUMIF($K$7:$K$12,AO7,$M$7:$M$12) + SUMIF($N$7:$N$12,AO7,$L$7:$L$12) -> 0 | AV7: =AO7 -> Alemania | AW7: =IF(AZ7=AZ8,AV8,IF(AZ7=AZ9,AV9,IF(AZ7=AZ10,AV10,""))) -> Curazao | AX7: =IF(AW7="","",IFERROR(VLOOKUP(CONCATENATE(AV7,"_",AW7),$AI$7:$AL$16,4,FALSE),VLOOKUP(CONCATENATE(AW7,"_",AV7),$AI$7:$AL$16,4,FALSE))) -> SIN GANADOR | AY7: =IF(AX7="",1,IF(AX7=AV7,1,0)) -> 0 | AZ7: =-AP7*10000000 - AQ7*10000 - AR7*100 -> -30000000 | BA7: =AZ7-AY7*10 -> -30000000 | BB7: =BA7+N23 -> -29999999
B8: 1 | C8: =IFERROR(VLOOKUP($B8,$AN$7:$AS$11,C$5,FALSE),"") -> Alemania | D8: =IFERROR(VLOOKUP($B8,$AN$7:$AS$11,D$5,FALSE),"") -> 3 | E8: =IFERROR(VLOOKUP($B8,$AN$7:$AS$11,E$5,FALSE),"") -> 0 | F8: =IFERROR(VLOOKUP($B8,$AN$7:$AS$11,F$5,FALSE),"") -> 0 | G8: =IFERROR(VLOOKUP($B8,$AN$7:$AS$11,G$5,FALSE),"") -> 0 | I8: 11 | J8: 46187 | K8: Costa de Marfil | N8: Ecuador | AG8: =IF(OR(L8="",M8=""),1,0) -> 1 | AI8: =CONCATENATE(K8,"_",N8) -> Costa de Marfil_Ecuador | AJ8: =IF(L8>M8,3,IF(L8<M8,0,1)) -> 1 | AK8: =IF(AJ8=3,0,IF(AJ8=1,1,3)) -> 1 | AL8: =IF(AJ8>AK8,K8,IF(AK8>AJ8,N8,"SIN GANADOR")) -> SIN GANADOR | AN8: =_xlfn.RANK.EQ(BB8,BB$7:BB$11,1) -> 2 | AO8: =J24 -> Curazao | AP8: =SUMIF($K$7:$K$12,AO8,$AJ$7:$AJ$12) + SUMIF($N$7:$N$12,AO8,$AK$7:$AK$12) -> 3 | AQ8: =AR8-AS8 -> 0 | AR8: =SUMIF($K$7:$K$12,AO8,$L$7:$L$12) + SUMIF($N$7:$N$12,AO8,$M$7:$M$12) -> 0 | AS8: =SUMIF($K$7:$K$12,AO8,$M$7:$M$12) + SUMIF($N$7:$N$12,AO8,$L$7:$L$12) -> 0 | AV8: =AO8 -> Curazao | AW8: =IF(AZ8=AZ9,AV9,IF(AZ8=AZ10,AV10,IF(AZ8=AZ7,AV7,""))) -> Costa de Marfil | AX8: =IF(AW8="","",IFERROR(VLOOKUP(CONCATENATE(AV8,"_",AW8),$AI$7:$AL$16,4,FALSE),VLOOKUP(CONCATENATE(AW8,"_",AV8),$AI$7:$AL$16,4,FALSE))) -> SIN GANADOR | AY8: =IF(AX8="",1,IF(AX8=AV8,1,0)) -> 0 | AZ8: =-AP8*10000000 - AQ8*10000 - AR8*100 -> -30000000 | BA8: =AZ8-AY8*10 -> -30000000 | BB8: =BA8+N24 -> -29999998
B9: 2 | C9: =IFERROR(VLOOKUP($B9,$AN$7:$AS$11,C$5,FALSE),"") -> Curazao | D9: =IFERROR(VLOOKUP($B9,$AN$7:$AS$11,D$5,FALSE),"") -> 3 | E9: =IFERROR(VLOOKUP($B9,$AN$7:$AS$11,E$5,FALSE),"") -> 0 | F9: =IFERROR(VLOOKUP($B9,$AN$7:$AS$11,F$5,FALSE),"") -> 0 | G9: =IFERROR(VLOOKUP($B9,$AN$7:$AS$11,G$5,FALSE),"") -> 0 | I9: 34 | J9: 46193 | K9: Alemania | N9: Costa de Marfil | AG9: =IF(OR(L9="",M9=""),1,0) -> 1 | AI9: =CONCATENATE(K9,"_",N9) -> Alemania_Costa de Marfil | AJ9: =IF(L9>M9,3,IF(L9<M9,0,1)) -> 1 | AK9: =IF(AJ9=3,0,IF(AJ9=1,1,3)) -> 1 | AL9: =IF(AJ9>AK9,K9,IF(AK9>AJ9,N9,"SIN GANADOR")) -> SIN GANADOR | AN9: =_xlfn.RANK.EQ(BB9,BB$7:BB$11,1) -> 3 | AO9: =J25 -> Costa de Marfil | AP9: =SUMIF($K$7:$K$12,AO9,$AJ$7:$AJ$12) + SUMIF($N$7:$N$12,AO9,$AK$7:$AK$12) -> 3 | AQ9: =AR9-AS9 -> 0 | AR9: =SUMIF($K$7:$K$12,AO9,$L$7:$L$12) + SUMIF($N$7:$N$12,AO9,$M$7:$M$12) -> 0 | AS9: =SUMIF($K$7:$K$12,AO9,$M$7:$M$12) + SUMIF($N$7:$N$12,AO9,$L$7:$L$12) -> 0 | AV9: =AO9 -> Costa de Marfil | AW9: =IF(AZ9=AZ10,AV10,IF(AZ9=AZ7,AV7,IF(AZ9=AZ8,AV8,""))) -> Ecuador | AX9: =IF(AW9="","",IFERROR(VLOOKUP(CONCATENATE(AV9,"_",AW9),$AI$7:$AL$16,4,FALSE),VLOOKUP(CONCATENATE(AW9,"_",AV9),$AI$7:$AL$16,4,FALSE))) -> SIN GANADOR | AY9: =IF(AX9="",1,IF(AX9=AV9,1,0)) -> 0 | AZ9: =-AP9*10000000 - AQ9*10000 - AR9*100 -> -30000000 | BA9: =AZ9-AY9*10 -> -30000000 | BB9: =BA9+N25 -> -29999997
B10: 3 | C10: =IFERROR(VLOOKUP($B10,$AN$7:$AS$11,C$5,FALSE),"") -> Costa de Marfil | D10: =IFERROR(VLOOKUP($B10,$AN$7:$AS$11,D$5,FALSE),"") -> 3 | E10: =IFERROR(VLOOKUP($B10,$AN$7:$AS$11,E$5,FALSE),"") -> 0 | F10: =IFERROR(VLOOKUP($B10,$AN$7:$AS$11,F$5,FALSE),"") -> 0 | G10: =IFERROR(VLOOKUP($B10,$AN$7:$AS$11,G$5,FALSE),"") -> 0 | I10: 35 | J10: 46193 | K10: Ecuador | N10: Curazao | AG10: =IF(OR(L10="",M10=""),1,0) -> 1 | AI10: =CONCATENATE(K10,"_",N10) -> Ecuador_Curazao | AJ10: =IF(L10>M10,3,IF(L10<M10,0,1)) -> 1 | AK10: =IF(AJ10=3,0,IF(AJ10=1,1,3)) -> 1 | AL10: =IF(AJ10>AK10,K10,IF(AK10>AJ10,N10,"SIN GANADOR")) -> SIN GANADOR | AN10: =_xlfn.RANK.EQ(BB10,BB$7:BB$11,1) -> 4 | AO10: =J26 -> Ecuador | AP10: =SUMIF($K$7:$K$12,AO10,$AJ$7:$AJ$12) + SUMIF($N$7:$N$12,AO10,$AK$7:$AK$12) -> 3 | AQ10: =AR10-AS10 -> 0 | AR10: =SUMIF($K$7:$K$12,AO10,$L$7:$L$12) + SUMIF($N$7:$N$12,AO10,$M$7:$M$12) -> 0 | AS10: =SUMIF($K$7:$K$12,AO10,$M$7:$M$12) + SUMIF($N$7:$N$12,AO10,$L$7:$L$12) -> 0 | AV10: =AO10 -> Ecuador | AW10: =IF(AZ10=AZ7,AV7,IF(AZ10=AZ8,AV8,IF(AZ10=AZ9,AV9,""))) -> Alemania | AX10: =IF(AW10="","",IFERROR(VLOOKUP(CONCATENATE(AV10,"_",AW10),$AI$7:$AL$16,4,FALSE),VLOOKUP(CONCATENATE(AW10,"_",AV10),$AI$7:$AL$16,4,FALSE))) -> SIN GANADOR | AY10: =IF(AX10="",1,IF(AX10=AV10,1,0)) -> 0 | AZ10: =-AP10*10000000 - AQ10*10000 - AR10*100 -> -30000000 | BA10: =AZ10-AY10*10 -> -30000000 | BB10: =BA10+N26 -> -29999996
B11: 4 | C11: =IFERROR(VLOOKUP($B11,$AN$7:$AS$11,C$5,FALSE),"") -> Ecuador | D11: =IFERROR(VLOOKUP($B11,$AN$7:$AS$11,D$5,FALSE),"") -> 3 | E11: =IFERROR(VLOOKUP($B11,$AN$7:$AS$11,E$5,FALSE),"") -> 0 | F11: =IFERROR(VLOOKUP($B11,$AN$7:$AS$11,F$5,FALSE),"") -> 0 | G11: =IFERROR(VLOOKUP($B11,$AN$7:$AS$11,G$5,FALSE),"") -> 0 | I11: 55 | J11: 46198 | K11: Curazao | N11: Costa de Marfil | AG11: =IF(OR(L11="",M11=""),1,0) -> 1 | AI11: =CONCATENATE(K11,"_",N11) -> Curazao_Costa de Marfil | AJ11: =IF(L11>M11,3,IF(L11<M11,0,1)) -> 1 | AK11: =IF(AJ11=3,0,IF(AJ11=1,1,3)) -> 1 | AL11: =IF(AJ11>AK11,K11,IF(AK11>AJ11,N11,"SIN GANADOR")) -> SIN GANADOR
I12: 56 | J12: 46198 | K12: Ecuador | N12: Alemania | AG12: =IF(OR(L12="",M12=""),1,0) -> 1 | AI12: =CONCATENATE(K12,"_",N12) -> Ecuador_Alemania | AJ12: =IF(L12>M12,3,IF(L12<M12,0,1)) -> 1 | AK12: =IF(AJ12=3,0,IF(AJ12=1,1,3)) -> 1 | AL12: =IF(AJ12>AK12,K12,IF(AK12>AJ12,N12,"SIN GANADOR")) -> SIN GANADOR
AG13: =IF(SUM(AG7:AG12)>0,1,0) -> 1
B22: El recuadro de la derecha sirve para desempatar, en caso de que haya empate entre | I22: 1 | J22: Escoja por prioridad los siguientes equipos:
B23: uno o más equipos en todos los criterios considerados. | I23: =IF(J23="",0,1) -> 1 | J23: Alemania | M23: 1 | N23: =IF(J23="",0,M23) -> 1
B24: Para utilizarlo, asigne una prioridad entre 1 y 5 (siendo más bajo mejor) a cada equipo. | I24: =IF(J24="",0,1) -> 1 | J24: Curazao | M24: 2 | N24: =IF(J24="",0,M24) -> 2
B25: Puede pensarlo como el lugar que quedarían en la tabla de posiciones. | I25: =IF(J25="",0,1) -> 1 | J25: Costa de Marfil | M25: 3 | N25: =IF(J25="",0,M25) -> 3
B26: A modo de ejemplo, si su predicción es que todos los partidos terminan 0-0, el orden | I26: =IF(J26="",0,1) -> 1 | J26: Ecuador | M26: 4 | N26: =IF(J26="",0,M26) -> 4
B27: asignado en este recuadro es el que finalmente quedará en la tabla de posiciones. | N27: =IF(J27="",0,M27) -> 0

Sheet GRUPO F
B3: GRUPO F
C5: 2 | D5: 3 | E5: 5 | F5: 6 | G5: 4
B6: Tabla de Posiciones | J6: Fecha | K6: Partidos | AJ6: 1 | AK6: 2 | AL6: Ganador | AN6: Orden | AO6: Equipo | AP6: Puntos | AQ6: DG | AR6: GF | AS6: GC | AV6: Equipo | AW6: Empatado Con | AX6: Ganador | AY6: Ganador? | AZ6: Formula Rank | BA6: Formula Rank Con Duelo Directo | BB6: Formula Rank Con Prioridad
B7: Posición | C7: Equipo | D7: Puntos | E7: GF | F7: GC | G7: DG | I7: 10 | J7: 46187 | K7: Países Bajos | N7: Japón | AG7: =IF(OR(L7="",M7=""),1,0) -> 1 | AI7: =CONCATENATE(K7,"_",N7) -> Países Bajos_Japón | AJ7: =IF(L7>M7,3,IF(L7<M7,0,1)) -> 1 | AK7: =IF(AJ7=3,0,IF(AJ7=1,1,3)) -> 1 | AL7: =IF(AJ7>AK7,K7,IF(AK7>AJ7,N7,"SIN GANADOR")) -> SIN GANADOR | AN7: =_xlfn.RANK.EQ(BB7,BB$7:BB$11,1) -> 1 | AO7: =J23 -> Países Bajos | AP7: =SUMIF($K$7:$K$12,AO7,$AJ$7:$AJ$12) + SUMIF($N$7:$N$12,AO7,$AK$7:$AK$12) -> 3 | AQ7: =AR7-AS7 -> 0 | AR7: =SUMIF($K$7:$K$12,AO7,$L$7:$L$12) + SUMIF($N$7:$N$12,AO7,$M$7:$M$12) -> 0 | AS7: =SUMIF($K$7:$K$12,AO7,$M$7:$M$12) + SUMIF($N$7:$N$12,AO7,$L$7:$L$12) -> 0 | AV7: =AO7 -> Países Bajos | AW7: =IF(AZ7=AZ8,AV8,IF(AZ7=AZ9,AV9,IF(AZ7=AZ10,AV10,""))) -> Japón | AX7: =IF(AW7="","",IFERROR(VLOOKUP(CONCATENATE(AV7,"_",AW7),$AI$7:$AL$16,4,FALSE),VLOOKUP(CONCATENATE(AW7,"_",AV7),$AI$7:$AL$16,4,FALSE))) -> SIN GANADOR | AY7: =IF(AX7="",1,IF(AX7=AV7,1,0)) -> 0 | AZ7: =-AP7*10000000 - AQ7*10000 - AR7*100 -> -30000000 | BA7: =AZ7-AY7*10 -> -30000000 | BB7: =BA7+N23 -> -29999999
B8: 1 | C8: =IFERROR(VLOOKUP($B8,$AN$7:$AS$11,C$5,FALSE),"") -> Países Bajos | D8: =IFERROR(VLOOKUP($B8,$AN$7:$AS$11,D$5,FALSE),"") -> 3 | E8: =IFERROR(VLOOKUP($B8,$AN$7:$AS$11,E$5,FALSE),"") -> 0 | F8: =IFERROR(VLOOKUP($B8,$AN$7:$AS$11,F$5,FALSE),"") -> 0 | G8: =IFERROR(VLOOKUP($B8,$AN$7:$AS$11,G$5,FALSE),"") -> 0 | I8: 12 | J8: 46187 | K8: Suecia | N8: Túnez | AG8: =IF(OR(L8="",M8=""),1,0) -> 1 | AI8: =CONCATENATE(K8,"_",N8) -> Suecia_Túnez | AJ8: =IF(L8>M8,3,IF(L8<M8,0,1)) -> 1 | AK8: =IF(AJ8=3,0,IF(AJ8=1,1,3)) -> 1 | AL8: =IF(AJ8>AK8,K8,IF(AK8>AJ8,N8,"SIN GANADOR")) -> SIN GANADOR | AN8: =_xlfn.RANK.EQ(BB8,BB$7:BB$11,1) -> 2 | AO8: =J24 -> Japón | AP8: =SUMIF($K$7:$K$12,AO8,$AJ$7:$AJ$12) + SUMIF($N$7:$N$12,AO8,$AK$7:$AK$12) -> 3 | AQ8: =AR8-AS8 -> 0 | AR8: =SUMIF($K$7:$K$12,AO8,$L$7:$L$12) + SUMIF($N$7:$N$12,AO8,$M$7:$M$12) -> 0 | AS8: =SUMIF($K$7:$K$12,AO8,$M$7:$M$12) + SUMIF($N$7:$N$12,AO8,$L$7:$L$12) -> 0 | AV8: =AO8 -> Japón | AW8: =IF(AZ8=AZ9,AV9,IF(AZ8=AZ10,AV10,IF(AZ8=AZ7,AV7,""))) -> Suecia | AX8: =IF(AW8="","",IFERROR(VLOOKUP(CONCATENATE(AV8,"_",AW8),$AI$7:$AL$16,4,FALSE),VLOOKUP(CONCATENATE(AW8,"_",AV8),$AI$7:$AL$16,4,FALSE))) -> SIN GANADOR | AY8: =IF(AX8="",1,IF(AX8=AV8,1,0)) -> 0 | AZ8: =-AP8*10000000 - AQ8*10000 - AR8*100 -> -30000000 | BA8: =AZ8-AY8*10 -> -30000000 | BB8: =BA8+N24 -> -29999998
B9: 2 | C9: =IFERROR(VLOOKUP($B9,$AN$7:$AS$11,C$5,FALSE),"") -> Japón | D9: =IFERROR(VLOOKUP($B9,$AN$7:$AS$11,D$5,FALSE),"") -> 3 | E9: =IFERROR(VLOOKUP($B9,$AN$7:$AS$11,E$5,FALSE),"") -> 0 | F9: =IFERROR(VLOOKUP($B9,$AN$7:$AS$11,F$5,FALSE),"") -> 0 | G9: =IFERROR(VLOOKUP($B9,$AN$7:$AS$11,G$5,FALSE),"") -> 0 | I9: 33 | J9: 46193 | K9: Países Bajos | N9: Suecia | AG9: =IF(OR(L9="",M9=""),1,0) -> 1 | AI9: =CONCATENATE(K9,"_",N9) -> Países Bajos_Suecia | AJ9: =IF(L9>M9,3,IF(L9<M9,0,1)) -> 1 | AK9: =IF(AJ9=3,0,IF(AJ9=1,1,3)) -> 1 | AL9: =IF(AJ9>AK9,K9,IF(AK9>AJ9,N9,"SIN GANADOR")) -> SIN GANADOR | AN9: =_xlfn.RANK.EQ(BB9,BB$7:BB$11,1) -> 3 | AO9: =J25 -> Suecia | AP9: =SUMIF($K$7:$K$12,AO9,$AJ$7:$AJ$12) + SUMIF($N$7:$N$12,AO9,$AK$7:$AK$12) -> 3 | AQ9: =AR9-AS9 -> 0 | AR9: =SUMIF($K$7:$K$12,AO9,$L$7:$L$12) + SUMIF($N$7:$N$12,AO9,$M$7:$M$12) -> 0 | AS9: =SUMIF($K$7:$K$12,AO9,$M$7:$M$12) + SUMIF($N$7:$N$12,AO9,$L$7:$L$12) -> 0 | AV9: =AO9 -> Suecia | AW9: =IF(AZ9=AZ10,AV10,IF(AZ9=AZ7,AV7,IF(AZ9=AZ8,AV8,""))) -> Túnez | AX9: =IF(AW9="","",IFERROR(VLOOKUP(CONCATENATE(AV9,"_",AW9),$AI$7:$AL$16,4,FALSE),VLOOKUP(CONCATENATE(AW9,"_",AV9),$AI$7:$AL$16,4,FALSE))) -> SIN GANADOR | AY9: =IF(AX9="",1,IF(AX9=AV9,1,0)) -> 0 | AZ9: =-AP9*10000000 - AQ9*10000 - AR9*100 -> -30000000 | BA9: =AZ9-AY9*10 -> -30000000 | BB9: =BA9+N25 -> -29999997
B10: 3 | C10: =IFERROR(VLOOKUP($B10,$AN$7:$AS$11,C$5,FALSE),"") -> Suecia | D10: =IFERROR(VLOOKUP($B10,$AN$7:$AS$11,D$5,FALSE),"") -> 3 | E10: =IFERROR(VLOOKUP($B10,$AN$7:$AS$11,E$5,FALSE),"") -> 0 | F10: =IFERROR(VLOOKUP($B10,$AN$7:$AS$11,F$5,FALSE),"") -> 0 | G10: =IFERROR(VLOOKUP($B10,$AN$7:$AS$11,G$5,FALSE),"") -> 0 | I10: 36 | J10: 46193 | K10: Túnez | N10: Japón | AG10: =IF(OR(L10="",M10=""),1,0) -> 1 | AI10: =CONCATENATE(K10,"_",N10) -> Túnez_Japón | AJ10: =IF(L10>M10,3,IF(L10<M10,0,1)) -> 1 | AK10: =IF(AJ10=3,0,IF(AJ10=1,1,3)) -> 1 | AL10: =IF(AJ10>AK10,K10,IF(AK10>AJ10,N10,"SIN GANADOR")) -> SIN GANADOR | AN10: =_xlfn.RANK.EQ(BB10,BB$7:BB$11,1) -> 4 | AO10: =J26 -> Túnez | AP10: =SUMIF($K$7:$K$12,AO10,$AJ$7:$AJ$12) + SUMIF($N$7:$N$12,AO10,$AK$7:$AK$12) -> 3 | AQ10: =AR10-AS10 -> 0 | AR10: =SUMIF($K$7:$K$12,AO10,$L$7:$L$12) + SUMIF($N$7:$N$12,AO10,$M$7:$M$12) -> 0 | AS10: =SUMIF($K$7:$K$12,AO10,$M$7:$M$12) + SUMIF($N$7:$N$12,AO10,$L$7:$L$12) -> 0 | AV10: =AO10 -> Túnez | AW10: =IF(AZ10=AZ7,AV7,IF(AZ10=AZ8,AV8,IF(AZ10=AZ9,AV9,""))) -> Países Bajos | AX10: =IF(AW10="","",IFERROR(VLOOKUP(CONCATENATE(AV10,"_",AW10),$AI$7:$AL$16,4,FALSE),VLOOKUP(CONCATENATE(AW10,"_",AV10),$AI$7:$AL$16,4,FALSE))) -> SIN GANADOR | AY10: =IF(AX10="",1,IF(AX10=AV10,1,0)) -> 0 | AZ10: =-AP10*10000000 - AQ10*10000 - AR10*100 -> -30000000 | BA10: =AZ10-AY10*10 -> -30000000 | BB10: =BA10+N26 -> -29999996
B11: 4 | C11: =IFERROR(VLOOKUP($B11,$AN$7:$AS$11,C$5,FALSE),"") -> Túnez | D11: =IFERROR(VLOOKUP($B11,$AN$7:$AS$11,D$5,FALSE),"") -> 3 | E11: =IFERROR(VLOOKUP($B11,$AN$7:$AS$11,E$5,FALSE),"") -> 0 | F11: =IFERROR(VLOOKUP($B11,$AN$7:$AS$11,F$5,FALSE),"") -> 0 | G11: =IFERROR(VLOOKUP($B11,$AN$7:$AS$11,G$5,FALSE),"") -> 0 | I11: 57 | J11: 46198 | K11: Japón | N11: Suecia | AG11: =IF(OR(L11="",M11=""),1,0) -> 1 | AI11: =CONCATENATE(K11,"_",N11) -> Japón_Suecia | AJ11: =IF(L11>M11,3,IF(L11<M11,0,1)) -> 1 | AK11: =IF(AJ11=3,0,IF(AJ11=1,1,3)) -> 1 | AL11: =IF(AJ11>AK11,K11,IF(AK11>AJ11,N11,"SIN GANADOR")) -> SIN GANADOR
I12: 58 | J12: 46198 | K12: Túnez | N12: Países Bajos | AG12: =IF(OR(L12="",M12=""),1,0) -> 1 | AI12: =CONCATENATE(K12,"_",N12) -> Túnez_Países Bajos | AJ12: =IF(L12>M12,3,IF(L12<M12,0,1)) -> 1 | AK12: =IF(AJ12=3,0,IF(AJ12=1,1,3)) -> 1 | AL12: =IF(AJ12>AK12,K12,IF(AK12>AJ12,N12,"SIN GANADOR")) -> SIN GANADOR
AG13: =IF(SUM(AG7:AG12)>0,1,0) -> 1
B22: El recuadro de la derecha sirve para desempatar, en caso de que haya empate entre | I22: 1 | J22: Escoja por prioridad los siguientes equipos:
B23: uno o más equipos en todos los criterios considerados. | I23: =IF(J23="",0,1) -> 1 | J23: Países Bajos | M23: 1 | N23: =IF(J23="",0,M23) -> 1
B24: Para utilizarlo, asigne una prioridad entre 1 y 5 (siendo más bajo mejor) a cada equipo. | I24: =IF(J24="",0,1) -> 1 | J24: Japón | M24: 2 | N24: =IF(J24="",0,M24) -> 2
B25: Puede pensarlo como el lugar que quedarían en la tabla de posiciones. | I25: =IF(J25="",0,1) -> 1 | J25: Suecia | M25: 3 | N25: =IF(J25="",0,M25) -> 3
B26: A modo de ejemplo, si su predicción es que todos los partidos terminan 0-0, el orden | I26: =IF(J26="",0,1) -> 1 | J26: Túnez | M26: 4 | N26: =IF(J26="",0,M26) -> 4
B27: asignado en este recuadro es el que finalmente quedará en la tabla de posiciones. | N27: =IF(J27="",0,M27) -> 0

Sheet GRUPO G
B3: GRUPO G
C5: 2 | D5: 3 | E5: 5 | F5: 6 | G5: 4
B6: Tabla de Posiciones | J6: Fecha | K6: Partidos | AJ6: 1 | AK6: 2 | AL6: Ganador | AN6: Orden | AO6: Equipo | AP6: Puntos | AQ6: DG | AR6: GF | AS6: GC | AV6: Equipo | AW6: Empatado Con | AX6: Ganador | AY6: Ganador? | AZ6: Formula Rank | BA6: Formula Rank Con Duelo Directo | BB6: Formula Rank Con Prioridad
B7: Posición | C7: Equipo | D7: Puntos | E7: GF | F7: GC | G7: DG | I7: 14 | J7: 46188 | K7: Bélgica | N7: Egipto | AG7: =IF(OR(L7="",M7=""),1,0) -> 1 | AI7: =CONCATENATE(K7,"_",N7) -> Bélgica_Egipto | AJ7: =IF(L7>M7,3,IF(L7<M7,0,1)) -> 1 | AK7: =IF(AJ7=3,0,IF(AJ7=1,1,3)) -> 1 | AL7: =IF(AJ7>AK7,K7,IF(AK7>AJ7,N7,"SIN GANADOR")) -> SIN GANADOR | AN7: =_xlfn.RANK.EQ(BB7,BB$7:BB$11,1) -> 1 | AO7: =J23 -> Bélgica | AP7: =SUMIF($K$7:$K$12,AO7,$AJ$7:$AJ$12) + SUMIF($N$7:$N$12,AO7,$AK$7:$AK$12) -> 3 | AQ7: =AR7-AS7 -> 0 | AR7: =SUMIF($K$7:$K$12,AO7,$L$7:$L$12) + SUMIF($N$7:$N$12,AO7,$M$7:$M$12) -> 0 | AS7: =SUMIF($K$7:$K$12,AO7,$M$7:$M$12) + SUMIF($N$7:$N$12,AO7,$L$7:$L$12) -> 0 | AV7: =AO7 -> Bélgica | AW7: =IF(AZ7=AZ8,AV8,IF(AZ7=AZ9,AV9,IF(AZ7=AZ10,AV10,""))) -> Egipto | AX7: =IF(AW7="","",IFERROR(VLOOKUP(CONCATENATE(AV7,"_",AW7),$AI$7:$AL$16,4,FALSE),VLOOKUP(CONCATENATE(AW7,"_",AV7),$AI$7:$AL$16,4,FALSE))) -> SIN GANADOR | AY7: =IF(AX7="",1,IF(AX7=AV7,1,0)) -> 0 | AZ7: =-AP7*10000000 - AQ7*10000 - AR7*100 -> -30000000 | BA7: =AZ7-AY7*10 -> -30000000 | BB7: =BA7+N23 -> -29999999
B8: 1 | C8: =IFERROR(VLOOKUP($B8,$AN$7:$AS$11,C$5,FALSE),"") -> Bélgica | D8: =IFERROR(VLOOKUP($B8,$AN$7:$AS$11,D$5,FALSE),"") -> 3 | E8: =IFERROR(VLOOKUP($B8,$AN$7:$AS$11,E$5,FALSE),"") -> 0 | F8: =IFERROR(VLOOKUP($B8,$AN$7:$AS$11,F$5,FALSE),"") -> 0 | G8: =IFERROR(VLOOKUP($B8,$AN$7:$AS$11,G$5,FALSE),"") -> 0 | I8: 16 | J8: 46188 | K8: Irán | N8: Nueva Zelanda | AG8: =IF(OR(L8="",M8=""),1,0) -> 1 | AI8: =CONCATENATE(K8,"_",N8) -> Irán_Nueva Zelanda | AJ8: =IF(L8>M8,3,IF(L8<M8,0,1)) -> 1 | AK8: =IF(AJ8=3,0,IF(AJ8=1,1,3)) -> 1 | AL8: =IF(AJ8>AK8,K8,IF(AK8>AJ8,N8,"SIN GANADOR")) -> SIN GANADOR | AN8: =_xlfn.RANK.EQ(BB8,BB$7:BB$11,1) -> 2 | AO8: =J24 -> Egipto | AP8: =SUMIF($K$7:$K$12,AO8,$AJ$7:$AJ$12) + SUMIF($N$7:$N$12,AO8,$AK$7:$AK$12) -> 3 | AQ8: =AR8-AS8 -> 0 | AR8: =SUMIF($K$7:$K$12,AO8,$L$7:$L$12) + SUMIF($N$7:$N$12,AO8,$M$7:$M$12) -> 0 | AS8: =SUMIF($K$7:$K$12,AO8,$M$7:$M$12) + SUMIF($N$7:$N$12,AO8,$L$7:$L$12) -> 0 | AV8: =AO8 -> Egipto | AW8: =IF(AZ8=AZ9,AV9,IF(AZ8=AZ10,AV10,IF(AZ8=AZ7,AV7,""))) -> Irán | AX8: =IF(AW8="","",IFERROR(VLOOKUP(CONCATENATE(AV8,"_",AW8),$AI$7:$AL$16,4,FALSE),VLOOKUP(CONCATENATE(AW8,"_",AV8),$AI$7:$AL$16,4,FALSE))) -> SIN GANADOR | AY8: =IF(AX8="",1,IF(AX8=AV8,1,0)) -> 0 | AZ8: =-AP8*10000000 - AQ8*10000 - AR8*100 -> -30000000 | BA8: =AZ8-AY8*10 -> -30000000 | BB8: =BA8+N24 -> -29999998
B9: 2 | C9: =IFERROR(VLOOKUP($B9,$AN$7:$AS$11,C$5,FALSE),"") -> Egipto | D9: =IFERROR(VLOOKUP($B9,$AN$7:$AS$11,D$5,FALSE),"") -> 3 | E9: =IFERROR(VLOOKUP($B9,$AN$7:$AS$11,E$5,FALSE),"") -> 0 | F9: =IFERROR(VLOOKUP($B9,$AN$7:$AS$11,F$5,FALSE),"") -> 0 | G9: =IFERROR(VLOOKUP($B9,$AN$7:$AS$11,G$5,FALSE),"") -> 0 | I9: 38 | J9: 46194 | K9: Bélgica | N9: Irán | AG9: =IF(OR(L9="",M9=""),1,0) -> 1 | AI9: =CONCATENATE(K9,"_",N9) -> Bélgica_Irán | AJ9: =IF(L9>M9,3,IF(L9<M9,0,1)) -> 1 | AK9: =IF(AJ9=3,0,IF(AJ9=1,1,3)) -> 1 | AL9: =IF(AJ9>AK9,K9,IF(AK9>AJ9,N9,"SIN GANADOR")) -> SIN GANADOR | AN9: =_xlfn.RANK.EQ(BB9,BB$7:BB$11,1) -> 3 | AO9: =J25 -> Irán | AP9: =SUMIF($K$7:$K$12,AO9,$AJ$7:$AJ$12) + SUMIF($N$7:$N$12,AO9,$AK$7:$AK$12) -> 3 | AQ9: =AR9-AS9 -> 0 | AR9: =SUMIF($K$7:$K$12,AO9,$L$7:$L$12) + SUMIF($N$7:$N$12,AO9,$M$7:$M$12) -> 0 | AS9: =SUMIF($K$7:$K$12,AO9,$M$7:$M$12) + SUMIF($N$7:$N$12,AO9,$L$7:$L$12) -> 0 | AV9: =AO9 -> Irán | AW9: =IF(AZ9=AZ10,AV10,IF(AZ9=AZ7,AV7,IF(AZ9=AZ8,AV8,""))) -> Nueva Zelanda | AX9: =IF(AW9="","",IFERROR(VLOOKUP(CONCATENATE(AV9,"_",AW9),$AI$7:$AL$16,4,FALSE),VLOOKUP(CONCATENATE(AW9,"_",AV9),$AI$7:$AL$16,4,FALSE))) -> SIN GANADOR | AY9: =IF(AX9="",1,IF(AX9=AV9,1,0)) -> 0 | AZ9: =-AP9*10000000 - AQ9*10000 - AR9*100 -> -30000000 | BA9: =AZ9-AY9*10 -> -30000000 | BB9: =BA9+N25 -> -29999997
B10: 3 | C10: =IFERROR(VLOOKUP($B10,$AN$7:$AS$11,C$5,FALSE),"") -> Irán | D10: =IFERROR(VLOOKUP($B10,$AN$7:$AS$11,D$5,FALSE),"") -> 3 | E10: =IFERROR(VLOOKUP($B10,$AN$7:$AS$11,E$5,FALSE),"") -> 0 | F10: =IFERROR(VLOOKUP($B10,$AN$7:$AS$11,F$5,FALSE),"") -> 0 | G10: =IFERROR(VLOOKUP($B10,$AN$7:$AS$11,G$5,FALSE),"") -> 0 | I10: 39 | J10: 46194 | K10: Nueva Zelanda | N10: Egipto | AG10: =IF(OR(L10="",M10=""),1,0) -> 1 | AI10: =CONCATENATE(K10,"_",N10) -> Nueva Zelanda_Egipto | AJ10: =IF(L10>M10,3,IF(L10<M10,0,1)) -> 1 | AK10: =IF(AJ10=3,0,IF(AJ10=1,1,3)) -> 1 | AL10: =IF(AJ10>AK10,K10,IF(AK10>AJ10,N10,"SIN GANADOR")) -> SIN GANADOR | AN10: =_xlfn.RANK.EQ(BB10,BB$7:BB$11,1) -> 4 | AO10: =J26 -> Nueva Zelanda | AP10: =SUMIF($K$7:$K$12,AO10,$AJ$7:$AJ$12) + SUMIF($N$7:$N$12,AO10,$AK$7:$AK$12) -> 3 | AQ10: =AR10-AS10 -> 0 | AR10: =SUMIF($K$7:$K$12,AO10,$L$7:$L$12) + SUMIF($N$7:$N$12,AO10,$M$7:$M$12) -> 0 | AS10: =SUMIF($K$7:$K$12,AO10,$M$7:$M$12) + SUMIF($N$7:$N$12,AO10,$L$7:$L$12) -> 0 | AV10: =AO10 -> Nueva Zelanda | AW10: =IF(AZ10=AZ7,AV7,IF(AZ10=AZ8,AV8,IF(AZ10=AZ9,AV9,""))) -> Bélgica | AX10: =IF(AW10="","",IFERROR(VLOOKUP(CONCATENATE(AV10,"_",AW10),$AI$7:$AL$16,4,FALSE),VLOOKUP(CONCATENATE(AW10,"_",AV10),$AI$7:$AL$16,4,FALSE))) -> SIN GANADOR | AY10: =IF(AX10="",1,IF(AX10=AV10,1,0)) -> 0 | AZ10: =-AP10*10000000 - AQ10*10000 - AR10*100 -> -30000000 | BA10: =AZ10-AY10*10 -> -30000000 | BB10: =BA10+N26 -> -29999996
B11: 4 | C11: =IFERROR(VLOOKUP($B11,$AN$7:$AS$11,C$5,FALSE),"") -> Nueva Zelanda | D11: =IFERROR(VLOOKUP($B11,$AN$7:$AS$11,D$5,FALSE),"") -> 3 | E11: =IFERROR(VLOOKUP($B11,$AN$7:$AS$11,E$5,FALSE),"") -> 0 | F11: =IFERROR(VLOOKUP($B11,$AN$7:$AS$11,F$5,FALSE),"") -> 0 | G11: =IFERROR(VLOOKUP($B11,$AN$7:$AS$11,G$5,FALSE),"") -> 0 | I11: 65 | J11: 46199 | K11: Egipto | N11: Irán | AG11: =IF(OR(L11="",M11=""),1,0) -> 1 | AI11: =CONCATENATE(K11,"_",N11) -> Egipto_Irán | AJ11: =IF(L11>M11,3,IF(L11<M11,0,1)) -> 1 | AK11: =IF(AJ11=3,0,IF(AJ11=1,1,3)) -> 1 | AL11: =IF(AJ11>AK11,K11,IF(AK11>AJ11,N11,"SIN GANADOR")) -> SIN GANADOR
I12: 66 | J12: 46199 | K12: Nueva Zelanda | N12: Bélgica | AG12: =IF(OR(L12="",M12=""),1,0) -> 1 | AI12: =CONCATENATE(K12,"_",N12) -> Nueva Zelanda_Bélgica | AJ12: =IF(L12>M12,3,IF(L12<M12,0,1)) -> 1 | AK12: =IF(AJ12=3,0,IF(AJ12=1,1,3)) -> 1 | AL12: =IF(AJ12>AK12,K12,IF(AK12>AJ12,N12,"SIN GANADOR")) -> SIN GANADOR
AG13: =IF(SUM(AG7:AG12)>0,1,0) -> 1
B22: El recuadro de la derecha sirve para desempatar, en caso de que haya empate entre | I22: 1 | J22: Escoja por prioridad los siguientes equipos:
B23: uno o más equipos en todos los criterios considerados. | I23: =IF(J23="",0,1) -> 1 | J23: Bélgica | M23: 1 | N23: =IF(J23="",0,M23) -> 1
B24: Para utilizarlo, asigne una prioridad entre 1 y 5 (siendo más bajo mejor) a cada equipo. | I24: =IF(J24="",0,1) -> 1 | J24: Egipto | M24: 2 | N24: =IF(J24="",0,M24) -> 2
B25: Puede pensarlo como el lugar que quedarían en la tabla de posiciones. | I25: =IF(J25="",0,1) -> 1 | J25: Irán | M25: 3 | N25: =IF(J25="",0,M25) -> 3
B26: A modo de ejemplo, si su predicción es que todos los partidos terminan 0-0, el orden | I26: =IF(J26="",0,1) -> 1 | J26: Nueva Zelanda | M26: 4 | N26: =IF(J26="",0,M26) -> 4
B27: asignado en este recuadro es el que finalmente quedará en la tabla de posiciones. | N27: =IF(J27="",0,M27) -> 0

Sheet GRUPO H
B3: GRUPO H
C5: 2 | D5: 3 | E5: 5 | F5: 6 | G5: 4
B6: Tabla de Posiciones | J6: Fecha | K6: Partidos | AJ6: 1 | AK6: 2 | AL6: Ganador | AN6: Orden | AO6: Equipo | AP6: Puntos | AQ6: DG | AR6: GF | AS6: GC | AV6: Equipo | AW6: Empatado Con | AX6: Ganador | AY6: Ganador? | AZ6: Formula Rank | BA6: Formula Rank Con Duelo Directo | BB6: Formula Rank Con Prioridad
B7: Posición | C7: Equipo | D7: Puntos | E7: GF | F7: GC | G7: DG | I7: 13 | J7: 46188 | K7: España | N7: Cabo Verde | AG7: =IF(OR(L7="",M7=""),1,0) -> 1 | AI7: =CONCATENATE(K7,"_",N7) -> España_Cabo Verde | AJ7: =IF(L7>M7,3,IF(L7<M7,0,1)) -> 1 | AK7: =IF(AJ7=3,0,IF(AJ7=1,1,3)) -> 1 | AL7: =IF(AJ7>AK7,K7,IF(AK7>AJ7,N7,"SIN GANADOR")) -> SIN GANADOR | AN7: =_xlfn.RANK.EQ(BB7,BB$7:BB$11,1) -> 1 | AO7: =J23 -> España | AP7: =SUMIF($K$7:$K$12,AO7,$AJ$7:$AJ$12) + SUMIF($N$7:$N$12,AO7,$AK$7:$AK$12) -> 3 | AQ7: =AR7-AS7 -> 0 | AR7: =SUMIF($K$7:$K$12,AO7,$L$7:$L$12) + SUMIF($N$7:$N$12,AO7,$M$7:$M$12) -> 0 | AS7: =SUMIF($K$7:$K$12,AO7,$M$7:$M$12) + SUMIF($N$7:$N$12,AO7,$L$7:$L$12) -> 0 | AV7: =AO7 -> España | AW7: =IF(AZ7=AZ8,AV8,IF(AZ7=AZ9,AV9,IF(AZ7=AZ10,AV10,""))) -> Cabo Verde | AX7: =IF(AW7="","",IFERROR(VLOOKUP(CONCATENATE(AV7,"_",AW7),$AI$7:$AL$16,4,FALSE),VLOOKUP(CONCATENATE(AW7,"_",AV7),$AI$7:$AL$16,4,FALSE))) -> SIN GANADOR | AY7: =IF(AX7="",1,IF(AX7=AV7,1,0)) -> 0 | AZ7: =-AP7*10000000 - AQ7*10000 - AR7*100 -> -30000000 | BA7: =AZ7-AY7*10 -> -30000000 | BB7: =BA7+N23 -> -29999999
B8: 1 | C8: =IFERROR(VLOOKUP($B8,$AN$7:$AS$11,C$5,FALSE),"") -> España | D8: =IFERROR(VLOOKUP($B8,$AN$7:$AS$11,D$5,FALSE),"") -> 3 | E8: =IFERROR(VLOOKUP($B8,$AN$7:$AS$11,E$5,FALSE),"") -> 0 | F8: =IFERROR(VLOOKUP($B8,$AN$7:$AS$11,F$5,FALSE),"") -> 0 | G8: =IFERROR(VLOOKUP($B8,$AN$7:$AS$11,G$5,FALSE),"") -> 0 | I8: 15 | J8: 46188 | K8: Arabia Saudita | N8: Uruguay | AG8: =IF(OR(L8="",M8=""),1,0) -> 1 | AI8: =CONCATENATE(K8,"_",N8) -> Arabia Saudita_Uruguay | AJ8: =IF(L8>M8,3,IF(L8<M8,0,1)) -> 1 | AK8: =IF(AJ8=3,0,IF(AJ8=1,1,3)) -> 1 | AL8: =IF(AJ8>AK8,K8,IF(AK8>AJ8,N8,"SIN GANADOR")) -> SIN GANADOR | AN8: =_xlfn.RANK.EQ(BB8,BB$7:BB$11,1) -> 2 | AO8: =J24 -> Cabo Verde | AP8: =SUMIF($K$7:$K$12,AO8,$AJ$7:$AJ$12) + SUMIF($N$7:$N$12,AO8,$AK$7:$AK$12) -> 3 | AQ8: =AR8-AS8 -> 0 | AR8: =SUMIF($K$7:$K$12,AO8,$L$7:$L$12) + SUMIF($N$7:$N$12,AO8,$M$7:$M$12) -> 0 | AS8: =SUMIF($K$7:$K$12,AO8,$M$7:$M$12) + SUMIF($N$7:$N$12,AO8,$L$7:$L$12) -> 0 | AV8: =AO8 -> Cabo Verde | AW8: =IF(AZ8=AZ9,AV9,IF(AZ8=AZ10,AV10,IF(AZ8=AZ7,AV7,""))) -> Arabia Saudita | AX8: =IF(AW8="","",IFERROR(VLOOKUP(CONCATENATE(AV8,"_",AW8),$AI$7:$AL$16,4,FALSE),VLOOKUP(CONCATENATE(AW8,"_",AV8),$AI$7:$AL$16,4,FALSE))) -> SIN GANADOR | AY8: =IF(AX8="",1,IF(AX8=AV8,1,0)) -> 0 | AZ8: =-AP8*10000000 - AQ8*10000 - AR8*100 -> -30000000 | BA8: =AZ8-AY8*10 -> -30000000 | BB8: =BA8+N24 -> -29999998
B9: 2 | C9: =IFERROR(VLOOKUP($B9,$AN$7:$AS$11,C$5,FALSE),"") -> Cabo Verde | D9: =IFERROR(VLOOKUP($B9,$AN$7:$AS$11,D$5,FALSE),"") -> 3 | E9: =IFERROR(VLOOKUP($B9,$AN$7:$AS$11,E$5,FALSE),"") -> 0 | F9: =IFERROR(VLOOKUP($B9,$AN$7:$AS$11,F$5,FALSE),"") -> 0 | G9: =IFERROR(VLOOKUP($B9,$AN$7:$AS$11,G$5,FALSE),"") -> 0 | I9: 37 | J9: 46194 | K9: España | N9: Arabia Saudita | AG9: =IF(OR(L9="",M9=""),1,0) -> 1 | AI9: =CONCATENATE(K9,"_",N9) -> España_Arabia Saudita | AJ9: =IF(L9>M9,3,IF(L9<M9,0,1)) -> 1 | AK9: =IF(AJ9=3,0,IF(AJ9=1,1,3)) -> 1 | AL9: =IF(AJ9>AK9,K9,IF(AK9>AJ9,N9,"SIN GANADOR")) -> SIN GANADOR | AN9: =_xlfn.RANK.EQ(BB9,BB$7:BB$11,1) -> 3 | AO9: =J25 -> Arabia Saudita | AP9: =SUMIF($K$7:$K$12,AO9,$AJ$7:$AJ$12) + SUMIF($N$7:$N$12,AO9,$AK$7:$AK$12) -> 3 | AQ9: =AR9-AS9 -> 0 | AR9: =SUMIF($K$7:$K$12,AO9,$L$7:$L$12) + SUMIF($N$7:$N$12,AO9,$M$7:$M$12) -> 0 | AS9: =SUMIF($K$7:$K$12,AO9,$M$7:$M$12) + SUMIF($N$7:$N$12,AO9,$L$7:$L$12) -> 0 | AV9: =AO9 -> Arabia Saudita | AW9: =IF(AZ9=AZ10,AV10,IF(AZ9=AZ7,AV7,IF(AZ9=AZ8,AV8,""))) -> Uruguay | AX9: =IF(AW9="","",IFERROR(VLOOKUP(CONCATENATE(AV9,"_",AW9),$AI$7:$AL$16,4,FALSE),VLOOKUP(CONCATENATE(AW9,"_",AV9),$AI$7:$AL$16,4,FALSE))) -> SIN GANADOR | AY9: =IF(AX9="",1,IF(AX9=AV9,1,0)) -> 0 | AZ9: =-AP9*10000000 - AQ9*10000 - AR9*100 -> -30000000 | BA9: =AZ9-AY9*10 -> -30000000 | BB9: =BA9+N25 -> -29999997
B10: 3 | C10: =IFERROR(VLOOKUP($B10,$AN$7:$AS$11,C$5,FALSE),"") -> Arabia Saudita | D10: =IFERROR(VLOOKUP($B10,$AN$7:$AS$11,D$5,FALSE),"") -> 3 | E10: =IFERROR(VLOOKUP($B10,$AN$7:$AS$11,E$5,FALSE),"") -> 0 | F10: =IFERROR(VLOOKUP($B10,$AN$7:$AS$11,F$5,FALSE),"") -> 0 | G10: =IFERROR(VLOOKUP($B10,$AN$7:$AS$11,G$5,FALSE),"") -> 0 | I10: 40 | J10: 46194 | K10: Uruguay | N10: Cabo Verde | AG10: =IF(OR(L10="",M10=""),1,0) -> 1 | AI10: =CONCATENATE(K10,"_",N10) -> Uruguay_Cabo Verde | AJ10: =IF(L10>M10,3,IF(L10<M10,0,1)) -> 1 | AK10: =IF(AJ10=3,0,IF(AJ10=1,1,3)) -> 1 | AL10: =IF(AJ10>AK10,K10,IF(AK10>AJ10,N10,"SIN GANADOR")) -> SIN GANADOR | AN10: =_xlfn.RANK.EQ(BB10,BB$7:BB$11,1) -> 4 | AO10: =J26 -> Uruguay | AP10: =SUMIF($K$7:$K$12,AO10,$AJ$7:$AJ$12) + SUMIF($N$7:$N$12,AO10,$AK$7:$AK$12) -> 3 | AQ10: =AR10-AS10 -> 0 | AR10: =SUMIF($K$7:$K$12,AO10,$L$7:$L$12) + SUMIF($N$7:$N$12,AO10,$M$7:$M$12) -> 0 | AS10: =SUMIF($K$7:$K$12,AO10,$M$7:$M$12) + SUMIF($N$7:$N$12,AO10,$L$7:$L$12) -> 0 | AV10: =AO10 -> Uruguay | AW10: =IF(AZ10=AZ7,AV7,IF(AZ10=AZ8,AV8,IF(AZ10=AZ9,AV9,""))) -> España | AX10: =IF(AW10="","",IFERROR(VLOOKUP(CONCATENATE(AV10,"_",AW10),$AI$7:$AL$16,4,FALSE),VLOOKUP(CONCATENATE(AW10,"_",AV10),$AI$7:$AL$16,4,FALSE))) -> SIN GANADOR | AY10: =IF(AX10="",1,IF(AX10=AV10,1,0)) -> 0 | AZ10: =-AP10*10000000 - AQ10*10000 - AR10*100 -> -30000000 | BA10: =AZ10-AY10*10 -> -30000000 | BB10: =BA10+N26 -> -29999996
B11: 4 | C11: =IFERROR(VLOOKUP($B11,$AN$7:$AS$11,C$5,FALSE),"") -> Uruguay | D11: =IFERROR(VLOOKUP($B11,$AN$7:$AS$11,D$5,FALSE),"") -> 3 | E11: =IFERROR(VLOOKUP($B11,$AN$7:$AS$11,E$5,FALSE),"") -> 0 | F11: =IFERROR(VLOOKUP($B11,$AN$7:$AS$11,F$5,FALSE),"") -> 0 | G11: =IFERROR(VLOOKUP($B11,$AN$7:$AS$11,G$5,FALSE),"") -> 0 | I11: 63 | J11: 46199 | K11: Cabo Verde | N11: Arabia Saudita | AG11: =IF(OR(L11="",M11=""),1,0) -> 1 | AI11: =CONCATENATE(K11,"_",N11) -> Cabo Verde_Arabia Saudita | AJ11: =IF(L11>M11,3,IF(L11<M11,0,1)) -> 1 | AK11: =IF(AJ11=3,0,IF(AJ11=1,1,3)) -> 1 | AL11: =IF(AJ11>AK11,K11,IF(AK11>AJ11,N11,"SIN GANADOR")) -> SIN GANADOR
I12: 64 | J12: 46199 | K12: Uruguay | N12: España | AG12: =IF(OR(L12="",M12=""),1,0) -> 1 | AI12: =CONCATENATE(K12,"_",N12) -> Uruguay_España | AJ12: =IF(L12>M12,3,IF(L12<M12,0,1)) -> 1 | AK12: =IF(AJ12=3,0,IF(AJ12=1,1,3)) -> 1 | AL12: =IF(AJ12>AK12,K12,IF(AK12>AJ12,N12,"SIN GANADOR")) -> SIN GANADOR
AG13: =IF(SUM(AG7:AG12)>0,1,0) -> 1
B22: El recuadro de la derecha sirve para desempatar, en caso de que haya empate entre | I22: 1 | J22: Escoja por prioridad los siguientes equipos:
B23: uno o más equipos en todos los criterios considerados. | I23: =IF(J23="",0,1) -> 1 | J23: España | M23: 1 | N23: =IF(J23="",0,M23) -> 1
B24: Para utilizarlo, asigne una prioridad entre 1 y 5 (siendo más bajo mejor) a cada equipo. | I24: =IF(J24="",0,1) -> 1 | J24: Cabo Verde | M24: 2 | N24: =IF(J24="",0,M24) -> 2
B25: Puede pensarlo como el lugar que quedarían en la tabla de posiciones. | I25: =IF(J25="",0,1) -> 1 | J25: Arabia Saudita | M25: 3 | N25: =IF(J25="",0,M25) -> 3
B26: A modo de ejemplo, si su predicción es que todos los partidos terminan 0-0, el orden | I26: =IF(J26="",0,1) -> 1 | J26: Uruguay | M26: 4 | N26: =IF(J26="",0,M26) -> 4
B27: asignado en este recuadro es el que finalmente quedará en la tabla de posiciones. | N27: =IF(J27="",0,M27) -> 0

Sheet GRUPO I
B3: GRUPO I
